[2025-07-21 17:13:46] ERROR signal Signal handler <promise@0xffff7e2f4dc0 --> <bound method Celery._autodiscover_tasks of <Celery __main__ at 0xffff7e304d60>>> raised: SyntaxError("unmatched ')'", ('/code/apps/challenges/aws_utils.py', 2220, 1, '):'))
Traceback (most recent call last):
  File "/usr/local/lib/python3.9/site-packages/celery/utils/dispatch/signal.py", line 288, in send
    response = receiver(signal=self, sender=sender, **named)
  File "/usr/local/lib/python3.9/site-packages/vine/promises.py", line 170, in __call__
    return self.throw()
  File "/usr/local/lib/python3.9/site-packages/vine/promises.py", line 167, in __call__
    retval = fun(*final_args, **final_kwargs)
  File "/usr/local/lib/python3.9/site-packages/celery/app/base.py", line 679, in _autodiscover_tasks
    return self._autodiscover_tasks_from_names(packages, related_name)
  File "/usr/local/lib/python3.9/site-packages/celery/app/base.py", line 684, in _autodiscover_tasks_from_names
    return self.loader.autodiscover_tasks(
  File "/usr/local/lib/python3.9/site-packages/celery/loaders/base.py", line 223, in autodiscover_tasks
    mod.__name__ for mod in autodiscover_tasks(packages or (),
  File "/usr/local/lib/python3.9/site-packages/celery/loaders/base.py", line 249, in autodiscover_tasks
    return [find_related_module(pkg, related_name) for pkg in packages]
  File "/usr/local/lib/python3.9/site-packages/celery/loaders/base.py", line 249, in <listcomp>
    return [find_related_module(pkg, related_name) for pkg in packages]
  File "/usr/local/lib/python3.9/site-packages/celery/loaders/base.py", line 268, in find_related_module
    return importlib.import_module('{0}.{1}'.format(package, related_name))
  File "/usr/local/lib/python3.9/importlib/__init__.py", line 127, in import_module
    return _bootstrap._gcd_import(name[level:], package, level)
  File "<frozen importlib._bootstrap>", line 1030, in _gcd_import
  File "<frozen importlib._bootstrap>", line 1007, in _find_and_load
  File "<frozen importlib._bootstrap>", line 986, in _find_and_load_unlocked
  File "<frozen importlib._bootstrap>", line 680, in _load_unlocked
  File "<frozen importlib._bootstrap_external>", line 850, in exec_module
  File "<frozen importlib._bootstrap>", line 228, in _call_with_frames_removed
  File "/code/apps/jobs/tasks.py", line 5, in <module>
    from challenges.models import ChallengePhase
  File "/code/apps/challenges/models.py", line 489, in <module>
    post_save_connect("evaluation_script", Challenge)
  File "/code/apps/challenges/models.py", line 478, in post_save_connect
    import challenges.aws_utils as aws
  File "/code/apps/challenges/aws_utils.py", line 2220
    ):
    ^
SyntaxError: unmatched ')'
[2025-07-21 17:13:53] ERROR signal Signal handler <bound method DjangoFixup.on_import_modules of <celery.fixups.django.DjangoFixup object at 0xffff8444b1c0>> raised: SyntaxError("unmatched ')'", ('/code/apps/challenges/aws_utils.py', 2220, 1, '):'))
Traceback (most recent call last):
  File "/usr/local/lib/python3.9/site-packages/celery/utils/dispatch/signal.py", line 288, in send
    response = receiver(signal=self, sender=sender, **named)
  File "/usr/local/lib/python3.9/site-packages/celery/fixups/django.py", line 84, in on_import_modules
    self.worker_fixup.validate_models()
  File "/usr/local/lib/python3.9/site-packages/celery/fixups/django.py", line 122, in validate_models
    self.django_setup()
  File "/usr/local/lib/python3.9/site-packages/celery/fixups/django.py", line 118, in django_setup
    django.setup()
  File "/usr/local/lib/python3.9/site-packages/django/__init__.py", line 24, in setup
    apps.populate(settings.INSTALLED_APPS)
  File "/usr/local/lib/python3.9/site-packages/django/apps/registry.py", line 114, in populate
    app_config.import_models()
  File "/usr/local/lib/python3.9/site-packages/django/apps/config.py", line 211, in import_models
    self.models_module = import_module(models_module_name)
  File "/usr/local/lib/python3.9/importlib/__init__.py", line 127, in import_module
    return _bootstrap._gcd_import(name[level:], package, level)
  File "<frozen importlib._bootstrap>", line 1030, in _gcd_import
  File "<frozen importlib._bootstrap>", line 1007, in _find_and_load
  File "<frozen importlib._bootstrap>", line 986, in _find_and_load_unlocked
  File "<frozen importlib._bootstrap>", line 680, in _load_unlocked
  File "<frozen importlib._bootstrap_external>", line 850, in exec_module
  File "<frozen importlib._bootstrap>", line 228, in _call_with_frames_removed
  File "/code/apps/challenges/models.py", line 489, in <module>
    post_save_connect("evaluation_script", Challenge)
  File "/code/apps/challenges/models.py", line 478, in post_save_connect
    import challenges.aws_utils as aws
  File "/code/apps/challenges/aws_utils.py", line 2220
    ):
    ^
SyntaxError: unmatched ')'
[2025-07-21 17:13:53] ERROR signal Signal handler <bound method DjangoFixup.on_import_modules of <celery.fixups.django.DjangoFixup object at 0xffff943ff220>> raised: SyntaxError("unmatched ')'", ('/code/apps/challenges/aws_utils.py', 2220, 1, '):'))
Traceback (most recent call last):
  File "/usr/local/lib/python3.9/site-packages/celery/utils/dispatch/signal.py", line 288, in send
    response = receiver(signal=self, sender=sender, **named)
  File "/usr/local/lib/python3.9/site-packages/celery/fixups/django.py", line 84, in on_import_modules
    self.worker_fixup.validate_models()
  File "/usr/local/lib/python3.9/site-packages/celery/fixups/django.py", line 122, in validate_models
    self.django_setup()
  File "/usr/local/lib/python3.9/site-packages/celery/fixups/django.py", line 118, in django_setup
    django.setup()
  File "/usr/local/lib/python3.9/site-packages/django/__init__.py", line 24, in setup
    apps.populate(settings.INSTALLED_APPS)
  File "/usr/local/lib/python3.9/site-packages/django/apps/registry.py", line 114, in populate
    app_config.import_models()
  File "/usr/local/lib/python3.9/site-packages/django/apps/config.py", line 211, in import_models
    self.models_module = import_module(models_module_name)
  File "/usr/local/lib/python3.9/importlib/__init__.py", line 127, in import_module
    return _bootstrap._gcd_import(name[level:], package, level)
  File "<frozen importlib._bootstrap>", line 1030, in _gcd_import
  File "<frozen importlib._bootstrap>", line 1007, in _find_and_load
  File "<frozen importlib._bootstrap>", line 986, in _find_and_load_unlocked
  File "<frozen importlib._bootstrap>", line 680, in _load_unlocked
  File "<frozen importlib._bootstrap_external>", line 850, in exec_module
  File "<frozen importlib._bootstrap>", line 228, in _call_with_frames_removed
  File "/code/apps/challenges/models.py", line 489, in <module>
    post_save_connect("evaluation_script", Challenge)
  File "/code/apps/challenges/models.py", line 478, in post_save_connect
    import challenges.aws_utils as aws
  File "/code/apps/challenges/aws_utils.py", line 2220
    ):
    ^
SyntaxError: unmatched ')'
[2025-07-21 17:13:53] ERROR signal Signal handler <promise@0xffff84484dc0 --> <bound method Celery._autodiscover_tasks of <Celery __main__ at 0xffff84493d60>>> raised: SyntaxError("unmatched ')'", ('/code/apps/challenges/aws_utils.py', 2220, 1, '):'))
Traceback (most recent call last):
  File "/usr/local/lib/python3.9/site-packages/celery/utils/dispatch/signal.py", line 288, in send
    response = receiver(signal=self, sender=sender, **named)
  File "/usr/local/lib/python3.9/site-packages/vine/promises.py", line 170, in __call__
    return self.throw()
  File "/usr/local/lib/python3.9/site-packages/vine/promises.py", line 167, in __call__
    retval = fun(*final_args, **final_kwargs)
  File "/usr/local/lib/python3.9/site-packages/celery/app/base.py", line 679, in _autodiscover_tasks
    return self._autodiscover_tasks_from_names(packages, related_name)
  File "/usr/local/lib/python3.9/site-packages/celery/app/base.py", line 684, in _autodiscover_tasks_from_names
    return self.loader.autodiscover_tasks(
  File "/usr/local/lib/python3.9/site-packages/celery/loaders/base.py", line 223, in autodiscover_tasks
    mod.__name__ for mod in autodiscover_tasks(packages or (),
  File "/usr/local/lib/python3.9/site-packages/celery/loaders/base.py", line 249, in autodiscover_tasks
    return [find_related_module(pkg, related_name) for pkg in packages]
  File "/usr/local/lib/python3.9/site-packages/celery/loaders/base.py", line 249, in <listcomp>
    return [find_related_module(pkg, related_name) for pkg in packages]
  File "/usr/local/lib/python3.9/site-packages/celery/loaders/base.py", line 268, in find_related_module
    return importlib.import_module('{0}.{1}'.format(package, related_name))
  File "/usr/local/lib/python3.9/importlib/__init__.py", line 127, in import_module
    return _bootstrap._gcd_import(name[level:], package, level)
  File "<frozen importlib._bootstrap>", line 1030, in _gcd_import
  File "<frozen importlib._bootstrap>", line 1007, in _find_and_load
  File "<frozen importlib._bootstrap>", line 986, in _find_and_load_unlocked
  File "<frozen importlib._bootstrap>", line 680, in _load_unlocked
  File "<frozen importlib._bootstrap_external>", line 850, in exec_module
  File "<frozen importlib._bootstrap>", line 228, in _call_with_frames_removed
  File "/code/apps/jobs/tasks.py", line 5, in <module>
    from challenges.models import ChallengePhase
  File "/code/apps/challenges/models.py", line 489, in <module>
    post_save_connect("evaluation_script", Challenge)
  File "/code/apps/challenges/models.py", line 478, in post_save_connect
    import challenges.aws_utils as aws
  File "/code/apps/challenges/aws_utils.py", line 2220
    ):
    ^
SyntaxError: unmatched ')'
[2025-07-21 17:13:53] ERROR signal Signal handler <promise@0xffff94434dc0 --> <bound method Celery._autodiscover_tasks of <Celery __main__ at 0xffff94444d00>>> raised: SyntaxError("unmatched ')'", ('/code/apps/challenges/aws_utils.py', 2220, 1, '):'))
Traceback (most recent call last):
  File "/usr/local/lib/python3.9/site-packages/celery/utils/dispatch/signal.py", line 288, in send
    response = receiver(signal=self, sender=sender, **named)
  File "/usr/local/lib/python3.9/site-packages/vine/promises.py", line 170, in __call__
    return self.throw()
  File "/usr/local/lib/python3.9/site-packages/vine/promises.py", line 167, in __call__
    retval = fun(*final_args, **final_kwargs)
  File "/usr/local/lib/python3.9/site-packages/celery/app/base.py", line 679, in _autodiscover_tasks
    return self._autodiscover_tasks_from_names(packages, related_name)
  File "/usr/local/lib/python3.9/site-packages/celery/app/base.py", line 684, in _autodiscover_tasks_from_names
    return self.loader.autodiscover_tasks(
  File "/usr/local/lib/python3.9/site-packages/celery/loaders/base.py", line 223, in autodiscover_tasks
    mod.__name__ for mod in autodiscover_tasks(packages or (),
  File "/usr/local/lib/python3.9/site-packages/celery/loaders/base.py", line 249, in autodiscover_tasks
    return [find_related_module(pkg, related_name) for pkg in packages]
  File "/usr/local/lib/python3.9/site-packages/celery/loaders/base.py", line 249, in <listcomp>
    return [find_related_module(pkg, related_name) for pkg in packages]
  File "/usr/local/lib/python3.9/site-packages/celery/loaders/base.py", line 268, in find_related_module
    return importlib.import_module('{0}.{1}'.format(package, related_name))
  File "/usr/local/lib/python3.9/importlib/__init__.py", line 127, in import_module
    return _bootstrap._gcd_import(name[level:], package, level)
  File "<frozen importlib._bootstrap>", line 1030, in _gcd_import
  File "<frozen importlib._bootstrap>", line 1007, in _find_and_load
  File "<frozen importlib._bootstrap>", line 986, in _find_and_load_unlocked
  File "<frozen importlib._bootstrap>", line 680, in _load_unlocked
  File "<frozen importlib._bootstrap_external>", line 850, in exec_module
  File "<frozen importlib._bootstrap>", line 228, in _call_with_frames_removed
  File "/code/apps/jobs/tasks.py", line 5, in <module>
    from challenges.models import ChallengePhase
  File "/code/apps/challenges/models.py", line 489, in <module>
    post_save_connect("evaluation_script", Challenge)
  File "/code/apps/challenges/models.py", line 478, in post_save_connect
    import challenges.aws_utils as aws
  File "/code/apps/challenges/aws_utils.py", line 2220
    ):
    ^
SyntaxError: unmatched ')'
[2025-07-21 17:14:07] ERROR signal Signal handler <bound method DjangoFixup.on_import_modules of <celery.fixups.django.DjangoFixup object at 0xffff819ec1c0>> raised: SyntaxError("unmatched ')'", ('/code/apps/challenges/aws_utils.py', 2220, 1, '):'))
Traceback (most recent call last):
  File "/usr/local/lib/python3.9/site-packages/celery/utils/dispatch/signal.py", line 288, in send
    response = receiver(signal=self, sender=sender, **named)
  File "/usr/local/lib/python3.9/site-packages/celery/fixups/django.py", line 84, in on_import_modules
    self.worker_fixup.validate_models()
  File "/usr/local/lib/python3.9/site-packages/celery/fixups/django.py", line 122, in validate_models
    self.django_setup()
  File "/usr/local/lib/python3.9/site-packages/celery/fixups/django.py", line 118, in django_setup
    django.setup()
  File "/usr/local/lib/python3.9/site-packages/django/__init__.py", line 24, in setup
    apps.populate(settings.INSTALLED_APPS)
  File "/usr/local/lib/python3.9/site-packages/django/apps/registry.py", line 114, in populate
    app_config.import_models()
  File "/usr/local/lib/python3.9/site-packages/django/apps/config.py", line 211, in import_models
    self.models_module = import_module(models_module_name)
  File "/usr/local/lib/python3.9/importlib/__init__.py", line 127, in import_module
    return _bootstrap._gcd_import(name[level:], package, level)
  File "<frozen importlib._bootstrap>", line 1030, in _gcd_import
  File "<frozen importlib._bootstrap>", line 1007, in _find_and_load
  File "<frozen importlib._bootstrap>", line 986, in _find_and_load_unlocked
  File "<frozen importlib._bootstrap>", line 680, in _load_unlocked
  File "<frozen importlib._bootstrap_external>", line 850, in exec_module
  File "<frozen importlib._bootstrap>", line 228, in _call_with_frames_removed
  File "/code/apps/challenges/models.py", line 489, in <module>
    post_save_connect("evaluation_script", Challenge)
  File "/code/apps/challenges/models.py", line 478, in post_save_connect
    import challenges.aws_utils as aws
  File "/code/apps/challenges/aws_utils.py", line 2220
    ):
    ^
SyntaxError: unmatched ')'
[2025-07-21 17:14:07] ERROR signal Signal handler <bound method DjangoFixup.on_import_modules of <celery.fixups.django.DjangoFixup object at 0xffffb8a1f220>> raised: SyntaxError("unmatched ')'", ('/code/apps/challenges/aws_utils.py', 2220, 1, '):'))
Traceback (most recent call last):
  File "/usr/local/lib/python3.9/site-packages/celery/utils/dispatch/signal.py", line 288, in send
    response = receiver(signal=self, sender=sender, **named)
  File "/usr/local/lib/python3.9/site-packages/celery/fixups/django.py", line 84, in on_import_modules
    self.worker_fixup.validate_models()
  File "/usr/local/lib/python3.9/site-packages/celery/fixups/django.py", line 122, in validate_models
    self.django_setup()
  File "/usr/local/lib/python3.9/site-packages/celery/fixups/django.py", line 118, in django_setup
    django.setup()
  File "/usr/local/lib/python3.9/site-packages/django/__init__.py", line 24, in setup
    apps.populate(settings.INSTALLED_APPS)
  File "/usr/local/lib/python3.9/site-packages/django/apps/registry.py", line 114, in populate
    app_config.import_models()
  File "/usr/local/lib/python3.9/site-packages/django/apps/config.py", line 211, in import_models
    self.models_module = import_module(models_module_name)
  File "/usr/local/lib/python3.9/importlib/__init__.py", line 127, in import_module
    return _bootstrap._gcd_import(name[level:], package, level)
  File "<frozen importlib._bootstrap>", line 1030, in _gcd_import
  File "<frozen importlib._bootstrap>", line 1007, in _find_and_load
  File "<frozen importlib._bootstrap>", line 986, in _find_and_load_unlocked
  File "<frozen importlib._bootstrap>", line 680, in _load_unlocked
  File "<frozen importlib._bootstrap_external>", line 850, in exec_module
  File "<frozen importlib._bootstrap>", line 228, in _call_with_frames_removed
  File "/code/apps/challenges/models.py", line 489, in <module>
    post_save_connect("evaluation_script", Challenge)
  File "/code/apps/challenges/models.py", line 478, in post_save_connect
    import challenges.aws_utils as aws
  File "/code/apps/challenges/aws_utils.py", line 2220
    ):
    ^
SyntaxError: unmatched ')'
[2025-07-21 17:14:07] ERROR signal Signal handler <promise@0xffffb8a54dc0 --> <bound method Celery._autodiscover_tasks of <Celery __main__ at 0xffffb8a64d00>>> raised: SyntaxError("unmatched ')'", ('/code/apps/challenges/aws_utils.py', 2220, 1, '):'))
Traceback (most recent call last):
  File "/usr/local/lib/python3.9/site-packages/celery/utils/dispatch/signal.py", line 288, in send
    response = receiver(signal=self, sender=sender, **named)
  File "/usr/local/lib/python3.9/site-packages/vine/promises.py", line 170, in __call__
    return self.throw()
  File "/usr/local/lib/python3.9/site-packages/vine/promises.py", line 167, in __call__
    retval = fun(*final_args, **final_kwargs)
  File "/usr/local/lib/python3.9/site-packages/celery/app/base.py", line 679, in _autodiscover_tasks
    return self._autodiscover_tasks_from_names(packages, related_name)
  File "/usr/local/lib/python3.9/site-packages/celery/app/base.py", line 684, in _autodiscover_tasks_from_names
    return self.loader.autodiscover_tasks(
  File "/usr/local/lib/python3.9/site-packages/celery/loaders/base.py", line 223, in autodiscover_tasks
    mod.__name__ for mod in autodiscover_tasks(packages or (),
  File "/usr/local/lib/python3.9/site-packages/celery/loaders/base.py", line 249, in autodiscover_tasks
    return [find_related_module(pkg, related_name) for pkg in packages]
  File "/usr/local/lib/python3.9/site-packages/celery/loaders/base.py", line 249, in <listcomp>
    return [find_related_module(pkg, related_name) for pkg in packages]
  File "/usr/local/lib/python3.9/site-packages/celery/loaders/base.py", line 268, in find_related_module
    return importlib.import_module('{0}.{1}'.format(package, related_name))
  File "/usr/local/lib/python3.9/importlib/__init__.py", line 127, in import_module
    return _bootstrap._gcd_import(name[level:], package, level)
  File "<frozen importlib._bootstrap>", line 1030, in _gcd_import
  File "<frozen importlib._bootstrap>", line 1007, in _find_and_load
  File "<frozen importlib._bootstrap>", line 986, in _find_and_load_unlocked
  File "<frozen importlib._bootstrap>", line 680, in _load_unlocked
  File "<frozen importlib._bootstrap_external>", line 850, in exec_module
  File "<frozen importlib._bootstrap>", line 228, in _call_with_frames_removed
  File "/code/apps/jobs/tasks.py", line 5, in <module>
    from challenges.models import ChallengePhase
  File "/code/apps/challenges/models.py", line 489, in <module>
    post_save_connect("evaluation_script", Challenge)
  File "/code/apps/challenges/models.py", line 478, in post_save_connect
    import challenges.aws_utils as aws
  File "/code/apps/challenges/aws_utils.py", line 2220
    ):
    ^
SyntaxError: unmatched ')'
[2025-07-21 17:14:07] ERROR signal Signal handler <promise@0xffff81a24dc0 --> <bound method Celery._autodiscover_tasks of <Celery __main__ at 0xffff81a34d30>>> raised: SyntaxError("unmatched ')'", ('/code/apps/challenges/aws_utils.py', 2220, 1, '):'))
Traceback (most recent call last):
  File "/usr/local/lib/python3.9/site-packages/celery/utils/dispatch/signal.py", line 288, in send
    response = receiver(signal=self, sender=sender, **named)
  File "/usr/local/lib/python3.9/site-packages/vine/promises.py", line 170, in __call__
    return self.throw()
  File "/usr/local/lib/python3.9/site-packages/vine/promises.py", line 167, in __call__
    retval = fun(*final_args, **final_kwargs)
  File "/usr/local/lib/python3.9/site-packages/celery/app/base.py", line 679, in _autodiscover_tasks
    return self._autodiscover_tasks_from_names(packages, related_name)
  File "/usr/local/lib/python3.9/site-packages/celery/app/base.py", line 684, in _autodiscover_tasks_from_names
    return self.loader.autodiscover_tasks(
  File "/usr/local/lib/python3.9/site-packages/celery/loaders/base.py", line 223, in autodiscover_tasks
    mod.__name__ for mod in autodiscover_tasks(packages or (),
  File "/usr/local/lib/python3.9/site-packages/celery/loaders/base.py", line 249, in autodiscover_tasks
    return [find_related_module(pkg, related_name) for pkg in packages]
  File "/usr/local/lib/python3.9/site-packages/celery/loaders/base.py", line 249, in <listcomp>
    return [find_related_module(pkg, related_name) for pkg in packages]
  File "/usr/local/lib/python3.9/site-packages/celery/loaders/base.py", line 268, in find_related_module
    return importlib.import_module('{0}.{1}'.format(package, related_name))
  File "/usr/local/lib/python3.9/importlib/__init__.py", line 127, in import_module
    return _bootstrap._gcd_import(name[level:], package, level)
  File "<frozen importlib._bootstrap>", line 1030, in _gcd_import
  File "<frozen importlib._bootstrap>", line 1007, in _find_and_load
  File "<frozen importlib._bootstrap>", line 986, in _find_and_load_unlocked
  File "<frozen importlib._bootstrap>", line 680, in _load_unlocked
  File "<frozen importlib._bootstrap_external>", line 850, in exec_module
  File "<frozen importlib._bootstrap>", line 228, in _call_with_frames_removed
  File "/code/apps/jobs/tasks.py", line 5, in <module>
    from challenges.models import ChallengePhase
  File "/code/apps/challenges/models.py", line 489, in <module>
    post_save_connect("evaluation_script", Challenge)
  File "/code/apps/challenges/models.py", line 478, in post_save_connect
    import challenges.aws_utils as aws
  File "/code/apps/challenges/aws_utils.py", line 2220
    ):
    ^
SyntaxError: unmatched ')'
[2025-07-21 17:14:33] ERROR signal Signal handler <bound method DjangoFixup.on_import_modules of <celery.fixups.django.DjangoFixup object at 0xffff9075f220>> raised: SyntaxError("unmatched ')'", ('/code/apps/challenges/aws_utils.py', 2220, 1, '):'))
Traceback (most recent call last):
  File "/usr/local/lib/python3.9/site-packages/celery/utils/dispatch/signal.py", line 288, in send
    response = receiver(signal=self, sender=sender, **named)
  File "/usr/local/lib/python3.9/site-packages/celery/fixups/django.py", line 84, in on_import_modules
    self.worker_fixup.validate_models()
  File "/usr/local/lib/python3.9/site-packages/celery/fixups/django.py", line 122, in validate_models
    self.django_setup()
  File "/usr/local/lib/python3.9/site-packages/celery/fixups/django.py", line 118, in django_setup
    django.setup()
  File "/usr/local/lib/python3.9/site-packages/django/__init__.py", line 24, in setup
    apps.populate(settings.INSTALLED_APPS)
  File "/usr/local/lib/python3.9/site-packages/django/apps/registry.py", line 114, in populate
    app_config.import_models()
  File "/usr/local/lib/python3.9/site-packages/django/apps/config.py", line 211, in import_models
    self.models_module = import_module(models_module_name)
  File "/usr/local/lib/python3.9/importlib/__init__.py", line 127, in import_module
    return _bootstrap._gcd_import(name[level:], package, level)
  File "<frozen importlib._bootstrap>", line 1030, in _gcd_import
  File "<frozen importlib._bootstrap>", line 1007, in _find_and_load
  File "<frozen importlib._bootstrap>", line 986, in _find_and_load_unlocked
  File "<frozen importlib._bootstrap>", line 680, in _load_unlocked
  File "<frozen importlib._bootstrap_external>", line 850, in exec_module
  File "<frozen importlib._bootstrap>", line 228, in _call_with_frames_removed
  File "/code/apps/challenges/models.py", line 489, in <module>
    post_save_connect("evaluation_script", Challenge)
  File "/code/apps/challenges/models.py", line 478, in post_save_connect
    import challenges.aws_utils as aws
  File "/code/apps/challenges/aws_utils.py", line 2220
    ):
    ^
SyntaxError: unmatched ')'
[2025-07-21 17:14:33] ERROR signal Signal handler <bound method DjangoFixup.on_import_modules of <celery.fixups.django.DjangoFixup object at 0xffff8ad2b1c0>> raised: SyntaxError("unmatched ')'", ('/code/apps/challenges/aws_utils.py', 2220, 1, '):'))
Traceback (most recent call last):
  File "/usr/local/lib/python3.9/site-packages/celery/utils/dispatch/signal.py", line 288, in send
    response = receiver(signal=self, sender=sender, **named)
  File "/usr/local/lib/python3.9/site-packages/celery/fixups/django.py", line 84, in on_import_modules
    self.worker_fixup.validate_models()
  File "/usr/local/lib/python3.9/site-packages/celery/fixups/django.py", line 122, in validate_models
    self.django_setup()
  File "/usr/local/lib/python3.9/site-packages/celery/fixups/django.py", line 118, in django_setup
    django.setup()
  File "/usr/local/lib/python3.9/site-packages/django/__init__.py", line 24, in setup
    apps.populate(settings.INSTALLED_APPS)
  File "/usr/local/lib/python3.9/site-packages/django/apps/registry.py", line 114, in populate
    app_config.import_models()
  File "/usr/local/lib/python3.9/site-packages/django/apps/config.py", line 211, in import_models
    self.models_module = import_module(models_module_name)
  File "/usr/local/lib/python3.9/importlib/__init__.py", line 127, in import_module
    return _bootstrap._gcd_import(name[level:], package, level)
  File "<frozen importlib._bootstrap>", line 1030, in _gcd_import
  File "<frozen importlib._bootstrap>", line 1007, in _find_and_load
  File "<frozen importlib._bootstrap>", line 986, in _find_and_load_unlocked
  File "<frozen importlib._bootstrap>", line 680, in _load_unlocked
  File "<frozen importlib._bootstrap_external>", line 850, in exec_module
  File "<frozen importlib._bootstrap>", line 228, in _call_with_frames_removed
  File "/code/apps/challenges/models.py", line 489, in <module>
    post_save_connect("evaluation_script", Challenge)
  File "/code/apps/challenges/models.py", line 478, in post_save_connect
    import challenges.aws_utils as aws
  File "/code/apps/challenges/aws_utils.py", line 2220
    ):
    ^
SyntaxError: unmatched ')'
[2025-07-21 17:14:33] ERROR signal Signal handler <promise@0xffff90794dc0 --> <bound method Celery._autodiscover_tasks of <Celery __main__ at 0xffff907a4d00>>> raised: SyntaxError("unmatched ')'", ('/code/apps/challenges/aws_utils.py', 2220, 1, '):'))
Traceback (most recent call last):
  File "/usr/local/lib/python3.9/site-packages/celery/utils/dispatch/signal.py", line 288, in send
    response = receiver(signal=self, sender=sender, **named)
  File "/usr/local/lib/python3.9/site-packages/vine/promises.py", line 170, in __call__
    return self.throw()
  File "/usr/local/lib/python3.9/site-packages/vine/promises.py", line 167, in __call__
    retval = fun(*final_args, **final_kwargs)
  File "/usr/local/lib/python3.9/site-packages/celery/app/base.py", line 679, in _autodiscover_tasks
    return self._autodiscover_tasks_from_names(packages, related_name)
  File "/usr/local/lib/python3.9/site-packages/celery/app/base.py", line 684, in _autodiscover_tasks_from_names
    return self.loader.autodiscover_tasks(
  File "/usr/local/lib/python3.9/site-packages/celery/loaders/base.py", line 223, in autodiscover_tasks
    mod.__name__ for mod in autodiscover_tasks(packages or (),
  File "/usr/local/lib/python3.9/site-packages/celery/loaders/base.py", line 249, in autodiscover_tasks
    return [find_related_module(pkg, related_name) for pkg in packages]
  File "/usr/local/lib/python3.9/site-packages/celery/loaders/base.py", line 249, in <listcomp>
    return [find_related_module(pkg, related_name) for pkg in packages]
  File "/usr/local/lib/python3.9/site-packages/celery/loaders/base.py", line 268, in find_related_module
    return importlib.import_module('{0}.{1}'.format(package, related_name))
  File "/usr/local/lib/python3.9/importlib/__init__.py", line 127, in import_module
    return _bootstrap._gcd_import(name[level:], package, level)
  File "<frozen importlib._bootstrap>", line 1030, in _gcd_import
  File "<frozen importlib._bootstrap>", line 1007, in _find_and_load
  File "<frozen importlib._bootstrap>", line 986, in _find_and_load_unlocked
  File "<frozen importlib._bootstrap>", line 680, in _load_unlocked
  File "<frozen importlib._bootstrap_external>", line 850, in exec_module
  File "<frozen importlib._bootstrap>", line 228, in _call_with_frames_removed
  File "/code/apps/jobs/tasks.py", line 5, in <module>
    from challenges.models import ChallengePhase
  File "/code/apps/challenges/models.py", line 489, in <module>
    post_save_connect("evaluation_script", Challenge)
  File "/code/apps/challenges/models.py", line 478, in post_save_connect
    import challenges.aws_utils as aws
  File "/code/apps/challenges/aws_utils.py", line 2220
    ):
    ^
SyntaxError: unmatched ')'
[2025-07-21 17:14:33] ERROR signal Signal handler <promise@0xffff8ad64dc0 --> <bound method Celery._autodiscover_tasks of <Celery __main__ at 0xffff8ad74d60>>> raised: SyntaxError("unmatched ')'", ('/code/apps/challenges/aws_utils.py', 2220, 1, '):'))
Traceback (most recent call last):
  File "/usr/local/lib/python3.9/site-packages/celery/utils/dispatch/signal.py", line 288, in send
    response = receiver(signal=self, sender=sender, **named)
  File "/usr/local/lib/python3.9/site-packages/vine/promises.py", line 170, in __call__
    return self.throw()
  File "/usr/local/lib/python3.9/site-packages/vine/promises.py", line 167, in __call__
    retval = fun(*final_args, **final_kwargs)
  File "/usr/local/lib/python3.9/site-packages/celery/app/base.py", line 679, in _autodiscover_tasks
    return self._autodiscover_tasks_from_names(packages, related_name)
  File "/usr/local/lib/python3.9/site-packages/celery/app/base.py", line 684, in _autodiscover_tasks_from_names
    return self.loader.autodiscover_tasks(
  File "/usr/local/lib/python3.9/site-packages/celery/loaders/base.py", line 223, in autodiscover_tasks
    mod.__name__ for mod in autodiscover_tasks(packages or (),
  File "/usr/local/lib/python3.9/site-packages/celery/loaders/base.py", line 249, in autodiscover_tasks
    return [find_related_module(pkg, related_name) for pkg in packages]
  File "/usr/local/lib/python3.9/site-packages/celery/loaders/base.py", line 249, in <listcomp>
    return [find_related_module(pkg, related_name) for pkg in packages]
  File "/usr/local/lib/python3.9/site-packages/celery/loaders/base.py", line 268, in find_related_module
    return importlib.import_module('{0}.{1}'.format(package, related_name))
  File "/usr/local/lib/python3.9/importlib/__init__.py", line 127, in import_module
    return _bootstrap._gcd_import(name[level:], package, level)
  File "<frozen importlib._bootstrap>", line 1030, in _gcd_import
  File "<frozen importlib._bootstrap>", line 1007, in _find_and_load
  File "<frozen importlib._bootstrap>", line 986, in _find_and_load_unlocked
  File "<frozen importlib._bootstrap>", line 680, in _load_unlocked
  File "<frozen importlib._bootstrap_external>", line 850, in exec_module
  File "<frozen importlib._bootstrap>", line 228, in _call_with_frames_removed
  File "/code/apps/jobs/tasks.py", line 5, in <module>
    from challenges.models import ChallengePhase
  File "/code/apps/challenges/models.py", line 489, in <module>
    post_save_connect("evaluation_script", Challenge)
  File "/code/apps/challenges/models.py", line 478, in post_save_connect
    import challenges.aws_utils as aws
  File "/code/apps/challenges/aws_utils.py", line 2220
    ):
    ^
SyntaxError: unmatched ')'
[2025-07-21 17:15:25] ERROR signal Signal handler <bound method DjangoFixup.on_import_modules of <celery.fixups.django.DjangoFixup object at 0xffff8796f220>> raised: SyntaxError("unmatched ')'", ('/code/apps/challenges/aws_utils.py', 2220, 1, '):'))
Traceback (most recent call last):
  File "/usr/local/lib/python3.9/site-packages/celery/utils/dispatch/signal.py", line 288, in send
    response = receiver(signal=self, sender=sender, **named)
  File "/usr/local/lib/python3.9/site-packages/celery/fixups/django.py", line 84, in on_import_modules
    self.worker_fixup.validate_models()
  File "/usr/local/lib/python3.9/site-packages/celery/fixups/django.py", line 122, in validate_models
    self.django_setup()
  File "/usr/local/lib/python3.9/site-packages/celery/fixups/django.py", line 118, in django_setup
    django.setup()
  File "/usr/local/lib/python3.9/site-packages/django/__init__.py", line 24, in setup
    apps.populate(settings.INSTALLED_APPS)
  File "/usr/local/lib/python3.9/site-packages/django/apps/registry.py", line 114, in populate
    app_config.import_models()
  File "/usr/local/lib/python3.9/site-packages/django/apps/config.py", line 211, in import_models
    self.models_module = import_module(models_module_name)
  File "/usr/local/lib/python3.9/importlib/__init__.py", line 127, in import_module
    return _bootstrap._gcd_import(name[level:], package, level)
  File "<frozen importlib._bootstrap>", line 1030, in _gcd_import
  File "<frozen importlib._bootstrap>", line 1007, in _find_and_load
  File "<frozen importlib._bootstrap>", line 986, in _find_and_load_unlocked
  File "<frozen importlib._bootstrap>", line 680, in _load_unlocked
  File "<frozen importlib._bootstrap_external>", line 850, in exec_module
  File "<frozen importlib._bootstrap>", line 228, in _call_with_frames_removed
  File "/code/apps/challenges/models.py", line 489, in <module>
    post_save_connect("evaluation_script", Challenge)
  File "/code/apps/challenges/models.py", line 478, in post_save_connect
    import challenges.aws_utils as aws
  File "/code/apps/challenges/aws_utils.py", line 2220
    ):
    ^
SyntaxError: unmatched ')'
[2025-07-21 17:15:25] ERROR signal Signal handler <bound method DjangoFixup.on_import_modules of <celery.fixups.django.DjangoFixup object at 0xffff8168c1c0>> raised: SyntaxError("unmatched ')'", ('/code/apps/challenges/aws_utils.py', 2220, 1, '):'))
Traceback (most recent call last):
  File "/usr/local/lib/python3.9/site-packages/celery/utils/dispatch/signal.py", line 288, in send
    response = receiver(signal=self, sender=sender, **named)
  File "/usr/local/lib/python3.9/site-packages/celery/fixups/django.py", line 84, in on_import_modules
    self.worker_fixup.validate_models()
  File "/usr/local/lib/python3.9/site-packages/celery/fixups/django.py", line 122, in validate_models
    self.django_setup()
  File "/usr/local/lib/python3.9/site-packages/celery/fixups/django.py", line 118, in django_setup
    django.setup()
  File "/usr/local/lib/python3.9/site-packages/django/__init__.py", line 24, in setup
    apps.populate(settings.INSTALLED_APPS)
  File "/usr/local/lib/python3.9/site-packages/django/apps/registry.py", line 114, in populate
    app_config.import_models()
  File "/usr/local/lib/python3.9/site-packages/django/apps/config.py", line 211, in import_models
    self.models_module = import_module(models_module_name)
  File "/usr/local/lib/python3.9/importlib/__init__.py", line 127, in import_module
    return _bootstrap._gcd_import(name[level:], package, level)
  File "<frozen importlib._bootstrap>", line 1030, in _gcd_import
  File "<frozen importlib._bootstrap>", line 1007, in _find_and_load
  File "<frozen importlib._bootstrap>", line 986, in _find_and_load_unlocked
  File "<frozen importlib._bootstrap>", line 680, in _load_unlocked
  File "<frozen importlib._bootstrap_external>", line 850, in exec_module
  File "<frozen importlib._bootstrap>", line 228, in _call_with_frames_removed
  File "/code/apps/challenges/models.py", line 489, in <module>
    post_save_connect("evaluation_script", Challenge)
  File "/code/apps/challenges/models.py", line 478, in post_save_connect
    import challenges.aws_utils as aws
  File "/code/apps/challenges/aws_utils.py", line 2220
    ):
    ^
SyntaxError: unmatched ')'
[2025-07-21 17:15:25] ERROR signal Signal handler <promise@0xffff879a4dc0 --> <bound method Celery._autodiscover_tasks of <Celery __main__ at 0xffff879b4d00>>> raised: SyntaxError("unmatched ')'", ('/code/apps/challenges/aws_utils.py', 2220, 1, '):'))
Traceback (most recent call last):
  File "/usr/local/lib/python3.9/site-packages/celery/utils/dispatch/signal.py", line 288, in send
    response = receiver(signal=self, sender=sender, **named)
  File "/usr/local/lib/python3.9/site-packages/vine/promises.py", line 170, in __call__
    return self.throw()
  File "/usr/local/lib/python3.9/site-packages/vine/promises.py", line 167, in __call__
    retval = fun(*final_args, **final_kwargs)
  File "/usr/local/lib/python3.9/site-packages/celery/app/base.py", line 679, in _autodiscover_tasks
    return self._autodiscover_tasks_from_names(packages, related_name)
  File "/usr/local/lib/python3.9/site-packages/celery/app/base.py", line 684, in _autodiscover_tasks_from_names
    return self.loader.autodiscover_tasks(
  File "/usr/local/lib/python3.9/site-packages/celery/loaders/base.py", line 223, in autodiscover_tasks
    mod.__name__ for mod in autodiscover_tasks(packages or (),
  File "/usr/local/lib/python3.9/site-packages/celery/loaders/base.py", line 249, in autodiscover_tasks
    return [find_related_module(pkg, related_name) for pkg in packages]
  File "/usr/local/lib/python3.9/site-packages/celery/loaders/base.py", line 249, in <listcomp>
    return [find_related_module(pkg, related_name) for pkg in packages]
  File "/usr/local/lib/python3.9/site-packages/celery/loaders/base.py", line 268, in find_related_module
    return importlib.import_module('{0}.{1}'.format(package, related_name))
  File "/usr/local/lib/python3.9/importlib/__init__.py", line 127, in import_module
    return _bootstrap._gcd_import(name[level:], package, level)
  File "<frozen importlib._bootstrap>", line 1030, in _gcd_import
  File "<frozen importlib._bootstrap>", line 1007, in _find_and_load
  File "<frozen importlib._bootstrap>", line 986, in _find_and_load_unlocked
  File "<frozen importlib._bootstrap>", line 680, in _load_unlocked
  File "<frozen importlib._bootstrap_external>", line 850, in exec_module
  File "<frozen importlib._bootstrap>", line 228, in _call_with_frames_removed
  File "/code/apps/jobs/tasks.py", line 5, in <module>
    from challenges.models import ChallengePhase
  File "/code/apps/challenges/models.py", line 489, in <module>
    post_save_connect("evaluation_script", Challenge)
  File "/code/apps/challenges/models.py", line 478, in post_save_connect
    import challenges.aws_utils as aws
  File "/code/apps/challenges/aws_utils.py", line 2220
    ):
    ^
SyntaxError: unmatched ')'
[2025-07-21 17:15:25] ERROR signal Signal handler <promise@0xffff816c4dc0 --> <bound method Celery._autodiscover_tasks of <Celery __main__ at 0xffff816d4d60>>> raised: SyntaxError("unmatched ')'", ('/code/apps/challenges/aws_utils.py', 2220, 1, '):'))
Traceback (most recent call last):
  File "/usr/local/lib/python3.9/site-packages/celery/utils/dispatch/signal.py", line 288, in send
    response = receiver(signal=self, sender=sender, **named)
  File "/usr/local/lib/python3.9/site-packages/vine/promises.py", line 170, in __call__
    return self.throw()
  File "/usr/local/lib/python3.9/site-packages/vine/promises.py", line 167, in __call__
    retval = fun(*final_args, **final_kwargs)
  File "/usr/local/lib/python3.9/site-packages/celery/app/base.py", line 679, in _autodiscover_tasks
    return self._autodiscover_tasks_from_names(packages, related_name)
  File "/usr/local/lib/python3.9/site-packages/celery/app/base.py", line 684, in _autodiscover_tasks_from_names
    return self.loader.autodiscover_tasks(
  File "/usr/local/lib/python3.9/site-packages/celery/loaders/base.py", line 223, in autodiscover_tasks
    mod.__name__ for mod in autodiscover_tasks(packages or (),
  File "/usr/local/lib/python3.9/site-packages/celery/loaders/base.py", line 249, in autodiscover_tasks
    return [find_related_module(pkg, related_name) for pkg in packages]
  File "/usr/local/lib/python3.9/site-packages/celery/loaders/base.py", line 249, in <listcomp>
    return [find_related_module(pkg, related_name) for pkg in packages]
  File "/usr/local/lib/python3.9/site-packages/celery/loaders/base.py", line 268, in find_related_module
    return importlib.import_module('{0}.{1}'.format(package, related_name))
  File "/usr/local/lib/python3.9/importlib/__init__.py", line 127, in import_module
    return _bootstrap._gcd_import(name[level:], package, level)
  File "<frozen importlib._bootstrap>", line 1030, in _gcd_import
  File "<frozen importlib._bootstrap>", line 1007, in _find_and_load
  File "<frozen importlib._bootstrap>", line 986, in _find_and_load_unlocked
  File "<frozen importlib._bootstrap>", line 680, in _load_unlocked
  File "<frozen importlib._bootstrap_external>", line 850, in exec_module
  File "<frozen importlib._bootstrap>", line 228, in _call_with_frames_removed
  File "/code/apps/jobs/tasks.py", line 5, in <module>
    from challenges.models import ChallengePhase
  File "/code/apps/challenges/models.py", line 489, in <module>
    post_save_connect("evaluation_script", Challenge)
  File "/code/apps/challenges/models.py", line 478, in post_save_connect
    import challenges.aws_utils as aws
  File "/code/apps/challenges/aws_utils.py", line 2220
    ):
    ^
SyntaxError: unmatched ')'
[2025-07-21 17:17:42] ERROR aws_utils An error occurred (Unknown) when calling the DeregisterTaskDefinition operation: Scaling inactive workers not supported
Traceback (most recent call last):
  File "/code/apps/challenges/aws_utils.py", line 1040, in scale_resources
    response = client.deregister_task_definition(
  File "/usr/local/lib/python3.9/unittest/mock.py", line 1092, in __call__
    return self._mock_call(*args, **kwargs)
  File "/usr/local/lib/python3.9/unittest/mock.py", line 1096, in _mock_call
    return self._execute_mock_call(*args, **kwargs)
  File "/usr/local/lib/python3.9/unittest/mock.py", line 1151, in _execute_mock_call
    raise effect
botocore.exceptions.ClientError: An error occurred (Unknown) when calling the DeregisterTaskDefinition operation: Scaling inactive workers not supported
[2025-07-21 17:17:42] ERROR aws_utils Failed to set log retention for challenge 123
Traceback (most recent call last):
  File "/code/apps/challenges/aws_utils.py", line 1910, in set_cloudwatch_log_retention
    challenge = Challenge.objects.get(pk=challenge_pk)
  File "/usr/local/lib/python3.9/site-packages/django/db/models/manager.py", line 82, in manager_method
    return getattr(self.get_queryset(), name)(*args, **kwargs)
  File "/usr/local/lib/python3.9/site-packages/django/db/models/query.py", line 406, in get
    raise self.model.DoesNotExist(
challenges.models.Challenge.DoesNotExist: Challenge matching query does not exist.
[2025-07-21 17:17:42] WARNING aws_utils Failed to update log retention for challenge 123: Challenge matching query does not exist.
[2025-07-21 17:17:42] ERROR aws_utils An error occurred (Unknown) when calling the RegisterTaskDefinition operation: Failed to register task definition
Traceback (most recent call last):
  File "/code/apps/challenges/aws_utils.py", line 1081, in scale_resources
    response = client.register_task_definition(**task_def)
  File "/usr/local/lib/python3.9/unittest/mock.py", line 1092, in __call__
    return self._mock_call(*args, **kwargs)
  File "/usr/local/lib/python3.9/unittest/mock.py", line 1096, in _mock_call
    return self._execute_mock_call(*args, **kwargs)
  File "/usr/local/lib/python3.9/unittest/mock.py", line 1151, in _execute_mock_call
    raise effect
botocore.exceptions.ClientError: An error occurred (Unknown) when calling the RegisterTaskDefinition operation: Failed to register task definition
[2025-07-21 17:17:42] ERROR aws_utils Failed to set log retention for challenge 123
Traceback (most recent call last):
  File "/code/apps/challenges/aws_utils.py", line 1910, in set_cloudwatch_log_retention
    challenge = Challenge.objects.get(pk=challenge_pk)
  File "/usr/local/lib/python3.9/site-packages/django/db/models/manager.py", line 82, in manager_method
    return getattr(self.get_queryset(), name)(*args, **kwargs)
  File "/usr/local/lib/python3.9/site-packages/django/db/models/query.py", line 406, in get
    raise self.model.DoesNotExist(
challenges.models.Challenge.DoesNotExist: Challenge matching query does not exist.
[2025-07-21 17:17:42] WARNING aws_utils Failed to update log retention for challenge 123: Challenge matching query does not exist.
[2025-07-21 17:17:43] INFO aws_utils Set CloudWatch log retention for challenge 123 to 30 days
[2025-07-21 17:17:43] INFO aws_utils Set CloudWatch log retention for challenge 123 to 90 days
[2025-07-21 17:17:43] ERROR aws_utils Failed to set log retention for challenge 123
Traceback (most recent call last):
  File "/code/apps/challenges/aws_utils.py", line 1930, in set_cloudwatch_log_retention
    logs_client.put_retention_policy(logGroupName=log_group_name, retentionInDays=aws_retention_days)
  File "/usr/local/lib/python3.9/unittest/mock.py", line 1092, in __call__
    return self._mock_call(*args, **kwargs)
  File "/usr/local/lib/python3.9/unittest/mock.py", line 1096, in _mock_call
    return self._execute_mock_call(*args, **kwargs)
  File "/usr/local/lib/python3.9/unittest/mock.py", line 1151, in _execute_mock_call
    raise effect
botocore.exceptions.ClientError: An error occurred (ResourceNotFoundException) when calling the PutRetentionPolicy operation: Log group not found
[2025-07-21 17:17:43] INFO aws_utils Set CloudWatch log retention for challenge 123 to 30 days
[2025-07-21 17:17:43] INFO aws_utils Starting cleanup of expired submission artifacts
[2025-07-21 17:17:43] INFO aws_utils Cleanup completed: 0 successful, 0 failed
[2025-07-21 17:17:43] INFO aws_utils Updated log retention for challenge 123
[2025-07-21 17:17:43] ERROR aws_utils Failed to send email to test@example.com
Traceback (most recent call last):
  File "/code/apps/challenges/aws_utils.py", line 2061, in send_template_email
    html_message = render_to_string(template_name, template_context)
  File "/usr/local/lib/python3.9/site-packages/django/template/loader.py", line 61, in render_to_string
    template = get_template(template_name, using=using)
  File "/usr/local/lib/python3.9/site-packages/django/template/loader.py", line 19, in get_template
    raise TemplateDoesNotExist(template_name, chain=chain)
django.template.exceptions.TemplateDoesNotExist: test_template.html
[2025-07-21 17:17:43] ERROR aws_utils Failed to send email to test@example.com
Traceback (most recent call last):
  File "/code/apps/challenges/aws_utils.py", line 2061, in send_template_email
    html_message = render_to_string(template_name, template_context)
  File "/usr/local/lib/python3.9/site-packages/django/template/loader.py", line 61, in render_to_string
    template = get_template(template_name, using=using)
  File "/usr/local/lib/python3.9/site-packages/django/template/loader.py", line 19, in get_template
    raise TemplateDoesNotExist(template_name, chain=chain)
django.template.exceptions.TemplateDoesNotExist: test_template.html
[2025-07-21 17:17:43] INFO aws_utils Starting cleanup of expired submission artifacts
[2025-07-21 17:17:43] INFO aws_utils Cleanup completed: 1 successful, 0 failed
[2025-07-21 17:17:43] INFO aws_utils Starting cleanup of expired submission artifacts
[2025-07-21 17:17:43] INFO aws_utils No submissions eligible for cleanup
[2025-07-21 17:17:43] INFO aws_utils Starting cleanup of expired submission artifacts
[2025-07-21 17:17:43] INFO aws_utils Cleanup completed: 1 successful, 0 failed
[2025-07-21 17:17:43] INFO aws_utils Processing retention notifications and consent logging
[2025-07-21 17:17:43] INFO aws_utils Processing retention notifications and consent logging
[2025-07-21 17:17:43] INFO aws_utils Processing retention notifications and consent logging
[2025-07-21 17:17:44] INFO aws_utils Processing retention notifications and consent logging
[2025-07-21 17:17:44] INFO aws_utils Retention policy consent recorded for challenge 14 by user testuser
[2025-07-21 17:17:44] INFO aws_utils Updated log retention for challenge 20
[2025-07-21 17:17:44] INFO aws_utils Updated log retention for challenge 21
[2025-07-21 17:17:44] INFO aws_utils Updated log retention for challenge 22
[2025-07-21 17:17:44] INFO aws_utils Deleted submission artifacts for submission 7
[2025-07-21 17:17:44] INFO aws_utils Deleted submission artifacts for submission 8
[2025-07-21 17:17:44] ERROR aws_utils An error occurred (SomeError) when calling the CreateService operation: Unknown
Traceback (most recent call last):
  File "/code/apps/challenges/aws_utils.py", line 367, in create_service_by_challenge_pk
    response = client.create_service(**definition)
  File "/usr/local/lib/python3.9/unittest/mock.py", line 1092, in __call__
    return self._mock_call(*args, **kwargs)
  File "/usr/local/lib/python3.9/unittest/mock.py", line 1096, in _mock_call
    return self._execute_mock_call(*args, **kwargs)
  File "/usr/local/lib/python3.9/unittest/mock.py", line 1151, in _execute_mock_call
    raise effect
botocore.exceptions.ClientError: An error occurred (SomeError) when calling the CreateService operation: Unknown
