[2025-07-09 21:15:21] WARNING aws_utils Worker(s) for challenge 134 couldn't restart! Error: Please select challenges with active workers only.
[2025-07-09 21:15:21] INFO aws_utils The worker service for challenge 135 was restarted, as evaluation_script was changed.
[2025-07-09 21:15:21] WARNING aws_utils Worker(s) for challenge 135 couldn't restart! Error: Please select challenges with active workers only.
[2025-07-09 21:15:21] INFO aws_utils The worker service for challenge 136 was restarted, as evaluation_script was changed.
[2025-07-09 21:15:21] WARNING aws_utils Worker(s) for challenge 136 couldn't restart! Error: Please select challenges with active workers only.
[2025-07-09 21:15:21] INFO aws_utils The worker service for challenge 137 was restarted, as evaluation_script was changed.
[2025-07-09 21:15:21] WARNING aws_utils Worker(s) for challenge 137 couldn't restart! Error: Please select challenges with active workers only.
[2025-07-09 21:15:21] INFO aws_utils The worker service for challenge 138 was restarted, as evaluation_script was changed.
[2025-07-09 21:15:21] WARNING aws_utils Worker(s) for challenge 138 couldn't restart! Error: Please select challenges with active workers only.
[2025-07-09 21:15:25] INFO aws_utils The worker service for challenge 322 was restarted, as test_annotation was changed.
[2025-07-09 21:15:25] WARNING aws_utils Worker(s) for challenge 322 couldn't restart! Error: Please select challenges with active workers only.
[2025-07-09 21:15:43] ERROR aws_utils An error occurred (SomeError) when calling the CreateService operation: Unknown
Traceback (most recent call last):
  File "/code/apps/challenges/aws_utils.py", line 365, in create_service_by_challenge_pk
    response = client.create_service(**definition)
  File "/usr/local/lib/python3.9/unittest/mock.py", line 1092, in __call__
    return self._mock_call(*args, **kwargs)
  File "/usr/local/lib/python3.9/unittest/mock.py", line 1096, in _mock_call
    return self._execute_mock_call(*args, **kwargs)
  File "/usr/local/lib/python3.9/unittest/mock.py", line 1151, in _execute_mock_call
    raise effect
botocore.exceptions.ClientError: An error occurred (SomeError) when calling the CreateService operation: Unknown
[2025-07-09 21:15:43] ERROR aws_utils An error occurred (ServiceError) when calling the UpdateService operation: Unknown
Traceback (most recent call last):
  File "/code/apps/challenges/aws_utils.py", line 414, in update_service_by_challenge_pk
    response = client.update_service(**kwargs)
  File "/usr/local/lib/python3.9/unittest/mock.py", line 1092, in __call__
    return self._mock_call(*args, **kwargs)
  File "/usr/local/lib/python3.9/unittest/mock.py", line 1096, in _mock_call
    return self._execute_mock_call(*args, **kwargs)
  File "/usr/local/lib/python3.9/unittest/mock.py", line 1151, in _execute_mock_call
    raise effect
botocore.exceptions.ClientError: An error occurred (ServiceError) when calling the UpdateService operation: Unknown
[2025-07-09 21:15:43] ERROR aws_utils An error occurred (DeregisterError) when calling the DeregisterTaskDefinition operation: Unknown
Traceback (most recent call last):
  File "/code/apps/challenges/aws_utils.py", line 459, in delete_service_by_challenge_pk
    client.deregister_task_definition(
  File "/usr/local/lib/python3.9/unittest/mock.py", line 1092, in __call__
    return self._mock_call(*args, **kwargs)
  File "/usr/local/lib/python3.9/unittest/mock.py", line 1096, in _mock_call
    return self._execute_mock_call(*args, **kwargs)
  File "/usr/local/lib/python3.9/unittest/mock.py", line 1151, in _execute_mock_call
    raise effect
botocore.exceptions.ClientError: An error occurred (DeregisterError) when calling the DeregisterTaskDefinition operation: Unknown
[2025-07-09 21:15:43] ERROR aws_utils An error occurred (DeleteServiceError) when calling the DeleteService operation: Unknown
Traceback (most recent call last):
  File "/code/apps/challenges/aws_utils.py", line 455, in delete_service_by_challenge_pk
    response = client.delete_service(**kwargs)
  File "/usr/local/lib/python3.9/unittest/mock.py", line 1092, in __call__
    return self._mock_call(*args, **kwargs)
  File "/usr/local/lib/python3.9/unittest/mock.py", line 1096, in _mock_call
    return self._execute_mock_call(*args, **kwargs)
  File "/usr/local/lib/python3.9/unittest/mock.py", line 1151, in _execute_mock_call
    raise effect
botocore.exceptions.ClientError: An error occurred (DeleteServiceError) when calling the DeleteService operation: Unknown
[2025-07-09 21:15:43] ERROR aws_utils An error occurred (Unknown) when calling the DeregisterTaskDefinition operation: Scaling inactive workers not supported
Traceback (most recent call last):
  File "/code/apps/challenges/aws_utils.py", line 1038, in scale_resources
    response = client.deregister_task_definition(
  File "/usr/local/lib/python3.9/unittest/mock.py", line 1092, in __call__
    return self._mock_call(*args, **kwargs)
  File "/usr/local/lib/python3.9/unittest/mock.py", line 1096, in _mock_call
    return self._execute_mock_call(*args, **kwargs)
  File "/usr/local/lib/python3.9/unittest/mock.py", line 1151, in _execute_mock_call
    raise effect
botocore.exceptions.ClientError: An error occurred (Unknown) when calling the DeregisterTaskDefinition operation: Scaling inactive workers not supported
[2025-07-10 06:11:43] INFO aws_utils Updated log retention for approved challenge 126
[2025-07-10 06:11:47] ERROR aws_utils Failed to set log retention for challenge 128
Traceback (most recent call last):
  File "/code/apps/challenges/aws_utils.py", line 2006, in set_cloudwatch_log_retention
    logs_client.put_retention_policy(
  File "/usr/local/lib/python3.9/site-packages/botocore/client.py", line 535, in _api_call
    return self._make_api_call(operation_name, kwargs)
  File "/usr/local/lib/python3.9/site-packages/botocore/client.py", line 980, in _make_api_call
    raise error_class(parsed_response, operation_name)
botocore.errorfactory.UnrecognizedClientException: An error occurred (UnrecognizedClientException) when calling the PutRetentionPolicy operation: The security token included in the request is invalid.
[2025-07-10 06:11:47] WARNING aws_utils Failed to update log retention for challenge 128: An error occurred (UnrecognizedClientException) when calling the PutRetentionPolicy operation: The security token included in the request is invalid.
[2025-07-10 06:11:47] INFO aws_utils The worker service for challenge 130 was restarted, as evaluation_script was changed.
[2025-07-10 06:11:47] WARNING aws_utils Worker(s) for challenge 130 couldn't restart! Error: Please select challenges with active workers only.
[2025-07-10 06:11:47] INFO aws_utils The worker service for challenge 131 was restarted, as evaluation_script was changed.
[2025-07-10 06:11:47] WARNING aws_utils Worker(s) for challenge 131 couldn't restart! Error: Please select challenges with active workers only.
[2025-07-10 06:11:47] INFO aws_utils The worker service for challenge 132 was restarted, as evaluation_script was changed.
[2025-07-10 06:11:47] WARNING aws_utils Worker(s) for challenge 132 couldn't restart! Error: Please select challenges with active workers only.
[2025-07-10 06:11:47] INFO aws_utils The worker service for challenge 133 was restarted, as evaluation_script was changed.
[2025-07-10 06:11:47] WARNING aws_utils Worker(s) for challenge 133 couldn't restart! Error: Please select challenges with active workers only.
[2025-07-10 06:11:47] INFO aws_utils The worker service for challenge 133 was restarted, as evaluation_script was changed.
[2025-07-10 06:11:47] WARNING aws_utils Worker(s) for challenge 133 couldn't restart! Error: Please select challenges with active workers only.
[2025-07-10 06:11:47] INFO aws_utils The worker service for challenge 134 was restarted, as evaluation_script was changed.
[2025-07-10 06:11:47] WARNING aws_utils Worker(s) for challenge 134 couldn't restart! Error: Please select challenges with active workers only.
[2025-07-10 06:11:47] INFO aws_utils The worker service for challenge 135 was restarted, as evaluation_script was changed.
[2025-07-10 06:11:47] WARNING aws_utils Worker(s) for challenge 135 couldn't restart! Error: Please select challenges with active workers only.
[2025-07-10 06:11:47] INFO aws_utils The worker service for challenge 136 was restarted, as evaluation_script was changed.
[2025-07-10 06:11:47] WARNING aws_utils Worker(s) for challenge 136 couldn't restart! Error: Please select challenges with active workers only.
[2025-07-10 06:11:47] INFO aws_utils The worker service for challenge 137 was restarted, as evaluation_script was changed.
[2025-07-10 06:11:47] WARNING aws_utils Worker(s) for challenge 137 couldn't restart! Error: Please select challenges with active workers only.
[2025-07-10 06:11:47] INFO aws_utils The worker service for challenge 138 was restarted, as evaluation_script was changed.
[2025-07-10 06:11:47] WARNING aws_utils Worker(s) for challenge 138 couldn't restart! Error: Please select challenges with active workers only.
[2025-07-10 06:11:51] INFO aws_utils The worker service for challenge 322 was restarted, as test_annotation was changed.
[2025-07-10 06:11:51] WARNING aws_utils Worker(s) for challenge 322 couldn't restart! Error: Please select challenges with active workers only.
[2025-07-10 06:12:11] ERROR aws_utils An error occurred (SomeError) when calling the CreateService operation: Unknown
Traceback (most recent call last):
  File "/code/apps/challenges/aws_utils.py", line 365, in create_service_by_challenge_pk
    response = client.create_service(**definition)
  File "/usr/local/lib/python3.9/unittest/mock.py", line 1092, in __call__
    return self._mock_call(*args, **kwargs)
  File "/usr/local/lib/python3.9/unittest/mock.py", line 1096, in _mock_call
    return self._execute_mock_call(*args, **kwargs)
  File "/usr/local/lib/python3.9/unittest/mock.py", line 1151, in _execute_mock_call
    raise effect
botocore.exceptions.ClientError: An error occurred (SomeError) when calling the CreateService operation: Unknown
[2025-07-10 06:12:11] ERROR aws_utils An error occurred (ServiceError) when calling the UpdateService operation: Unknown
Traceback (most recent call last):
  File "/code/apps/challenges/aws_utils.py", line 414, in update_service_by_challenge_pk
    response = client.update_service(**kwargs)
  File "/usr/local/lib/python3.9/unittest/mock.py", line 1092, in __call__
    return self._mock_call(*args, **kwargs)
  File "/usr/local/lib/python3.9/unittest/mock.py", line 1096, in _mock_call
    return self._execute_mock_call(*args, **kwargs)
  File "/usr/local/lib/python3.9/unittest/mock.py", line 1151, in _execute_mock_call
    raise effect
botocore.exceptions.ClientError: An error occurred (ServiceError) when calling the UpdateService operation: Unknown
[2025-07-10 06:12:11] ERROR aws_utils An error occurred (DeregisterError) when calling the DeregisterTaskDefinition operation: Unknown
Traceback (most recent call last):
  File "/code/apps/challenges/aws_utils.py", line 459, in delete_service_by_challenge_pk
    client.deregister_task_definition(
  File "/usr/local/lib/python3.9/unittest/mock.py", line 1092, in __call__
    return self._mock_call(*args, **kwargs)
  File "/usr/local/lib/python3.9/unittest/mock.py", line 1096, in _mock_call
    return self._execute_mock_call(*args, **kwargs)
  File "/usr/local/lib/python3.9/unittest/mock.py", line 1151, in _execute_mock_call
    raise effect
botocore.exceptions.ClientError: An error occurred (DeregisterError) when calling the DeregisterTaskDefinition operation: Unknown
[2025-07-10 06:12:11] ERROR aws_utils An error occurred (DeleteServiceError) when calling the DeleteService operation: Unknown
Traceback (most recent call last):
  File "/code/apps/challenges/aws_utils.py", line 455, in delete_service_by_challenge_pk
    response = client.delete_service(**kwargs)
  File "/usr/local/lib/python3.9/unittest/mock.py", line 1092, in __call__
    return self._mock_call(*args, **kwargs)
  File "/usr/local/lib/python3.9/unittest/mock.py", line 1096, in _mock_call
    return self._execute_mock_call(*args, **kwargs)
  File "/usr/local/lib/python3.9/unittest/mock.py", line 1151, in _execute_mock_call
    raise effect
botocore.exceptions.ClientError: An error occurred (DeleteServiceError) when calling the DeleteService operation: Unknown
[2025-07-10 06:12:11] ERROR aws_utils An error occurred (Unknown) when calling the DeregisterTaskDefinition operation: Scaling inactive workers not supported
Traceback (most recent call last):
  File "/code/apps/challenges/aws_utils.py", line 1038, in scale_resources
    response = client.deregister_task_definition(
  File "/usr/local/lib/python3.9/unittest/mock.py", line 1092, in __call__
    return self._mock_call(*args, **kwargs)
  File "/usr/local/lib/python3.9/unittest/mock.py", line 1096, in _mock_call
    return self._execute_mock_call(*args, **kwargs)
  File "/usr/local/lib/python3.9/unittest/mock.py", line 1151, in _execute_mock_call
    raise effect
botocore.exceptions.ClientError: An error occurred (Unknown) when calling the DeregisterTaskDefinition operation: Scaling inactive workers not supported
[2025-07-10 06:17:13] INFO aws_utils Updated log retention for approved challenge 126
[2025-07-10 06:17:17] ERROR aws_utils Failed to set log retention for challenge 128
Traceback (most recent call last):
  File "/code/apps/challenges/aws_utils.py", line 2006, in set_cloudwatch_log_retention
    logs_client.put_retention_policy(
  File "/usr/local/lib/python3.9/site-packages/botocore/client.py", line 535, in _api_call
    return self._make_api_call(operation_name, kwargs)
  File "/usr/local/lib/python3.9/site-packages/botocore/client.py", line 980, in _make_api_call
    raise error_class(parsed_response, operation_name)
botocore.errorfactory.UnrecognizedClientException: An error occurred (UnrecognizedClientException) when calling the PutRetentionPolicy operation: The security token included in the request is invalid.
[2025-07-10 06:17:17] WARNING aws_utils Failed to update log retention for challenge 128: An error occurred (UnrecognizedClientException) when calling the PutRetentionPolicy operation: The security token included in the request is invalid.
[2025-07-10 06:17:17] INFO aws_utils The worker service for challenge 130 was restarted, as evaluation_script was changed.
[2025-07-10 06:17:17] WARNING aws_utils Worker(s) for challenge 130 couldn't restart! Error: Please select challenges with active workers only.
[2025-07-10 06:17:17] INFO aws_utils The worker service for challenge 131 was restarted, as evaluation_script was changed.
[2025-07-10 06:17:17] WARNING aws_utils Worker(s) for challenge 131 couldn't restart! Error: Please select challenges with active workers only.
[2025-07-10 06:17:17] INFO aws_utils The worker service for challenge 132 was restarted, as evaluation_script was changed.
[2025-07-10 06:17:17] WARNING aws_utils Worker(s) for challenge 132 couldn't restart! Error: Please select challenges with active workers only.
[2025-07-10 06:17:17] INFO aws_utils The worker service for challenge 133 was restarted, as evaluation_script was changed.
[2025-07-10 06:17:17] WARNING aws_utils Worker(s) for challenge 133 couldn't restart! Error: Please select challenges with active workers only.
[2025-07-10 06:17:17] INFO aws_utils The worker service for challenge 133 was restarted, as evaluation_script was changed.
[2025-07-10 06:17:17] WARNING aws_utils Worker(s) for challenge 133 couldn't restart! Error: Please select challenges with active workers only.
[2025-07-10 06:17:17] INFO aws_utils The worker service for challenge 134 was restarted, as evaluation_script was changed.
[2025-07-10 06:17:17] WARNING aws_utils Worker(s) for challenge 134 couldn't restart! Error: Please select challenges with active workers only.
[2025-07-10 06:17:17] INFO aws_utils The worker service for challenge 135 was restarted, as evaluation_script was changed.
[2025-07-10 06:17:17] WARNING aws_utils Worker(s) for challenge 135 couldn't restart! Error: Please select challenges with active workers only.
[2025-07-10 06:17:17] INFO aws_utils The worker service for challenge 136 was restarted, as evaluation_script was changed.
[2025-07-10 06:17:17] WARNING aws_utils Worker(s) for challenge 136 couldn't restart! Error: Please select challenges with active workers only.
[2025-07-10 06:17:17] INFO aws_utils The worker service for challenge 137 was restarted, as evaluation_script was changed.
[2025-07-10 06:17:17] WARNING aws_utils Worker(s) for challenge 137 couldn't restart! Error: Please select challenges with active workers only.
[2025-07-10 06:17:17] INFO aws_utils The worker service for challenge 138 was restarted, as evaluation_script was changed.
[2025-07-10 06:17:17] WARNING aws_utils Worker(s) for challenge 138 couldn't restart! Error: Please select challenges with active workers only.
[2025-07-10 06:17:21] INFO aws_utils The worker service for challenge 322 was restarted, as test_annotation was changed.
[2025-07-10 06:17:21] WARNING aws_utils Worker(s) for challenge 322 couldn't restart! Error: Please select challenges with active workers only.
[2025-07-10 06:17:40] ERROR aws_utils An error occurred (SomeError) when calling the CreateService operation: Unknown
Traceback (most recent call last):
  File "/code/apps/challenges/aws_utils.py", line 365, in create_service_by_challenge_pk
    response = client.create_service(**definition)
  File "/usr/local/lib/python3.9/unittest/mock.py", line 1092, in __call__
    return self._mock_call(*args, **kwargs)
  File "/usr/local/lib/python3.9/unittest/mock.py", line 1096, in _mock_call
    return self._execute_mock_call(*args, **kwargs)
  File "/usr/local/lib/python3.9/unittest/mock.py", line 1151, in _execute_mock_call
    raise effect
botocore.exceptions.ClientError: An error occurred (SomeError) when calling the CreateService operation: Unknown
[2025-07-10 06:17:40] ERROR aws_utils An error occurred (ServiceError) when calling the UpdateService operation: Unknown
Traceback (most recent call last):
  File "/code/apps/challenges/aws_utils.py", line 414, in update_service_by_challenge_pk
    response = client.update_service(**kwargs)
  File "/usr/local/lib/python3.9/unittest/mock.py", line 1092, in __call__
    return self._mock_call(*args, **kwargs)
  File "/usr/local/lib/python3.9/unittest/mock.py", line 1096, in _mock_call
    return self._execute_mock_call(*args, **kwargs)
  File "/usr/local/lib/python3.9/unittest/mock.py", line 1151, in _execute_mock_call
    raise effect
botocore.exceptions.ClientError: An error occurred (ServiceError) when calling the UpdateService operation: Unknown
[2025-07-10 06:17:40] ERROR aws_utils An error occurred (DeregisterError) when calling the DeregisterTaskDefinition operation: Unknown
Traceback (most recent call last):
  File "/code/apps/challenges/aws_utils.py", line 459, in delete_service_by_challenge_pk
    client.deregister_task_definition(
  File "/usr/local/lib/python3.9/unittest/mock.py", line 1092, in __call__
    return self._mock_call(*args, **kwargs)
  File "/usr/local/lib/python3.9/unittest/mock.py", line 1096, in _mock_call
    return self._execute_mock_call(*args, **kwargs)
  File "/usr/local/lib/python3.9/unittest/mock.py", line 1151, in _execute_mock_call
    raise effect
botocore.exceptions.ClientError: An error occurred (DeregisterError) when calling the DeregisterTaskDefinition operation: Unknown
[2025-07-10 06:17:40] ERROR aws_utils An error occurred (DeleteServiceError) when calling the DeleteService operation: Unknown
Traceback (most recent call last):
  File "/code/apps/challenges/aws_utils.py", line 455, in delete_service_by_challenge_pk
    response = client.delete_service(**kwargs)
  File "/usr/local/lib/python3.9/unittest/mock.py", line 1092, in __call__
    return self._mock_call(*args, **kwargs)
  File "/usr/local/lib/python3.9/unittest/mock.py", line 1096, in _mock_call
    return self._execute_mock_call(*args, **kwargs)
  File "/usr/local/lib/python3.9/unittest/mock.py", line 1151, in _execute_mock_call
    raise effect
botocore.exceptions.ClientError: An error occurred (DeleteServiceError) when calling the DeleteService operation: Unknown
[2025-07-10 06:17:40] ERROR aws_utils An error occurred (Unknown) when calling the DeregisterTaskDefinition operation: Scaling inactive workers not supported
Traceback (most recent call last):
  File "/code/apps/challenges/aws_utils.py", line 1038, in scale_resources
    response = client.deregister_task_definition(
  File "/usr/local/lib/python3.9/unittest/mock.py", line 1092, in __call__
    return self._mock_call(*args, **kwargs)
  File "/usr/local/lib/python3.9/unittest/mock.py", line 1096, in _mock_call
    return self._execute_mock_call(*args, **kwargs)
  File "/usr/local/lib/python3.9/unittest/mock.py", line 1151, in _execute_mock_call
    raise effect
botocore.exceptions.ClientError: An error occurred (Unknown) when calling the DeregisterTaskDefinition operation: Scaling inactive workers not supported
[2025-07-10 06:28:11] INFO aws_utils Updated log retention for approved challenge 126
[2025-07-10 06:28:15] ERROR aws_utils Failed to set log retention for challenge 128
Traceback (most recent call last):
  File "/code/apps/challenges/aws_utils.py", line 2006, in set_cloudwatch_log_retention
    logs_client.put_retention_policy(
  File "/usr/local/lib/python3.9/site-packages/botocore/client.py", line 535, in _api_call
    return self._make_api_call(operation_name, kwargs)
  File "/usr/local/lib/python3.9/site-packages/botocore/client.py", line 980, in _make_api_call
    raise error_class(parsed_response, operation_name)
botocore.errorfactory.UnrecognizedClientException: An error occurred (UnrecognizedClientException) when calling the PutRetentionPolicy operation: The security token included in the request is invalid.
[2025-07-10 06:28:15] WARNING aws_utils Failed to update log retention for challenge 128: An error occurred (UnrecognizedClientException) when calling the PutRetentionPolicy operation: The security token included in the request is invalid.
[2025-07-10 06:28:15] INFO aws_utils The worker service for challenge 130 was restarted, as evaluation_script was changed.
[2025-07-10 06:28:15] WARNING aws_utils Worker(s) for challenge 130 couldn't restart! Error: Please select challenges with active workers only.
[2025-07-10 06:28:15] INFO aws_utils The worker service for challenge 131 was restarted, as evaluation_script was changed.
[2025-07-10 06:28:15] WARNING aws_utils Worker(s) for challenge 131 couldn't restart! Error: Please select challenges with active workers only.
[2025-07-10 06:28:15] INFO aws_utils The worker service for challenge 132 was restarted, as evaluation_script was changed.
[2025-07-10 06:28:15] WARNING aws_utils Worker(s) for challenge 132 couldn't restart! Error: Please select challenges with active workers only.
[2025-07-10 06:28:15] INFO aws_utils The worker service for challenge 133 was restarted, as evaluation_script was changed.
[2025-07-10 06:28:15] WARNING aws_utils Worker(s) for challenge 133 couldn't restart! Error: Please select challenges with active workers only.
[2025-07-10 06:28:15] INFO aws_utils The worker service for challenge 133 was restarted, as evaluation_script was changed.
[2025-07-10 06:28:15] WARNING aws_utils Worker(s) for challenge 133 couldn't restart! Error: Please select challenges with active workers only.
[2025-07-10 06:28:15] INFO aws_utils The worker service for challenge 134 was restarted, as evaluation_script was changed.
[2025-07-10 06:28:15] WARNING aws_utils Worker(s) for challenge 134 couldn't restart! Error: Please select challenges with active workers only.
[2025-07-10 06:28:15] INFO aws_utils The worker service for challenge 135 was restarted, as evaluation_script was changed.
[2025-07-10 06:28:15] WARNING aws_utils Worker(s) for challenge 135 couldn't restart! Error: Please select challenges with active workers only.
[2025-07-10 06:28:15] INFO aws_utils The worker service for challenge 136 was restarted, as evaluation_script was changed.
[2025-07-10 06:28:15] WARNING aws_utils Worker(s) for challenge 136 couldn't restart! Error: Please select challenges with active workers only.
[2025-07-10 06:28:15] INFO aws_utils The worker service for challenge 137 was restarted, as evaluation_script was changed.
[2025-07-10 06:28:15] WARNING aws_utils Worker(s) for challenge 137 couldn't restart! Error: Please select challenges with active workers only.
[2025-07-10 06:28:15] INFO aws_utils The worker service for challenge 138 was restarted, as evaluation_script was changed.
[2025-07-10 06:28:15] WARNING aws_utils Worker(s) for challenge 138 couldn't restart! Error: Please select challenges with active workers only.
[2025-07-10 06:28:18] INFO aws_utils The worker service for challenge 322 was restarted, as test_annotation was changed.
[2025-07-10 06:28:18] WARNING aws_utils Worker(s) for challenge 322 couldn't restart! Error: Please select challenges with active workers only.
[2025-07-10 06:28:38] ERROR aws_utils An error occurred (ServiceError) when calling the UpdateService operation: Unknown
Traceback (most recent call last):
  File "/code/apps/challenges/aws_utils.py", line 414, in update_service_by_challenge_pk
    response = client.update_service(**kwargs)
  File "/usr/local/lib/python3.9/unittest/mock.py", line 1092, in __call__
    return self._mock_call(*args, **kwargs)
  File "/usr/local/lib/python3.9/unittest/mock.py", line 1096, in _mock_call
    return self._execute_mock_call(*args, **kwargs)
  File "/usr/local/lib/python3.9/unittest/mock.py", line 1151, in _execute_mock_call
    raise effect
botocore.exceptions.ClientError: An error occurred (ServiceError) when calling the UpdateService operation: Unknown
[2025-07-10 06:28:39] ERROR aws_utils An error occurred (Unknown) when calling the DeregisterTaskDefinition operation: Scaling inactive workers not supported
Traceback (most recent call last):
  File "/code/apps/challenges/aws_utils.py", line 1038, in scale_resources
    response = client.deregister_task_definition(
  File "/usr/local/lib/python3.9/unittest/mock.py", line 1092, in __call__
    return self._mock_call(*args, **kwargs)
  File "/usr/local/lib/python3.9/unittest/mock.py", line 1096, in _mock_call
    return self._execute_mock_call(*args, **kwargs)
  File "/usr/local/lib/python3.9/unittest/mock.py", line 1151, in _execute_mock_call
    raise effect
botocore.exceptions.ClientError: An error occurred (Unknown) when calling the DeregisterTaskDefinition operation: Scaling inactive workers not supported
[2025-07-10 07:31:58] ERROR aws_utils An error occurred (Unknown) when calling the RegisterTaskDefinition operation: Failed to register task definition
Traceback (most recent call last):
  File "/code/apps/challenges/aws_utils.py", line 1079, in scale_resources
    response = client.register_task_definition(**task_def)
  File "/usr/local/lib/python3.9/unittest/mock.py", line 1092, in __call__
    return self._mock_call(*args, **kwargs)
  File "/usr/local/lib/python3.9/unittest/mock.py", line 1096, in _mock_call
    return self._execute_mock_call(*args, **kwargs)
  File "/usr/local/lib/python3.9/unittest/mock.py", line 1151, in _execute_mock_call
    raise effect
botocore.exceptions.ClientError: An error occurred (Unknown) when calling the RegisterTaskDefinition operation: Failed to register task definition
[2025-07-10 18:02:27] ERROR aws_utils Unexpected error setting log retention for challenge 123
Traceback (most recent call last):
  File "/code/apps/challenges/aws_utils.py", line 1977, in set_cloudwatch_log_retention
    if not phases.exists():
AttributeError: 'list' object has no attribute 'exists'
[2025-07-10 18:03:31] ERROR aws_utils Unexpected error setting log retention for challenge 123
Traceback (most recent call last):
  File "/code/apps/challenges/aws_utils.py", line 1977, in set_cloudwatch_log_retention
    if not phases.exists():
AttributeError: 'list' object has no attribute 'exists'
[2025-07-10 18:04:14] ERROR aws_utils Unexpected error setting log retention for challenge 123
Traceback (most recent call last):
  File "/code/apps/challenges/aws_utils.py", line 1977, in set_cloudwatch_log_retention
    if not phases.exists():
AttributeError: 'list' object has no attribute 'exists'
[2025-07-10 18:05:12] INFO aws_utils Set CloudWatch log retention for challenge 123 to 30 days
[2025-07-10 18:07:21] INFO aws_utils Set CloudWatch log retention for challenge 123 to 60 days
[2025-07-10 18:07:21] INFO aws_utils Set CloudWatch log retention for challenge 123 to 90 days
[2025-07-10 18:07:21] ERROR aws_utils Unexpected error setting log retention for challenge 123
Traceback (most recent call last):
  File "/code/apps/challenges/aws_utils.py", line 2007, in set_cloudwatch_log_retention
    logs_client.put_retention_policy(
  File "/usr/local/lib/python3.9/unittest/mock.py", line 1092, in __call__
    return self._mock_call(*args, **kwargs)
  File "/usr/local/lib/python3.9/unittest/mock.py", line 1096, in _mock_call
    return self._execute_mock_call(*args, **kwargs)
  File "/usr/local/lib/python3.9/unittest/mock.py", line 1151, in _execute_mock_call
    raise effect
Exception
[2025-07-10 18:07:21] INFO aws_utils Set CloudWatch log retention for challenge 123 to 30 days
[2025-07-10 18:08:24] INFO aws_utils Set CloudWatch log retention for challenge 123 to 60 days
[2025-07-10 18:08:24] INFO aws_utils Set CloudWatch log retention for challenge 123 to 90 days
[2025-07-10 18:08:24] INFO aws_utils Set CloudWatch log retention for challenge 123 to 30 days
[2025-07-10 18:09:40] INFO aws_utils Set CloudWatch log retention for challenge 123 to 60 days
[2025-07-10 18:09:40] INFO aws_utils Set CloudWatch log retention for challenge 123 to 90 days
[2025-07-10 18:09:40] INFO aws_utils Set CloudWatch log retention for challenge 123 to 30 days
[2025-07-10 18:09:40] INFO aws_utils Starting cleanup of expired submission artifacts
[2025-07-10 18:09:40] INFO aws_utils Found <MagicMock name='filter().select_related().count()' id='281473259677056'> submissions eligible for cleanup
[2025-07-10 18:09:40] INFO aws_utils Cleanup completed. Processed: 0, Successful: 0, Failed: 0
[2025-07-10 18:09:40] INFO aws_utils Updated log retention for approved challenge 123
[2025-07-10 18:09:40] INFO aws_utils Updated log retention for approved challenge 123
[2025-07-10 18:09:43] ERROR aws_utils Failed to set log retention for challenge 123
Traceback (most recent call last):
  File "/code/apps/challenges/aws_utils.py", line 2007, in set_cloudwatch_log_retention
    logs_client.put_retention_policy(
  File "/usr/local/lib/python3.9/site-packages/botocore/client.py", line 535, in _api_call
    return self._make_api_call(operation_name, kwargs)
  File "/usr/local/lib/python3.9/site-packages/botocore/client.py", line 980, in _make_api_call
    raise error_class(parsed_response, operation_name)
botocore.errorfactory.UnrecognizedClientException: An error occurred (UnrecognizedClientException) when calling the PutRetentionPolicy operation: The security token included in the request is invalid.
[2025-07-10 18:09:43] WARNING aws_utils Failed to update log retention for challenge 123: An error occurred (UnrecognizedClientException) when calling the PutRetentionPolicy operation: The security token included in the request is invalid.
[2025-07-10 18:09:43] INFO aws_utils The worker service for challenge 125 was restarted, as evaluation_script was changed.
[2025-07-10 18:09:43] WARNING aws_utils Worker(s) for challenge 125 couldn't restart! Error: Please select challenges with active workers only.
[2025-07-10 18:09:43] INFO aws_utils The worker service for challenge 126 was restarted, as evaluation_script was changed.
[2025-07-10 18:09:43] WARNING aws_utils Worker(s) for challenge 126 couldn't restart! Error: Please select challenges with active workers only.
[2025-07-10 18:09:44] INFO aws_utils The worker service for challenge 127 was restarted, as evaluation_script was changed.
[2025-07-10 18:09:44] WARNING aws_utils Worker(s) for challenge 127 couldn't restart! Error: Please select challenges with active workers only.
[2025-07-10 18:09:44] INFO aws_utils The worker service for challenge 128 was restarted, as evaluation_script was changed.
[2025-07-10 18:09:44] WARNING aws_utils Worker(s) for challenge 128 couldn't restart! Error: Please select challenges with active workers only.
[2025-07-10 18:09:44] INFO aws_utils The worker service for challenge 128 was restarted, as evaluation_script was changed.
[2025-07-10 18:09:44] WARNING aws_utils Worker(s) for challenge 128 couldn't restart! Error: Please select challenges with active workers only.
[2025-07-10 18:09:44] INFO aws_utils The worker service for challenge 129 was restarted, as evaluation_script was changed.
[2025-07-10 18:09:44] WARNING aws_utils Worker(s) for challenge 129 couldn't restart! Error: Please select challenges with active workers only.
[2025-07-10 18:09:44] INFO aws_utils The worker service for challenge 130 was restarted, as evaluation_script was changed.
[2025-07-10 18:09:44] WARNING aws_utils Worker(s) for challenge 130 couldn't restart! Error: Please select challenges with active workers only.
[2025-07-10 18:09:44] INFO aws_utils The worker service for challenge 131 was restarted, as evaluation_script was changed.
[2025-07-10 18:09:44] WARNING aws_utils Worker(s) for challenge 131 couldn't restart! Error: Please select challenges with active workers only.
[2025-07-10 18:09:44] INFO aws_utils The worker service for challenge 132 was restarted, as evaluation_script was changed.
[2025-07-10 18:09:44] WARNING aws_utils Worker(s) for challenge 132 couldn't restart! Error: Please select challenges with active workers only.
[2025-07-10 18:09:44] INFO aws_utils The worker service for challenge 133 was restarted, as evaluation_script was changed.
[2025-07-10 18:09:44] WARNING aws_utils Worker(s) for challenge 133 couldn't restart! Error: Please select challenges with active workers only.
[2025-07-10 18:09:47] INFO aws_utils The worker service for challenge 317 was restarted, as test_annotation was changed.
[2025-07-10 18:09:47] WARNING aws_utils Worker(s) for challenge 317 couldn't restart! Error: Please select challenges with active workers only.
[2025-07-10 18:12:32] INFO aws_utils Updated log retention for approved challenge 123
[2025-07-10 18:24:14] INFO aws_utils Set CloudWatch log retention for challenge 123 to 60 days
[2025-07-10 18:24:14] INFO aws_utils Set CloudWatch log retention for challenge 123 to 90 days
[2025-07-10 18:24:14] INFO aws_utils Set CloudWatch log retention for challenge 123 to 30 days
[2025-07-10 18:24:14] INFO aws_utils Starting cleanup of expired submission artifacts
[2025-07-10 18:24:14] INFO aws_utils Found <MagicMock name='filter().select_related().count()' id='281473291150720'> submissions eligible for cleanup
[2025-07-10 18:24:14] INFO aws_utils Cleanup completed. Processed: 0, Successful: 0, Failed: 0
[2025-07-10 18:24:14] INFO aws_utils Updated log retention for approved challenge 123
[2025-07-10 18:24:14] ERROR aws_utils An error occurred (ServiceError) when calling the UpdateService operation: Unknown
Traceback (most recent call last):
  File "/code/apps/challenges/aws_utils.py", line 414, in update_service_by_challenge_pk
    response = client.update_service(**kwargs)
  File "/usr/local/lib/python3.9/unittest/mock.py", line 1092, in __call__
    return self._mock_call(*args, **kwargs)
  File "/usr/local/lib/python3.9/unittest/mock.py", line 1096, in _mock_call
    return self._execute_mock_call(*args, **kwargs)
  File "/usr/local/lib/python3.9/unittest/mock.py", line 1151, in _execute_mock_call
    raise effect
botocore.exceptions.ClientError: An error occurred (ServiceError) when calling the UpdateService operation: Unknown
[2025-07-10 18:26:19] INFO aws_utils Set CloudWatch log retention for challenge 123 to 60 days
[2025-07-10 18:26:19] INFO aws_utils Set CloudWatch log retention for challenge 123 to 90 days
[2025-07-10 18:26:19] INFO aws_utils Set CloudWatch log retention for challenge 123 to 30 days
[2025-07-10 18:26:19] INFO aws_utils Starting cleanup of expired submission artifacts
[2025-07-10 18:26:19] INFO aws_utils Found <MagicMock name='filter().select_related().count()' id='281473029170272'> submissions eligible for cleanup
[2025-07-10 18:26:19] INFO aws_utils Cleanup completed. Processed: 0, Successful: 0, Failed: 0
[2025-07-10 18:26:19] INFO aws_utils Updated log retention for approved challenge 123
[2025-07-10 18:26:19] ERROR aws_utils An error occurred (ServiceError) when calling the UpdateService operation: Unknown
Traceback (most recent call last):
  File "/code/apps/challenges/aws_utils.py", line 414, in update_service_by_challenge_pk
    response = client.update_service(**kwargs)
  File "/usr/local/lib/python3.9/unittest/mock.py", line 1092, in __call__
    return self._mock_call(*args, **kwargs)
  File "/usr/local/lib/python3.9/unittest/mock.py", line 1096, in _mock_call
    return self._execute_mock_call(*args, **kwargs)
  File "/usr/local/lib/python3.9/unittest/mock.py", line 1151, in _execute_mock_call
    raise effect
botocore.exceptions.ClientError: An error occurred (ServiceError) when calling the UpdateService operation: Unknown
[2025-07-10 18:28:19] INFO aws_utils Set CloudWatch log retention for challenge 123 to 60 days
[2025-07-10 18:28:19] INFO aws_utils Set CloudWatch log retention for challenge 123 to 90 days
[2025-07-10 18:28:19] INFO aws_utils Set CloudWatch log retention for challenge 123 to 30 days
[2025-07-10 18:28:19] INFO aws_utils Starting cleanup of expired submission artifacts
[2025-07-10 18:28:19] INFO aws_utils Found <MagicMock name='filter().select_related().count()' id='281472501212400'> submissions eligible for cleanup
[2025-07-10 18:28:19] INFO aws_utils Cleanup completed. Processed: 0, Successful: 0, Failed: 0
[2025-07-10 18:28:19] INFO aws_utils Updated log retention for approved challenge 123
[2025-07-10 18:28:20] ERROR aws_utils An error occurred (ServiceError) when calling the UpdateService operation: Unknown
Traceback (most recent call last):
  File "/code/apps/challenges/aws_utils.py", line 414, in update_service_by_challenge_pk
    response = client.update_service(**kwargs)
  File "/usr/local/lib/python3.9/unittest/mock.py", line 1092, in __call__
    return self._mock_call(*args, **kwargs)
  File "/usr/local/lib/python3.9/unittest/mock.py", line 1096, in _mock_call
    return self._execute_mock_call(*args, **kwargs)
  File "/usr/local/lib/python3.9/unittest/mock.py", line 1151, in _execute_mock_call
    raise effect
botocore.exceptions.ClientError: An error occurred (ServiceError) when calling the UpdateService operation: Unknown
[2025-07-10 18:30:19] INFO aws_utils Set CloudWatch log retention for challenge 123 to 60 days
[2025-07-10 18:30:19] INFO aws_utils Set CloudWatch log retention for challenge 123 to 90 days
[2025-07-10 18:30:19] INFO aws_utils Set CloudWatch log retention for challenge 123 to 30 days
[2025-07-10 18:30:19] INFO aws_utils Starting cleanup of expired submission artifacts
[2025-07-10 18:30:19] INFO aws_utils Found <MagicMock name='filter().select_related().count()' id='281473338408000'> submissions eligible for cleanup
[2025-07-10 18:30:19] INFO aws_utils Cleanup completed. Processed: 0, Successful: 0, Failed: 0
[2025-07-10 18:30:19] INFO aws_utils Updated log retention for approved challenge 123
[2025-07-10 18:30:20] ERROR aws_utils An error occurred (ServiceError) when calling the UpdateService operation: Unknown
Traceback (most recent call last):
  File "/code/apps/challenges/aws_utils.py", line 414, in update_service_by_challenge_pk
    response = client.update_service(**kwargs)
  File "/usr/local/lib/python3.9/unittest/mock.py", line 1092, in __call__
    return self._mock_call(*args, **kwargs)
  File "/usr/local/lib/python3.9/unittest/mock.py", line 1096, in _mock_call
    return self._execute_mock_call(*args, **kwargs)
  File "/usr/local/lib/python3.9/unittest/mock.py", line 1151, in _execute_mock_call
    raise effect
botocore.exceptions.ClientError: An error occurred (ServiceError) when calling the UpdateService operation: Unknown
[2025-07-10 18:31:53] INFO aws_utils Set CloudWatch log retention for challenge 123 to 60 days
[2025-07-10 18:31:53] INFO aws_utils Set CloudWatch log retention for challenge 123 to 90 days
[2025-07-10 18:31:53] INFO aws_utils Set CloudWatch log retention for challenge 123 to 30 days
[2025-07-10 18:31:53] INFO aws_utils Starting cleanup of expired submission artifacts
[2025-07-10 18:31:53] INFO aws_utils Found <MagicMock name='filter().select_related().count()' id='281473302569504'> submissions eligible for cleanup
[2025-07-10 18:31:53] INFO aws_utils Cleanup completed. Processed: 0, Successful: 0, Failed: 0
[2025-07-10 18:31:53] INFO aws_utils Updated log retention for approved challenge 123
[2025-07-10 18:31:54] ERROR aws_utils An error occurred (ServiceError) when calling the UpdateService operation: Unknown
Traceback (most recent call last):
  File "/code/apps/challenges/aws_utils.py", line 414, in update_service_by_challenge_pk
    response = client.update_service(**kwargs)
  File "/usr/local/lib/python3.9/unittest/mock.py", line 1092, in __call__
    return self._mock_call(*args, **kwargs)
  File "/usr/local/lib/python3.9/unittest/mock.py", line 1096, in _mock_call
    return self._execute_mock_call(*args, **kwargs)
  File "/usr/local/lib/python3.9/unittest/mock.py", line 1151, in _execute_mock_call
    raise effect
botocore.exceptions.ClientError: An error occurred (ServiceError) when calling the UpdateService operation: Unknown
[2025-07-10 18:33:39] INFO aws_utils Set CloudWatch log retention for challenge 123 to 60 days
[2025-07-10 18:33:39] INFO aws_utils Set CloudWatch log retention for challenge 123 to 90 days
[2025-07-10 18:33:39] INFO aws_utils Set CloudWatch log retention for challenge 123 to 30 days
[2025-07-10 18:33:39] INFO aws_utils Starting cleanup of expired submission artifacts
[2025-07-10 18:33:39] INFO aws_utils Found <MagicMock name='filter().select_related().count()' id='281473306976512'> submissions eligible for cleanup
[2025-07-10 18:33:39] INFO aws_utils Cleanup completed. Processed: 0, Successful: 0, Failed: 0
[2025-07-10 18:33:39] INFO aws_utils Updated log retention for approved challenge 123
[2025-07-10 18:33:39] ERROR aws_utils An error occurred (ServiceError) when calling the UpdateService operation: Unknown
Traceback (most recent call last):
  File "/code/apps/challenges/aws_utils.py", line 414, in update_service_by_challenge_pk
    response = client.update_service(**kwargs)
  File "/usr/local/lib/python3.9/unittest/mock.py", line 1092, in __call__
    return self._mock_call(*args, **kwargs)
  File "/usr/local/lib/python3.9/unittest/mock.py", line 1096, in _mock_call
    return self._execute_mock_call(*args, **kwargs)
  File "/usr/local/lib/python3.9/unittest/mock.py", line 1151, in _execute_mock_call
    raise effect
botocore.exceptions.ClientError: An error occurred (ServiceError) when calling the UpdateService operation: Unknown
[2025-07-10 18:35:30] INFO aws_utils Set CloudWatch log retention for challenge 123 to 60 days
[2025-07-10 18:35:30] INFO aws_utils Set CloudWatch log retention for challenge 123 to 90 days
[2025-07-10 18:35:30] INFO aws_utils Set CloudWatch log retention for challenge 123 to 30 days
[2025-07-10 18:35:30] INFO aws_utils Starting cleanup of expired submission artifacts
[2025-07-10 18:35:30] INFO aws_utils Found <MagicMock name='filter().select_related().count()' id='281472972375040'> submissions eligible for cleanup
[2025-07-10 18:35:30] INFO aws_utils Cleanup completed. Processed: 0, Successful: 0, Failed: 0
[2025-07-10 18:35:30] INFO aws_utils Updated log retention for approved challenge 123
[2025-07-10 18:35:31] ERROR aws_utils An error occurred (ServiceError) when calling the UpdateService operation: Unknown
Traceback (most recent call last):
  File "/code/apps/challenges/aws_utils.py", line 414, in update_service_by_challenge_pk
    response = client.update_service(**kwargs)
  File "/usr/local/lib/python3.9/unittest/mock.py", line 1092, in __call__
    return self._mock_call(*args, **kwargs)
  File "/usr/local/lib/python3.9/unittest/mock.py", line 1096, in _mock_call
    return self._execute_mock_call(*args, **kwargs)
  File "/usr/local/lib/python3.9/unittest/mock.py", line 1151, in _execute_mock_call
    raise effect
botocore.exceptions.ClientError: An error occurred (ServiceError) when calling the UpdateService operation: Unknown
[2025-07-10 18:41:30] INFO aws_utils Set CloudWatch log retention for challenge 123 to 60 days
[2025-07-10 18:41:30] INFO aws_utils Set CloudWatch log retention for challenge 123 to 90 days
[2025-07-10 18:41:30] INFO aws_utils Set CloudWatch log retention for challenge 123 to 30 days
[2025-07-10 18:41:30] INFO aws_utils Starting cleanup of expired submission artifacts
[2025-07-10 18:41:30] INFO aws_utils Found <MagicMock name='filter().select_related().count()' id='281472857263648'> submissions eligible for cleanup
[2025-07-10 18:41:30] INFO aws_utils Cleanup completed. Processed: 0, Successful: 0, Failed: 0
[2025-07-10 18:41:30] INFO aws_utils Updated log retention for approved challenge 123
[2025-07-10 18:41:30] ERROR aws_utils An error occurred (SomeError) when calling the CreateService operation: Unknown
Traceback (most recent call last):
  File "/code/apps/challenges/aws_utils.py", line 365, in create_service_by_challenge_pk
    response = client.create_service(**definition)
  File "/usr/local/lib/python3.9/unittest/mock.py", line 1092, in __call__
    return self._mock_call(*args, **kwargs)
  File "/usr/local/lib/python3.9/unittest/mock.py", line 1096, in _mock_call
    return self._execute_mock_call(*args, **kwargs)
  File "/usr/local/lib/python3.9/unittest/mock.py", line 1151, in _execute_mock_call
    raise effect
botocore.exceptions.ClientError: An error occurred (SomeError) when calling the CreateService operation: Unknown
[2025-07-10 18:41:30] ERROR aws_utils An error occurred (ServiceError) when calling the UpdateService operation: Unknown
Traceback (most recent call last):
  File "/code/apps/challenges/aws_utils.py", line 414, in update_service_by_challenge_pk
    response = client.update_service(**kwargs)
  File "/usr/local/lib/python3.9/unittest/mock.py", line 1092, in __call__
    return self._mock_call(*args, **kwargs)
  File "/usr/local/lib/python3.9/unittest/mock.py", line 1096, in _mock_call
    return self._execute_mock_call(*args, **kwargs)
  File "/usr/local/lib/python3.9/unittest/mock.py", line 1151, in _execute_mock_call
    raise effect
botocore.exceptions.ClientError: An error occurred (ServiceError) when calling the UpdateService operation: Unknown
[2025-07-10 18:42:26] INFO aws_utils Set CloudWatch log retention for challenge 123 to 60 days
[2025-07-10 18:42:26] INFO aws_utils Set CloudWatch log retention for challenge 123 to 90 days
[2025-07-10 18:42:26] INFO aws_utils Set CloudWatch log retention for challenge 123 to 30 days
[2025-07-10 18:42:26] INFO aws_utils Starting cleanup of expired submission artifacts
[2025-07-10 18:42:26] INFO aws_utils Found <MagicMock name='filter().select_related().count()' id='281472951617088'> submissions eligible for cleanup
[2025-07-10 18:42:26] INFO aws_utils Cleanup completed. Processed: 0, Successful: 0, Failed: 0
[2025-07-10 18:42:26] INFO aws_utils Updated log retention for approved challenge 123
[2025-07-10 18:42:26] ERROR aws_utils An error occurred (SomeError) when calling the CreateService operation: Unknown
Traceback (most recent call last):
  File "/code/apps/challenges/aws_utils.py", line 365, in create_service_by_challenge_pk
    response = client.create_service(**definition)
  File "/usr/local/lib/python3.9/unittest/mock.py", line 1092, in __call__
    return self._mock_call(*args, **kwargs)
  File "/usr/local/lib/python3.9/unittest/mock.py", line 1096, in _mock_call
    return self._execute_mock_call(*args, **kwargs)
  File "/usr/local/lib/python3.9/unittest/mock.py", line 1151, in _execute_mock_call
    raise effect
botocore.exceptions.ClientError: An error occurred (SomeError) when calling the CreateService operation: Unknown
[2025-07-10 18:42:26] ERROR aws_utils An error occurred (ServiceError) when calling the UpdateService operation: Unknown
Traceback (most recent call last):
  File "/code/apps/challenges/aws_utils.py", line 414, in update_service_by_challenge_pk
    response = client.update_service(**kwargs)
  File "/usr/local/lib/python3.9/unittest/mock.py", line 1092, in __call__
    return self._mock_call(*args, **kwargs)
  File "/usr/local/lib/python3.9/unittest/mock.py", line 1096, in _mock_call
    return self._execute_mock_call(*args, **kwargs)
  File "/usr/local/lib/python3.9/unittest/mock.py", line 1151, in _execute_mock_call
    raise effect
botocore.exceptions.ClientError: An error occurred (ServiceError) when calling the UpdateService operation: Unknown
[2025-07-10 18:42:26] ERROR aws_utils An error occurred (Unknown) when calling the DeregisterTaskDefinition operation: Scaling inactive workers not supported
Traceback (most recent call last):
  File "/code/apps/challenges/aws_utils.py", line 1038, in scale_resources
    response = client.deregister_task_definition(
  File "/usr/local/lib/python3.9/unittest/mock.py", line 1092, in __call__
    return self._mock_call(*args, **kwargs)
  File "/usr/local/lib/python3.9/unittest/mock.py", line 1096, in _mock_call
    return self._execute_mock_call(*args, **kwargs)
  File "/usr/local/lib/python3.9/unittest/mock.py", line 1151, in _execute_mock_call
    raise effect
botocore.exceptions.ClientError: An error occurred (Unknown) when calling the DeregisterTaskDefinition operation: Scaling inactive workers not supported
