[2025-07-05 14:45:34] ERROR aws_utils Failed to set log retention for challenge 123
Traceback (most recent call last):
  File "/code/apps/challenges/aws_utils.py", line 1994, in set_cloudwatch_log_retention
    response = logs_client.put_retention_policy(
  File "/usr/local/lib/python3.9/site-packages/botocore/client.py", line 535, in _api_call
    return self._make_api_call(operation_name, kwargs)
  File "/usr/local/lib/python3.9/site-packages/botocore/client.py", line 980, in _make_api_call
    raise error_class(parsed_response, operation_name)
botocore.errorfactory.UnrecognizedClientException: An error occurred (UnrecognizedClientException) when calling the PutRetentionPolicy operation: The security token included in the request is invalid.
[2025-07-05 14:45:34] WARNING aws_utils Failed to update log retention for challenge 123: An error occurred (UnrecognizedClientException) when calling the PutRetentionPolicy operation: The security token included in the request is invalid.
[2025-07-05 14:45:34] INFO aws_utils The worker service for challenge 125 was restarted, as evaluation_script was changed.
[2025-07-05 14:45:34] WARNING aws_utils Worker(s) for challenge 125 couldn't restart! Error: Please select challenges with active workers only.
[2025-07-05 14:45:34] INFO aws_utils The worker service for challenge 126 was restarted, as evaluation_script was changed.
[2025-07-05 14:45:34] WARNING aws_utils Worker(s) for challenge 126 couldn't restart! Error: Please select challenges with active workers only.
[2025-07-05 14:45:34] INFO aws_utils The worker service for challenge 127 was restarted, as evaluation_script was changed.
[2025-07-05 14:45:34] WARNING aws_utils Worker(s) for challenge 127 couldn't restart! Error: Please select challenges with active workers only.
[2025-07-05 14:45:34] INFO aws_utils The worker service for challenge 128 was restarted, as evaluation_script was changed.
[2025-07-05 14:45:34] WARNING aws_utils Worker(s) for challenge 128 couldn't restart! Error: Please select challenges with active workers only.
[2025-07-05 14:45:35] INFO aws_utils The worker service for challenge 128 was restarted, as evaluation_script was changed.
[2025-07-05 14:45:35] WARNING aws_utils Worker(s) for challenge 128 couldn't restart! Error: Please select challenges with active workers only.
[2025-07-05 14:45:35] INFO aws_utils The worker service for challenge 129 was restarted, as evaluation_script was changed.
[2025-07-05 14:45:35] WARNING aws_utils Worker(s) for challenge 129 couldn't restart! Error: Please select challenges with active workers only.
[2025-07-05 14:45:35] INFO aws_utils The worker service for challenge 130 was restarted, as evaluation_script was changed.
[2025-07-05 14:45:35] WARNING aws_utils Worker(s) for challenge 130 couldn't restart! Error: Please select challenges with active workers only.
[2025-07-05 14:45:35] INFO aws_utils The worker service for challenge 131 was restarted, as evaluation_script was changed.
[2025-07-05 14:45:35] WARNING aws_utils Worker(s) for challenge 131 couldn't restart! Error: Please select challenges with active workers only.
[2025-07-05 14:45:35] INFO aws_utils The worker service for challenge 132 was restarted, as evaluation_script was changed.
[2025-07-05 14:45:35] WARNING aws_utils Worker(s) for challenge 132 couldn't restart! Error: Please select challenges with active workers only.
[2025-07-05 14:45:35] INFO aws_utils The worker service for challenge 133 was restarted, as evaluation_script was changed.
[2025-07-05 14:45:35] WARNING aws_utils Worker(s) for challenge 133 couldn't restart! Error: Please select challenges with active workers only.
[2025-07-05 14:45:37] INFO aws_utils The worker service for challenge 317 was restarted, as test_annotation was changed.
[2025-07-05 14:45:37] WARNING aws_utils Worker(s) for challenge 317 couldn't restart! Error: Please select challenges with active workers only.
[2025-07-05 14:45:41] ERROR aws_utils An error occurred (UnrecognizedClientException) when calling the RegisterTaskDefinition operation: The security token included in the request is invalid.
Traceback (most recent call last):
  File "/code/apps/challenges/aws_utils.py", line 291, in register_task_def_by_challenge_pk
    response = client.register_task_definition(**definition)
  File "/usr/local/lib/python3.9/site-packages/botocore/client.py", line 535, in _api_call
    return self._make_api_call(operation_name, kwargs)
  File "/usr/local/lib/python3.9/site-packages/botocore/client.py", line 980, in _make_api_call
    raise error_class(parsed_response, operation_name)
botocore.exceptions.ClientError: An error occurred (UnrecognizedClientException) when calling the RegisterTaskDefinition operation: The security token included in the request is invalid.
[2025-07-05 14:45:41] ERROR aws_utils Worker for challenge 408 couldn't start! Error: {'Message': 'The security token included in the request is invalid.', 'Code': 'UnrecognizedClientException'}
[2025-07-05 14:45:41] WARNING aws_utils Failed to update log retention for challenge 408: No phases found for challenge 408
[2025-07-05 14:45:43] ERROR aws_utils An error occurred (UnrecognizedClientException) when calling the RegisterTaskDefinition operation: The security token included in the request is invalid.
Traceback (most recent call last):
  File "/code/apps/challenges/aws_utils.py", line 291, in register_task_def_by_challenge_pk
    response = client.register_task_definition(**definition)
  File "/usr/local/lib/python3.9/site-packages/botocore/client.py", line 535, in _api_call
    return self._make_api_call(operation_name, kwargs)
  File "/usr/local/lib/python3.9/site-packages/botocore/client.py", line 980, in _make_api_call
    raise error_class(parsed_response, operation_name)
botocore.exceptions.ClientError: An error occurred (UnrecognizedClientException) when calling the RegisterTaskDefinition operation: The security token included in the request is invalid.
[2025-07-05 14:45:43] ERROR aws_utils Worker for challenge 410 couldn't start! Error: {'Message': 'The security token included in the request is invalid.', 'Code': 'UnrecognizedClientException'}
[2025-07-05 14:45:43] WARNING aws_utils Failed to update log retention for challenge 410: No phases found for challenge 410
[2025-07-05 14:45:55] ERROR aws_utils An error occurred (SomeError) when calling the CreateService operation: Unknown
Traceback (most recent call last):
  File "/code/apps/challenges/aws_utils.py", line 364, in create_service_by_challenge_pk
    response = client.create_service(**definition)
  File "/usr/local/lib/python3.9/unittest/mock.py", line 1092, in __call__
    return self._mock_call(*args, **kwargs)
  File "/usr/local/lib/python3.9/unittest/mock.py", line 1096, in _mock_call
    return self._execute_mock_call(*args, **kwargs)
  File "/usr/local/lib/python3.9/unittest/mock.py", line 1151, in _execute_mock_call
    raise effect
botocore.exceptions.ClientError: An error occurred (SomeError) when calling the CreateService operation: Unknown
[2025-07-05 14:45:55] ERROR aws_utils An error occurred (ServiceError) when calling the UpdateService operation: Unknown
Traceback (most recent call last):
  File "/code/apps/challenges/aws_utils.py", line 413, in update_service_by_challenge_pk
    response = client.update_service(**kwargs)
  File "/usr/local/lib/python3.9/unittest/mock.py", line 1092, in __call__
    return self._mock_call(*args, **kwargs)
  File "/usr/local/lib/python3.9/unittest/mock.py", line 1096, in _mock_call
    return self._execute_mock_call(*args, **kwargs)
  File "/usr/local/lib/python3.9/unittest/mock.py", line 1151, in _execute_mock_call
    raise effect
botocore.exceptions.ClientError: An error occurred (ServiceError) when calling the UpdateService operation: Unknown
[2025-07-05 14:45:55] ERROR aws_utils An error occurred (DeregisterError) when calling the DeregisterTaskDefinition operation: Unknown
Traceback (most recent call last):
  File "/code/apps/challenges/aws_utils.py", line 458, in delete_service_by_challenge_pk
    client.deregister_task_definition(
  File "/usr/local/lib/python3.9/unittest/mock.py", line 1092, in __call__
    return self._mock_call(*args, **kwargs)
  File "/usr/local/lib/python3.9/unittest/mock.py", line 1096, in _mock_call
    return self._execute_mock_call(*args, **kwargs)
  File "/usr/local/lib/python3.9/unittest/mock.py", line 1151, in _execute_mock_call
    raise effect
botocore.exceptions.ClientError: An error occurred (DeregisterError) when calling the DeregisterTaskDefinition operation: Unknown
[2025-07-05 14:45:55] ERROR aws_utils An error occurred (DeleteServiceError) when calling the DeleteService operation: Unknown
Traceback (most recent call last):
  File "/code/apps/challenges/aws_utils.py", line 454, in delete_service_by_challenge_pk
    response = client.delete_service(**kwargs)
  File "/usr/local/lib/python3.9/unittest/mock.py", line 1092, in __call__
    return self._mock_call(*args, **kwargs)
  File "/usr/local/lib/python3.9/unittest/mock.py", line 1096, in _mock_call
    return self._execute_mock_call(*args, **kwargs)
  File "/usr/local/lib/python3.9/unittest/mock.py", line 1151, in _execute_mock_call
    raise effect
botocore.exceptions.ClientError: An error occurred (DeleteServiceError) when calling the DeleteService operation: Unknown
[2025-07-05 14:45:55] ERROR aws_utils An error occurred (Unknown) when calling the DeregisterTaskDefinition operation: Scaling inactive workers not supported
Traceback (most recent call last):
  File "/code/apps/challenges/aws_utils.py", line 1037, in scale_resources
    response = client.deregister_task_definition(
  File "/usr/local/lib/python3.9/unittest/mock.py", line 1092, in __call__
    return self._mock_call(*args, **kwargs)
  File "/usr/local/lib/python3.9/unittest/mock.py", line 1096, in _mock_call
    return self._execute_mock_call(*args, **kwargs)
  File "/usr/local/lib/python3.9/unittest/mock.py", line 1151, in _execute_mock_call
    raise effect
botocore.exceptions.ClientError: An error occurred (Unknown) when calling the DeregisterTaskDefinition operation: Scaling inactive workers not supported
[2025-07-09 18:26:15] ERROR aws_utils Failed to set log retention for challenge 27
Traceback (most recent call last):
  File "/code/apps/challenges/aws_utils.py", line 2000, in set_cloudwatch_log_retention
    logs_client.put_retention_policy(
  File "/usr/local/lib/python3.9/site-packages/botocore/client.py", line 535, in _api_call
    return self._make_api_call(operation_name, kwargs)
  File "/usr/local/lib/python3.9/site-packages/botocore/client.py", line 980, in _make_api_call
    raise error_class(parsed_response, operation_name)
botocore.errorfactory.UnrecognizedClientException: An error occurred (UnrecognizedClientException) when calling the PutRetentionPolicy operation: The security token included in the request is invalid.
[2025-07-09 18:28:39] INFO aws_utils Deleted 0 files for submission 3
[2025-07-09 18:28:56] ERROR aws_utils Failed to set log retention for challenge 9
Traceback (most recent call last):
  File "/code/apps/challenges/aws_utils.py", line 2000, in set_cloudwatch_log_retention
    logs_client.put_retention_policy(
  File "/usr/local/lib/python3.9/site-packages/botocore/client.py", line 535, in _api_call
    return self._make_api_call(operation_name, kwargs)
  File "/usr/local/lib/python3.9/site-packages/botocore/client.py", line 980, in _make_api_call
    raise error_class(parsed_response, operation_name)
botocore.errorfactory.UnrecognizedClientException: An error occurred (UnrecognizedClientException) when calling the PutRetentionPolicy operation: The security token included in the request is invalid.
[2025-07-09 18:28:58] ERROR aws_utils Failed to set log retention for challenge 11
Traceback (most recent call last):
  File "/code/apps/challenges/aws_utils.py", line 2000, in set_cloudwatch_log_retention
    logs_client.put_retention_policy(
  File "/usr/local/lib/python3.9/site-packages/botocore/client.py", line 535, in _api_call
    return self._make_api_call(operation_name, kwargs)
  File "/usr/local/lib/python3.9/site-packages/botocore/client.py", line 980, in _make_api_call
    raise error_class(parsed_response, operation_name)
botocore.errorfactory.UnrecognizedClientException: An error occurred (UnrecognizedClientException) when calling the PutRetentionPolicy operation: The security token included in the request is invalid.
[2025-07-09 18:28:59] ERROR aws_utils Failed to set log retention for challenge 12
Traceback (most recent call last):
  File "/code/apps/challenges/aws_utils.py", line 2000, in set_cloudwatch_log_retention
    logs_client.put_retention_policy(
  File "/usr/local/lib/python3.9/site-packages/botocore/client.py", line 535, in _api_call
    return self._make_api_call(operation_name, kwargs)
  File "/usr/local/lib/python3.9/site-packages/botocore/client.py", line 980, in _make_api_call
    raise error_class(parsed_response, operation_name)
botocore.errorfactory.UnrecognizedClientException: An error occurred (UnrecognizedClientException) when calling the PutRetentionPolicy operation: The security token included in the request is invalid.
[2025-07-09 18:29:26] ERROR aws_utils Failed to set log retention for challenge 1
Traceback (most recent call last):
  File "/code/apps/challenges/aws_utils.py", line 2000, in set_cloudwatch_log_retention
    logs_client.put_retention_policy(
  File "/usr/local/lib/python3.9/site-packages/botocore/client.py", line 535, in _api_call
    return self._make_api_call(operation_name, kwargs)
  File "/usr/local/lib/python3.9/site-packages/botocore/client.py", line 980, in _make_api_call
    raise error_class(parsed_response, operation_name)
botocore.errorfactory.UnrecognizedClientException: An error occurred (UnrecognizedClientException) when calling the PutRetentionPolicy operation: The security token included in the request is invalid.
[2025-07-09 18:31:52] ERROR aws_utils Failed to set log retention for challenge 27
Traceback (most recent call last):
  File "/code/apps/challenges/aws_utils.py", line 2000, in set_cloudwatch_log_retention
    logs_client.put_retention_policy(
  File "/usr/local/lib/python3.9/site-packages/botocore/client.py", line 535, in _api_call
    return self._make_api_call(operation_name, kwargs)
  File "/usr/local/lib/python3.9/site-packages/botocore/client.py", line 980, in _make_api_call
    raise error_class(parsed_response, operation_name)
botocore.errorfactory.UnrecognizedClientException: An error occurred (UnrecognizedClientException) when calling the PutRetentionPolicy operation: The security token included in the request is invalid.
[2025-07-09 18:40:45] INFO aws_utils Updated log retention for approved challenge 29
[2025-07-09 18:41:21] INFO aws_utils Updated log retention for approved challenge 29
[2025-07-09 18:42:13] INFO aws_utils Updated log retention for approved challenge 29
[2025-07-09 18:56:45] INFO aws_utils Updated log retention for approved challenge 29
[2025-07-09 18:58:09] INFO aws_utils Set CloudWatch log retention for challenge 19 to 545 days
[2025-07-09 18:59:39] INFO aws_utils Set CloudWatch log retention for challenge 19 to 545 days
[2025-07-09 18:59:39] INFO aws_utils Updated log retention for approved challenge 19
[2025-07-09 18:59:39] INFO aws_utils Updated log retention for restarted challenge 19
[2025-07-09 18:59:39] INFO aws_utils Updated log retention for challenge 19 task definition
[2025-07-09 18:59:39] ERROR aws_utils Unexpected error setting log retention for challenge 999999
Traceback (most recent call last):
  File "/code/apps/challenges/aws_utils.py", line 1968, in set_cloudwatch_log_retention
    challenge_obj = Challenge.objects.get(pk=challenge_pk)
  File "/usr/local/lib/python3.9/site-packages/django/db/models/manager.py", line 82, in manager_method
    return getattr(self.get_queryset(), name)(*args, **kwargs)
  File "/usr/local/lib/python3.9/site-packages/django/db/models/query.py", line 406, in get
    raise self.model.DoesNotExist(
challenges.models.Challenge.DoesNotExist: Challenge matching query does not exist.
[2025-07-09 19:01:14] INFO aws_utils Set CloudWatch log retention for challenge 19 to 545 days
[2025-07-09 19:01:14] INFO aws_utils Set CloudWatch log retention for challenge 5 to 545 days
[2025-07-09 19:01:14] INFO aws_utils Set CloudWatch log retention for challenge 6 to 1 days
[2025-07-09 19:01:14] INFO aws_utils Updated log retention for approved challenge 19
[2025-07-09 19:01:14] INFO aws_utils Updated log retention for restarted challenge 19
[2025-07-09 19:01:14] INFO aws_utils Updated log retention for challenge 19 task definition
[2025-07-09 19:01:14] ERROR aws_utils Unexpected error setting log retention for challenge 999999
Traceback (most recent call last):
  File "/code/apps/challenges/aws_utils.py", line 1968, in set_cloudwatch_log_retention
    challenge_obj = Challenge.objects.get(pk=challenge_pk)
  File "/usr/local/lib/python3.9/site-packages/django/db/models/manager.py", line 82, in manager_method
    return getattr(self.get_queryset(), name)(*args, **kwargs)
  File "/usr/local/lib/python3.9/site-packages/django/db/models/query.py", line 406, in get
    raise self.model.DoesNotExist(
challenges.models.Challenge.DoesNotExist: Challenge matching query does not exist.
[2025-07-09 19:01:14] INFO aws_utils Set CloudWatch log retention for challenge 19 to 545 days
[2025-07-09 20:31:12] ERROR aws_utils Failed to set log retention for challenge 126
Traceback (most recent call last):
  File "/code/apps/challenges/aws_utils.py", line 2006, in set_cloudwatch_log_retention
    logs_client.put_retention_policy(
  File "/usr/local/lib/python3.9/site-packages/botocore/client.py", line 535, in _api_call
    return self._make_api_call(operation_name, kwargs)
  File "/usr/local/lib/python3.9/site-packages/botocore/client.py", line 980, in _make_api_call
    raise error_class(parsed_response, operation_name)
botocore.errorfactory.UnrecognizedClientException: An error occurred (UnrecognizedClientException) when calling the PutRetentionPolicy operation: The security token included in the request is invalid.
[2025-07-09 20:31:12] WARNING aws_utils Failed to update log retention for challenge 126: An error occurred (UnrecognizedClientException) when calling the PutRetentionPolicy operation: The security token included in the request is invalid.
[2025-07-09 20:31:13] INFO aws_utils Deleted 0 files for submission 144
[2025-07-09 20:31:15] ERROR aws_utils Failed to set log retention for challenge 136
Traceback (most recent call last):
  File "/code/apps/challenges/aws_utils.py", line 2006, in set_cloudwatch_log_retention
    logs_client.put_retention_policy(
  File "/usr/local/lib/python3.9/site-packages/botocore/client.py", line 535, in _api_call
    return self._make_api_call(operation_name, kwargs)
  File "/usr/local/lib/python3.9/site-packages/botocore/client.py", line 980, in _make_api_call
    raise error_class(parsed_response, operation_name)
botocore.errorfactory.UnrecognizedClientException: An error occurred (UnrecognizedClientException) when calling the PutRetentionPolicy operation: The security token included in the request is invalid.
[2025-07-09 20:31:16] ERROR aws_utils Failed to set log retention for challenge 138
Traceback (most recent call last):
  File "/code/apps/challenges/aws_utils.py", line 2006, in set_cloudwatch_log_retention
    logs_client.put_retention_policy(
  File "/usr/local/lib/python3.9/site-packages/botocore/client.py", line 535, in _api_call
    return self._make_api_call(operation_name, kwargs)
  File "/usr/local/lib/python3.9/site-packages/botocore/client.py", line 980, in _make_api_call
    raise error_class(parsed_response, operation_name)
botocore.errorfactory.UnrecognizedClientException: An error occurred (UnrecognizedClientException) when calling the PutRetentionPolicy operation: The security token included in the request is invalid.
[2025-07-09 20:31:17] ERROR aws_utils Failed to set log retention for challenge 139
Traceback (most recent call last):
  File "/code/apps/challenges/aws_utils.py", line 2006, in set_cloudwatch_log_retention
    logs_client.put_retention_policy(
  File "/usr/local/lib/python3.9/site-packages/botocore/client.py", line 535, in _api_call
    return self._make_api_call(operation_name, kwargs)
  File "/usr/local/lib/python3.9/site-packages/botocore/client.py", line 980, in _make_api_call
    raise error_class(parsed_response, operation_name)
botocore.errorfactory.UnrecognizedClientException: An error occurred (UnrecognizedClientException) when calling the PutRetentionPolicy operation: The security token included in the request is invalid.
[2025-07-09 20:31:18] INFO aws_utils The worker service for challenge 144 was restarted, as evaluation_script was changed.
[2025-07-09 20:31:18] WARNING aws_utils Worker(s) for challenge 144 couldn't restart! Error: Please select challenges with active workers only.
[2025-07-09 20:31:18] INFO aws_utils The worker service for challenge 145 was restarted, as evaluation_script was changed.
[2025-07-09 20:31:18] WARNING aws_utils Worker(s) for challenge 145 couldn't restart! Error: Please select challenges with active workers only.
[2025-07-09 20:31:18] INFO aws_utils The worker service for challenge 146 was restarted, as evaluation_script was changed.
[2025-07-09 20:31:18] WARNING aws_utils Worker(s) for challenge 146 couldn't restart! Error: Please select challenges with active workers only.
[2025-07-09 20:31:18] INFO aws_utils The worker service for challenge 147 was restarted, as evaluation_script was changed.
[2025-07-09 20:31:18] WARNING aws_utils Worker(s) for challenge 147 couldn't restart! Error: Please select challenges with active workers only.
[2025-07-09 20:31:18] INFO aws_utils The worker service for challenge 147 was restarted, as evaluation_script was changed.
[2025-07-09 20:31:18] WARNING aws_utils Worker(s) for challenge 147 couldn't restart! Error: Please select challenges with active workers only.
[2025-07-09 20:31:18] INFO aws_utils The worker service for challenge 148 was restarted, as evaluation_script was changed.
[2025-07-09 20:31:18] WARNING aws_utils Worker(s) for challenge 148 couldn't restart! Error: Please select challenges with active workers only.
[2025-07-09 20:31:18] INFO aws_utils The worker service for challenge 149 was restarted, as evaluation_script was changed.
[2025-07-09 20:31:18] WARNING aws_utils Worker(s) for challenge 149 couldn't restart! Error: Please select challenges with active workers only.
[2025-07-09 20:31:18] INFO aws_utils The worker service for challenge 150 was restarted, as evaluation_script was changed.
[2025-07-09 20:31:18] WARNING aws_utils Worker(s) for challenge 150 couldn't restart! Error: Please select challenges with active workers only.
[2025-07-09 20:31:18] INFO aws_utils The worker service for challenge 151 was restarted, as evaluation_script was changed.
[2025-07-09 20:31:18] WARNING aws_utils Worker(s) for challenge 151 couldn't restart! Error: Please select challenges with active workers only.
[2025-07-09 20:31:18] INFO aws_utils The worker service for challenge 152 was restarted, as evaluation_script was changed.
[2025-07-09 20:31:18] WARNING aws_utils Worker(s) for challenge 152 couldn't restart! Error: Please select challenges with active workers only.
[2025-07-09 20:31:22] INFO aws_utils The worker service for challenge 336 was restarted, as test_annotation was changed.
[2025-07-09 20:31:22] WARNING aws_utils Worker(s) for challenge 336 couldn't restart! Error: Please select challenges with active workers only.
[2025-07-09 20:31:26] ERROR aws_utils An error occurred (UnrecognizedClientException) when calling the RegisterTaskDefinition operation: The security token included in the request is invalid.
Traceback (most recent call last):
  File "/code/apps/challenges/aws_utils.py", line 292, in register_task_def_by_challenge_pk
    response = client.register_task_definition(**definition)
  File "/usr/local/lib/python3.9/site-packages/botocore/client.py", line 535, in _api_call
    return self._make_api_call(operation_name, kwargs)
  File "/usr/local/lib/python3.9/site-packages/botocore/client.py", line 980, in _make_api_call
    raise error_class(parsed_response, operation_name)
botocore.exceptions.ClientError: An error occurred (UnrecognizedClientException) when calling the RegisterTaskDefinition operation: The security token included in the request is invalid.
[2025-07-09 20:31:26] ERROR aws_utils Worker for challenge 427 couldn't start! Error: {'Message': 'The security token included in the request is invalid.', 'Code': 'UnrecognizedClientException'}
[2025-07-09 20:31:26] WARNING aws_utils Failed to update log retention for challenge 427: No phases found for challenge 427
[2025-07-09 20:31:27] ERROR aws_utils An error occurred (UnrecognizedClientException) when calling the RegisterTaskDefinition operation: The security token included in the request is invalid.
Traceback (most recent call last):
  File "/code/apps/challenges/aws_utils.py", line 292, in register_task_def_by_challenge_pk
    response = client.register_task_definition(**definition)
  File "/usr/local/lib/python3.9/site-packages/botocore/client.py", line 535, in _api_call
    return self._make_api_call(operation_name, kwargs)
  File "/usr/local/lib/python3.9/site-packages/botocore/client.py", line 980, in _make_api_call
    raise error_class(parsed_response, operation_name)
botocore.exceptions.ClientError: An error occurred (UnrecognizedClientException) when calling the RegisterTaskDefinition operation: The security token included in the request is invalid.
[2025-07-09 20:31:27] ERROR aws_utils Worker for challenge 429 couldn't start! Error: {'Message': 'The security token included in the request is invalid.', 'Code': 'UnrecognizedClientException'}
[2025-07-09 20:31:27] WARNING aws_utils Failed to update log retention for challenge 429: No phases found for challenge 429
[2025-07-09 20:31:43] ERROR aws_utils An error occurred (SomeError) when calling the CreateService operation: Unknown
Traceback (most recent call last):
  File "/code/apps/challenges/aws_utils.py", line 365, in create_service_by_challenge_pk
    response = client.create_service(**definition)
  File "/usr/local/lib/python3.9/unittest/mock.py", line 1092, in __call__
    return self._mock_call(*args, **kwargs)
  File "/usr/local/lib/python3.9/unittest/mock.py", line 1096, in _mock_call
    return self._execute_mock_call(*args, **kwargs)
  File "/usr/local/lib/python3.9/unittest/mock.py", line 1151, in _execute_mock_call
    raise effect
botocore.exceptions.ClientError: An error occurred (SomeError) when calling the CreateService operation: Unknown
[2025-07-09 20:31:43] ERROR aws_utils An error occurred (ServiceError) when calling the UpdateService operation: Unknown
Traceback (most recent call last):
  File "/code/apps/challenges/aws_utils.py", line 414, in update_service_by_challenge_pk
    response = client.update_service(**kwargs)
  File "/usr/local/lib/python3.9/unittest/mock.py", line 1092, in __call__
    return self._mock_call(*args, **kwargs)
  File "/usr/local/lib/python3.9/unittest/mock.py", line 1096, in _mock_call
    return self._execute_mock_call(*args, **kwargs)
  File "/usr/local/lib/python3.9/unittest/mock.py", line 1151, in _execute_mock_call
    raise effect
botocore.exceptions.ClientError: An error occurred (ServiceError) when calling the UpdateService operation: Unknown
[2025-07-09 20:31:43] ERROR aws_utils An error occurred (DeregisterError) when calling the DeregisterTaskDefinition operation: Unknown
Traceback (most recent call last):
  File "/code/apps/challenges/aws_utils.py", line 459, in delete_service_by_challenge_pk
    client.deregister_task_definition(
  File "/usr/local/lib/python3.9/unittest/mock.py", line 1092, in __call__
    return self._mock_call(*args, **kwargs)
  File "/usr/local/lib/python3.9/unittest/mock.py", line 1096, in _mock_call
    return self._execute_mock_call(*args, **kwargs)
  File "/usr/local/lib/python3.9/unittest/mock.py", line 1151, in _execute_mock_call
    raise effect
botocore.exceptions.ClientError: An error occurred (DeregisterError) when calling the DeregisterTaskDefinition operation: Unknown
[2025-07-09 20:31:43] ERROR aws_utils An error occurred (DeleteServiceError) when calling the DeleteService operation: Unknown
Traceback (most recent call last):
  File "/code/apps/challenges/aws_utils.py", line 455, in delete_service_by_challenge_pk
    response = client.delete_service(**kwargs)
  File "/usr/local/lib/python3.9/unittest/mock.py", line 1092, in __call__
    return self._mock_call(*args, **kwargs)
  File "/usr/local/lib/python3.9/unittest/mock.py", line 1096, in _mock_call
    return self._execute_mock_call(*args, **kwargs)
  File "/usr/local/lib/python3.9/unittest/mock.py", line 1151, in _execute_mock_call
    raise effect
botocore.exceptions.ClientError: An error occurred (DeleteServiceError) when calling the DeleteService operation: Unknown
[2025-07-09 20:31:43] ERROR aws_utils An error occurred (Unknown) when calling the DeregisterTaskDefinition operation: Scaling inactive workers not supported
Traceback (most recent call last):
  File "/code/apps/challenges/aws_utils.py", line 1038, in scale_resources
    response = client.deregister_task_definition(
  File "/usr/local/lib/python3.9/unittest/mock.py", line 1092, in __call__
    return self._mock_call(*args, **kwargs)
  File "/usr/local/lib/python3.9/unittest/mock.py", line 1096, in _mock_call
    return self._execute_mock_call(*args, **kwargs)
  File "/usr/local/lib/python3.9/unittest/mock.py", line 1151, in _execute_mock_call
    raise effect
botocore.exceptions.ClientError: An error occurred (Unknown) when calling the DeregisterTaskDefinition operation: Scaling inactive workers not supported
[2025-07-09 20:40:04] ERROR aws_utils Failed to set log retention for challenge 126
Traceback (most recent call last):
  File "/code/apps/challenges/aws_utils.py", line 2006, in set_cloudwatch_log_retention
    logs_client.put_retention_policy(
  File "/usr/local/lib/python3.9/site-packages/botocore/client.py", line 535, in _api_call
    return self._make_api_call(operation_name, kwargs)
  File "/usr/local/lib/python3.9/site-packages/botocore/client.py", line 980, in _make_api_call
    raise error_class(parsed_response, operation_name)
botocore.errorfactory.UnrecognizedClientException: An error occurred (UnrecognizedClientException) when calling the PutRetentionPolicy operation: The security token included in the request is invalid.
[2025-07-09 20:40:04] WARNING aws_utils Failed to update log retention for challenge 126: An error occurred (UnrecognizedClientException) when calling the PutRetentionPolicy operation: The security token included in the request is invalid.
[2025-07-09 20:40:04] INFO aws_utils The worker service for challenge 128 was restarted, as evaluation_script was changed.
[2025-07-09 20:40:04] WARNING aws_utils Worker(s) for challenge 128 couldn't restart! Error: Please select challenges with active workers only.
[2025-07-09 20:40:04] INFO aws_utils The worker service for challenge 129 was restarted, as evaluation_script was changed.
[2025-07-09 20:40:04] WARNING aws_utils Worker(s) for challenge 129 couldn't restart! Error: Please select challenges with active workers only.
[2025-07-09 20:40:04] INFO aws_utils The worker service for challenge 130 was restarted, as evaluation_script was changed.
[2025-07-09 20:40:04] WARNING aws_utils Worker(s) for challenge 130 couldn't restart! Error: Please select challenges with active workers only.
[2025-07-09 20:40:04] INFO aws_utils The worker service for challenge 131 was restarted, as evaluation_script was changed.
[2025-07-09 20:40:04] WARNING aws_utils Worker(s) for challenge 131 couldn't restart! Error: Please select challenges with active workers only.
[2025-07-09 20:40:04] INFO aws_utils The worker service for challenge 131 was restarted, as evaluation_script was changed.
[2025-07-09 20:40:04] WARNING aws_utils Worker(s) for challenge 131 couldn't restart! Error: Please select challenges with active workers only.
[2025-07-09 20:40:04] INFO aws_utils The worker service for challenge 132 was restarted, as evaluation_script was changed.
[2025-07-09 20:40:04] WARNING aws_utils Worker(s) for challenge 132 couldn't restart! Error: Please select challenges with active workers only.
[2025-07-09 20:40:04] INFO aws_utils The worker service for challenge 133 was restarted, as evaluation_script was changed.
[2025-07-09 20:40:04] WARNING aws_utils Worker(s) for challenge 133 couldn't restart! Error: Please select challenges with active workers only.
[2025-07-09 20:40:04] INFO aws_utils The worker service for challenge 134 was restarted, as evaluation_script was changed.
[2025-07-09 20:40:04] WARNING aws_utils Worker(s) for challenge 134 couldn't restart! Error: Please select challenges with active workers only.
[2025-07-09 20:40:04] INFO aws_utils The worker service for challenge 135 was restarted, as evaluation_script was changed.
[2025-07-09 20:40:04] WARNING aws_utils Worker(s) for challenge 135 couldn't restart! Error: Please select challenges with active workers only.
[2025-07-09 20:40:04] INFO aws_utils The worker service for challenge 136 was restarted, as evaluation_script was changed.
[2025-07-09 20:40:04] WARNING aws_utils Worker(s) for challenge 136 couldn't restart! Error: Please select challenges with active workers only.
[2025-07-09 20:40:08] INFO aws_utils The worker service for challenge 320 was restarted, as test_annotation was changed.
[2025-07-09 20:40:08] WARNING aws_utils Worker(s) for challenge 320 couldn't restart! Error: Please select challenges with active workers only.
[2025-07-09 20:40:28] ERROR aws_utils An error occurred (Unknown) when calling the DeregisterTaskDefinition operation: Scaling inactive workers not supported
Traceback (most recent call last):
  File "/code/apps/challenges/aws_utils.py", line 1038, in scale_resources
    response = client.deregister_task_definition(
  File "/usr/local/lib/python3.9/unittest/mock.py", line 1092, in __call__
    return self._mock_call(*args, **kwargs)
  File "/usr/local/lib/python3.9/unittest/mock.py", line 1096, in _mock_call
    return self._execute_mock_call(*args, **kwargs)
  File "/usr/local/lib/python3.9/unittest/mock.py", line 1151, in _execute_mock_call
    raise effect
botocore.exceptions.ClientError: An error occurred (Unknown) when calling the DeregisterTaskDefinition operation: Scaling inactive workers not supported
[2025-07-09 20:51:26] ERROR aws_utils Failed to set log retention for challenge 126
Traceback (most recent call last):
  File "/code/apps/challenges/aws_utils.py", line 2006, in set_cloudwatch_log_retention
    logs_client.put_retention_policy(
  File "/usr/local/lib/python3.9/site-packages/botocore/client.py", line 535, in _api_call
    return self._make_api_call(operation_name, kwargs)
  File "/usr/local/lib/python3.9/site-packages/botocore/client.py", line 980, in _make_api_call
    raise error_class(parsed_response, operation_name)
botocore.errorfactory.UnrecognizedClientException: An error occurred (UnrecognizedClientException) when calling the PutRetentionPolicy operation: The security token included in the request is invalid.
[2025-07-09 20:51:26] WARNING aws_utils Failed to update log retention for challenge 126: An error occurred (UnrecognizedClientException) when calling the PutRetentionPolicy operation: The security token included in the request is invalid.
[2025-07-09 20:51:26] INFO aws_utils The worker service for challenge 128 was restarted, as evaluation_script was changed.
[2025-07-09 20:51:26] WARNING aws_utils Worker(s) for challenge 128 couldn't restart! Error: Please select challenges with active workers only.
[2025-07-09 20:51:26] INFO aws_utils The worker service for challenge 129 was restarted, as evaluation_script was changed.
[2025-07-09 20:51:26] WARNING aws_utils Worker(s) for challenge 129 couldn't restart! Error: Please select challenges with active workers only.
[2025-07-09 20:51:26] INFO aws_utils The worker service for challenge 130 was restarted, as evaluation_script was changed.
[2025-07-09 20:51:26] WARNING aws_utils Worker(s) for challenge 130 couldn't restart! Error: Please select challenges with active workers only.
[2025-07-09 20:51:26] INFO aws_utils The worker service for challenge 131 was restarted, as evaluation_script was changed.
[2025-07-09 20:51:26] WARNING aws_utils Worker(s) for challenge 131 couldn't restart! Error: Please select challenges with active workers only.
[2025-07-09 20:51:26] INFO aws_utils The worker service for challenge 131 was restarted, as evaluation_script was changed.
[2025-07-09 20:51:26] WARNING aws_utils Worker(s) for challenge 131 couldn't restart! Error: Please select challenges with active workers only.
[2025-07-09 20:51:26] INFO aws_utils The worker service for challenge 132 was restarted, as evaluation_script was changed.
[2025-07-09 20:51:26] WARNING aws_utils Worker(s) for challenge 132 couldn't restart! Error: Please select challenges with active workers only.
[2025-07-09 20:51:26] INFO aws_utils The worker service for challenge 133 was restarted, as evaluation_script was changed.
[2025-07-09 20:51:26] WARNING aws_utils Worker(s) for challenge 133 couldn't restart! Error: Please select challenges with active workers only.
[2025-07-09 20:51:26] INFO aws_utils The worker service for challenge 134 was restarted, as evaluation_script was changed.
[2025-07-09 20:51:26] WARNING aws_utils Worker(s) for challenge 134 couldn't restart! Error: Please select challenges with active workers only.
[2025-07-09 20:51:26] INFO aws_utils The worker service for challenge 135 was restarted, as evaluation_script was changed.
[2025-07-09 20:51:26] WARNING aws_utils Worker(s) for challenge 135 couldn't restart! Error: Please select challenges with active workers only.
[2025-07-09 20:51:26] INFO aws_utils The worker service for challenge 136 was restarted, as evaluation_script was changed.
[2025-07-09 20:51:26] WARNING aws_utils Worker(s) for challenge 136 couldn't restart! Error: Please select challenges with active workers only.
[2025-07-09 20:51:30] INFO aws_utils The worker service for challenge 320 was restarted, as test_annotation was changed.
[2025-07-09 20:51:30] WARNING aws_utils Worker(s) for challenge 320 couldn't restart! Error: Please select challenges with active workers only.
[2025-07-09 20:51:49] ERROR aws_utils An error occurred (Unknown) when calling the DeregisterTaskDefinition operation: Scaling inactive workers not supported
Traceback (most recent call last):
  File "/code/apps/challenges/aws_utils.py", line 1038, in scale_resources
    response = client.deregister_task_definition(
  File "/usr/local/lib/python3.9/unittest/mock.py", line 1092, in __call__
    return self._mock_call(*args, **kwargs)
  File "/usr/local/lib/python3.9/unittest/mock.py", line 1096, in _mock_call
    return self._execute_mock_call(*args, **kwargs)
  File "/usr/local/lib/python3.9/unittest/mock.py", line 1151, in _execute_mock_call
    raise effect
botocore.exceptions.ClientError: An error occurred (Unknown) when calling the DeregisterTaskDefinition operation: Scaling inactive workers not supported
[2025-07-09 21:00:12] INFO aws_utils Updated log retention for approved challenge 5
[2025-07-09 21:02:08] INFO aws_utils Updated log retention for approved challenge 126
[2025-07-09 21:02:12] ERROR aws_utils Failed to set log retention for challenge 128
Traceback (most recent call last):
  File "/code/apps/challenges/aws_utils.py", line 2006, in set_cloudwatch_log_retention
    logs_client.put_retention_policy(
  File "/usr/local/lib/python3.9/site-packages/botocore/client.py", line 535, in _api_call
    return self._make_api_call(operation_name, kwargs)
  File "/usr/local/lib/python3.9/site-packages/botocore/client.py", line 980, in _make_api_call
    raise error_class(parsed_response, operation_name)
botocore.errorfactory.UnrecognizedClientException: An error occurred (UnrecognizedClientException) when calling the PutRetentionPolicy operation: The security token included in the request is invalid.
[2025-07-09 21:02:12] WARNING aws_utils Failed to update log retention for challenge 128: An error occurred (UnrecognizedClientException) when calling the PutRetentionPolicy operation: The security token included in the request is invalid.
[2025-07-09 21:02:12] INFO aws_utils The worker service for challenge 130 was restarted, as evaluation_script was changed.
[2025-07-09 21:02:12] WARNING aws_utils Worker(s) for challenge 130 couldn't restart! Error: Please select challenges with active workers only.
[2025-07-09 21:02:12] INFO aws_utils The worker service for challenge 131 was restarted, as evaluation_script was changed.
[2025-07-09 21:02:12] WARNING aws_utils Worker(s) for challenge 131 couldn't restart! Error: Please select challenges with active workers only.
[2025-07-09 21:02:12] INFO aws_utils The worker service for challenge 132 was restarted, as evaluation_script was changed.
[2025-07-09 21:02:12] WARNING aws_utils Worker(s) for challenge 132 couldn't restart! Error: Please select challenges with active workers only.
[2025-07-09 21:02:12] INFO aws_utils The worker service for challenge 133 was restarted, as evaluation_script was changed.
[2025-07-09 21:02:12] WARNING aws_utils Worker(s) for challenge 133 couldn't restart! Error: Please select challenges with active workers only.
[2025-07-09 21:02:12] INFO aws_utils The worker service for challenge 133 was restarted, as evaluation_script was changed.
[2025-07-09 21:02:12] WARNING aws_utils Worker(s) for challenge 133 couldn't restart! Error: Please select challenges with active workers only.
[2025-07-09 21:02:12] INFO aws_utils The worker service for challenge 134 was restarted, as evaluation_script was changed.
[2025-07-09 21:02:12] WARNING aws_utils Worker(s) for challenge 134 couldn't restart! Error: Please select challenges with active workers only.
[2025-07-09 21:02:12] INFO aws_utils The worker service for challenge 135 was restarted, as evaluation_script was changed.
[2025-07-09 21:02:12] WARNING aws_utils Worker(s) for challenge 135 couldn't restart! Error: Please select challenges with active workers only.
[2025-07-09 21:02:12] INFO aws_utils The worker service for challenge 136 was restarted, as evaluation_script was changed.
[2025-07-09 21:02:12] WARNING aws_utils Worker(s) for challenge 136 couldn't restart! Error: Please select challenges with active workers only.
[2025-07-09 21:02:12] INFO aws_utils The worker service for challenge 137 was restarted, as evaluation_script was changed.
[2025-07-09 21:02:12] WARNING aws_utils Worker(s) for challenge 137 couldn't restart! Error: Please select challenges with active workers only.
[2025-07-09 21:02:12] INFO aws_utils The worker service for challenge 138 was restarted, as evaluation_script was changed.
[2025-07-09 21:02:12] WARNING aws_utils Worker(s) for challenge 138 couldn't restart! Error: Please select challenges with active workers only.
[2025-07-09 21:02:16] INFO aws_utils The worker service for challenge 322 was restarted, as test_annotation was changed.
[2025-07-09 21:02:16] WARNING aws_utils Worker(s) for challenge 322 couldn't restart! Error: Please select challenges with active workers only.
[2025-07-09 21:02:37] ERROR aws_utils An error occurred (Unknown) when calling the DeregisterTaskDefinition operation: Scaling inactive workers not supported
Traceback (most recent call last):
  File "/code/apps/challenges/aws_utils.py", line 1038, in scale_resources
    response = client.deregister_task_definition(
  File "/usr/local/lib/python3.9/unittest/mock.py", line 1092, in __call__
    return self._mock_call(*args, **kwargs)
  File "/usr/local/lib/python3.9/unittest/mock.py", line 1096, in _mock_call
    return self._execute_mock_call(*args, **kwargs)
  File "/usr/local/lib/python3.9/unittest/mock.py", line 1151, in _execute_mock_call
    raise effect
botocore.exceptions.ClientError: An error occurred (Unknown) when calling the DeregisterTaskDefinition operation: Scaling inactive workers not supported
[2025-07-09 21:12:51] ERROR aws_utils An error occurred (SomeError) when calling the CreateService operation: Unknown
Traceback (most recent call last):
  File "/code/apps/challenges/aws_utils.py", line 365, in create_service_by_challenge_pk
    response = client.create_service(**definition)
  File "/usr/local/lib/python3.9/unittest/mock.py", line 1092, in __call__
    return self._mock_call(*args, **kwargs)
  File "/usr/local/lib/python3.9/unittest/mock.py", line 1096, in _mock_call
    return self._execute_mock_call(*args, **kwargs)
  File "/usr/local/lib/python3.9/unittest/mock.py", line 1151, in _execute_mock_call
    raise effect
botocore.exceptions.ClientError: An error occurred (SomeError) when calling the CreateService operation: Unknown
[2025-07-09 21:13:26] INFO aws_utils Updated log retention for approved challenge 5
[2025-07-09 21:13:26] ERROR aws_utils An error occurred (SomeError) when calling the CreateService operation: Unknown
Traceback (most recent call last):
  File "/code/apps/challenges/aws_utils.py", line 365, in create_service_by_challenge_pk
    response = client.create_service(**definition)
  File "/usr/local/lib/python3.9/unittest/mock.py", line 1092, in __call__
    return self._mock_call(*args, **kwargs)
  File "/usr/local/lib/python3.9/unittest/mock.py", line 1096, in _mock_call
    return self._execute_mock_call(*args, **kwargs)
  File "/usr/local/lib/python3.9/unittest/mock.py", line 1151, in _execute_mock_call
    raise effect
botocore.exceptions.ClientError: An error occurred (SomeError) when calling the CreateService operation: Unknown
[2025-07-09 21:13:26] ERROR aws_utils An error occurred (ServiceError) when calling the UpdateService operation: Unknown
Traceback (most recent call last):
  File "/code/apps/challenges/aws_utils.py", line 414, in update_service_by_challenge_pk
    response = client.update_service(**kwargs)
  File "/usr/local/lib/python3.9/unittest/mock.py", line 1092, in __call__
    return self._mock_call(*args, **kwargs)
  File "/usr/local/lib/python3.9/unittest/mock.py", line 1096, in _mock_call
    return self._execute_mock_call(*args, **kwargs)
  File "/usr/local/lib/python3.9/unittest/mock.py", line 1151, in _execute_mock_call
    raise effect
botocore.exceptions.ClientError: An error occurred (ServiceError) when calling the UpdateService operation: Unknown
[2025-07-09 21:13:26] ERROR aws_utils An error occurred (DeleteServiceError) when calling the DeleteService operation: Unknown
Traceback (most recent call last):
  File "/code/apps/challenges/aws_utils.py", line 455, in delete_service_by_challenge_pk
    response = client.delete_service(**kwargs)
  File "/usr/local/lib/python3.9/unittest/mock.py", line 1092, in __call__
    return self._mock_call(*args, **kwargs)
  File "/usr/local/lib/python3.9/unittest/mock.py", line 1096, in _mock_call
    return self._execute_mock_call(*args, **kwargs)
  File "/usr/local/lib/python3.9/unittest/mock.py", line 1151, in _execute_mock_call
    raise effect
botocore.exceptions.ClientError: An error occurred (DeleteServiceError) when calling the DeleteService operation: Unknown
[2025-07-09 21:15:17] INFO aws_utils Updated log retention for approved challenge 126
[2025-07-09 21:15:21] ERROR aws_utils Failed to set log retention for challenge 128
Traceback (most recent call last):
  File "/code/apps/challenges/aws_utils.py", line 2006, in set_cloudwatch_log_retention
    logs_client.put_retention_policy(
  File "/usr/local/lib/python3.9/site-packages/botocore/client.py", line 535, in _api_call
    return self._make_api_call(operation_name, kwargs)
  File "/usr/local/lib/python3.9/site-packages/botocore/client.py", line 980, in _make_api_call
    raise error_class(parsed_response, operation_name)
botocore.errorfactory.UnrecognizedClientException: An error occurred (UnrecognizedClientException) when calling the PutRetentionPolicy operation: The security token included in the request is invalid.
[2025-07-09 21:15:21] WARNING aws_utils Failed to update log retention for challenge 128: An error occurred (UnrecognizedClientException) when calling the PutRetentionPolicy operation: The security token included in the request is invalid.
[2025-07-09 21:15:21] INFO aws_utils The worker service for challenge 130 was restarted, as evaluation_script was changed.
[2025-07-09 21:15:21] WARNING aws_utils Worker(s) for challenge 130 couldn't restart! Error: Please select challenges with active workers only.
[2025-07-09 21:15:21] INFO aws_utils The worker service for challenge 131 was restarted, as evaluation_script was changed.
[2025-07-09 21:15:21] WARNING aws_utils Worker(s) for challenge 131 couldn't restart! Error: Please select challenges with active workers only.
[2025-07-09 21:15:21] INFO aws_utils The worker service for challenge 132 was restarted, as evaluation_script was changed.
[2025-07-09 21:15:21] WARNING aws_utils Worker(s) for challenge 132 couldn't restart! Error: Please select challenges with active workers only.
[2025-07-09 21:15:21] INFO aws_utils The worker service for challenge 133 was restarted, as evaluation_script was changed.
[2025-07-09 21:15:21] WARNING aws_utils Worker(s) for challenge 133 couldn't restart! Error: Please select challenges with active workers only.
[2025-07-09 21:15:21] INFO aws_utils The worker service for challenge 133 was restarted, as evaluation_script was changed.
[2025-07-09 21:15:21] WARNING aws_utils Worker(s) for challenge 133 couldn't restart! Error: Please select challenges with active workers only.
[2025-07-09 21:15:21] INFO aws_utils The worker service for challenge 134 was restarted, as evaluation_script was changed.
