[2025-07-21 17:13:35] ERROR signal Signal handler <promise@0xffff9db94dc0 --> <bound method Celery._autodiscover_tasks of <Celery __main__ at 0xffff9dba4d00>>> raised: SyntaxError("unmatched ')'", ('/code/apps/challenges/aws_utils.py', 2220, 1, '):'))
Traceback (most recent call last):
  File "/usr/local/lib/python3.9/site-packages/celery/utils/dispatch/signal.py", line 288, in send
    response = receiver(signal=self, sender=sender, **named)
  File "/usr/local/lib/python3.9/site-packages/vine/promises.py", line 170, in __call__
    return self.throw()
  File "/usr/local/lib/python3.9/site-packages/vine/promises.py", line 167, in __call__
    retval = fun(*final_args, **final_kwargs)
  File "/usr/local/lib/python3.9/site-packages/celery/app/base.py", line 679, in _autodiscover_tasks
    return self._autodiscover_tasks_from_names(packages, related_name)
  File "/usr/local/lib/python3.9/site-packages/celery/app/base.py", line 684, in _autodiscover_tasks_from_names
    return self.loader.autodiscover_tasks(
  File "/usr/local/lib/python3.9/site-packages/celery/loaders/base.py", line 223, in autodiscover_tasks
    mod.__name__ for mod in autodiscover_tasks(packages or (),
  File "/usr/local/lib/python3.9/site-packages/celery/loaders/base.py", line 249, in autodiscover_tasks
    return [find_related_module(pkg, related_name) for pkg in packages]
  File "/usr/local/lib/python3.9/site-packages/celery/loaders/base.py", line 249, in <listcomp>
    return [find_related_module(pkg, related_name) for pkg in packages]
  File "/usr/local/lib/python3.9/site-packages/celery/loaders/base.py", line 268, in find_related_module
    return importlib.import_module('{0}.{1}'.format(package, related_name))
  File "/usr/local/lib/python3.9/importlib/__init__.py", line 127, in import_module
    return _bootstrap._gcd_import(name[level:], package, level)
  File "<frozen importlib._bootstrap>", line 1030, in _gcd_import
  File "<frozen importlib._bootstrap>", line 1007, in _find_and_load
  File "<frozen importlib._bootstrap>", line 986, in _find_and_load_unlocked
  File "<frozen importlib._bootstrap>", line 680, in _load_unlocked
  File "<frozen importlib._bootstrap_external>", line 850, in exec_module
  File "<frozen importlib._bootstrap>", line 228, in _call_with_frames_removed
  File "/code/apps/jobs/tasks.py", line 5, in <module>
    from challenges.models import ChallengePhase
  File "/code/apps/challenges/models.py", line 489, in <module>
    post_save_connect("evaluation_script", Challenge)
  File "/code/apps/challenges/models.py", line 478, in post_save_connect
    import challenges.aws_utils as aws
  File "/code/apps/challenges/aws_utils.py", line 2220
    ):
    ^
SyntaxError: unmatched ')'
[2025-07-21 17:13:37] ERROR signal Signal handler <bound method DjangoFixup.on_import_modules of <celery.fixups.django.DjangoFixup object at 0xffffa134d1c0>> raised: SyntaxError("unmatched ')'", ('/code/apps/challenges/aws_utils.py', 2220, 1, '):'))
Traceback (most recent call last):
  File "/usr/local/lib/python3.9/site-packages/celery/utils/dispatch/signal.py", line 288, in send
    response = receiver(signal=self, sender=sender, **named)
  File "/usr/local/lib/python3.9/site-packages/celery/fixups/django.py", line 84, in on_import_modules
    self.worker_fixup.validate_models()
  File "/usr/local/lib/python3.9/site-packages/celery/fixups/django.py", line 122, in validate_models
    self.django_setup()
  File "/usr/local/lib/python3.9/site-packages/celery/fixups/django.py", line 118, in django_setup
    django.setup()
  File "/usr/local/lib/python3.9/site-packages/django/__init__.py", line 24, in setup
    apps.populate(settings.INSTALLED_APPS)
  File "/usr/local/lib/python3.9/site-packages/django/apps/registry.py", line 114, in populate
    app_config.import_models()
  File "/usr/local/lib/python3.9/site-packages/django/apps/config.py", line 211, in import_models
    self.models_module = import_module(models_module_name)
  File "/usr/local/lib/python3.9/importlib/__init__.py", line 127, in import_module
    return _bootstrap._gcd_import(name[level:], package, level)
  File "<frozen importlib._bootstrap>", line 1030, in _gcd_import
  File "<frozen importlib._bootstrap>", line 1007, in _find_and_load
  File "<frozen importlib._bootstrap>", line 986, in _find_and_load_unlocked
  File "<frozen importlib._bootstrap>", line 680, in _load_unlocked
  File "<frozen importlib._bootstrap_external>", line 850, in exec_module
  File "<frozen importlib._bootstrap>", line 228, in _call_with_frames_removed
  File "/code/apps/challenges/models.py", line 489, in <module>
    post_save_connect("evaluation_script", Challenge)
  File "/code/apps/challenges/models.py", line 478, in post_save_connect
    import challenges.aws_utils as aws
  File "/code/apps/challenges/aws_utils.py", line 2220
    ):
    ^
SyntaxError: unmatched ')'
[2025-07-21 17:13:37] ERROR signal Signal handler <promise@0xffffa1384dc0 --> <bound method Celery._autodiscover_tasks of <Celery __main__ at 0xffffa1394d60>>> raised: SyntaxError("unmatched ')'", ('/code/apps/challenges/aws_utils.py', 2220, 1, '):'))
Traceback (most recent call last):
  File "/usr/local/lib/python3.9/site-packages/celery/utils/dispatch/signal.py", line 288, in send
    response = receiver(signal=self, sender=sender, **named)
  File "/usr/local/lib/python3.9/site-packages/vine/promises.py", line 170, in __call__
    return self.throw()
  File "/usr/local/lib/python3.9/site-packages/vine/promises.py", line 167, in __call__
    retval = fun(*final_args, **final_kwargs)
  File "/usr/local/lib/python3.9/site-packages/celery/app/base.py", line 679, in _autodiscover_tasks
    return self._autodiscover_tasks_from_names(packages, related_name)
  File "/usr/local/lib/python3.9/site-packages/celery/app/base.py", line 684, in _autodiscover_tasks_from_names
    return self.loader.autodiscover_tasks(
  File "/usr/local/lib/python3.9/site-packages/celery/loaders/base.py", line 223, in autodiscover_tasks
    mod.__name__ for mod in autodiscover_tasks(packages or (),
  File "/usr/local/lib/python3.9/site-packages/celery/loaders/base.py", line 249, in autodiscover_tasks
    return [find_related_module(pkg, related_name) for pkg in packages]
  File "/usr/local/lib/python3.9/site-packages/celery/loaders/base.py", line 249, in <listcomp>
    return [find_related_module(pkg, related_name) for pkg in packages]
  File "/usr/local/lib/python3.9/site-packages/celery/loaders/base.py", line 268, in find_related_module
    return importlib.import_module('{0}.{1}'.format(package, related_name))
  File "/usr/local/lib/python3.9/importlib/__init__.py", line 127, in import_module
    return _bootstrap._gcd_import(name[level:], package, level)
  File "<frozen importlib._bootstrap>", line 1030, in _gcd_import
  File "<frozen importlib._bootstrap>", line 1007, in _find_and_load
  File "<frozen importlib._bootstrap>", line 986, in _find_and_load_unlocked
  File "<frozen importlib._bootstrap>", line 680, in _load_unlocked
  File "<frozen importlib._bootstrap_external>", line 850, in exec_module
  File "<frozen importlib._bootstrap>", line 228, in _call_with_frames_removed
  File "/code/apps/jobs/tasks.py", line 5, in <module>
    from challenges.models import ChallengePhase
  File "/code/apps/challenges/models.py", line 489, in <module>
    post_save_connect("evaluation_script", Challenge)
  File "/code/apps/challenges/models.py", line 478, in post_save_connect
    import challenges.aws_utils as aws
  File "/code/apps/challenges/aws_utils.py", line 2220
    ):
    ^
SyntaxError: unmatched ')'
[2025-07-21 17:13:37] ERROR signal Signal handler <bound method DjangoFixup.on_import_modules of <celery.fixups.django.DjangoFixup object at 0xffff863af220>> raised: SyntaxError("unmatched ')'", ('/code/apps/challenges/aws_utils.py', 2220, 1, '):'))
Traceback (most recent call last):
  File "/usr/local/lib/python3.9/site-packages/celery/utils/dispatch/signal.py", line 288, in send
    response = receiver(signal=self, sender=sender, **named)
  File "/usr/local/lib/python3.9/site-packages/celery/fixups/django.py", line 84, in on_import_modules
    self.worker_fixup.validate_models()
  File "/usr/local/lib/python3.9/site-packages/celery/fixups/django.py", line 122, in validate_models
    self.django_setup()
  File "/usr/local/lib/python3.9/site-packages/celery/fixups/django.py", line 118, in django_setup
    django.setup()
  File "/usr/local/lib/python3.9/site-packages/django/__init__.py", line 24, in setup
    apps.populate(settings.INSTALLED_APPS)
  File "/usr/local/lib/python3.9/site-packages/django/apps/registry.py", line 114, in populate
    app_config.import_models()
  File "/usr/local/lib/python3.9/site-packages/django/apps/config.py", line 211, in import_models
    self.models_module = import_module(models_module_name)
  File "/usr/local/lib/python3.9/importlib/__init__.py", line 127, in import_module
    return _bootstrap._gcd_import(name[level:], package, level)
  File "<frozen importlib._bootstrap>", line 1030, in _gcd_import
  File "<frozen importlib._bootstrap>", line 1007, in _find_and_load
  File "<frozen importlib._bootstrap>", line 986, in _find_and_load_unlocked
  File "<frozen importlib._bootstrap>", line 680, in _load_unlocked
  File "<frozen importlib._bootstrap_external>", line 850, in exec_module
  File "<frozen importlib._bootstrap>", line 228, in _call_with_frames_removed
  File "/code/apps/challenges/models.py", line 489, in <module>
    post_save_connect("evaluation_script", Challenge)
  File "/code/apps/challenges/models.py", line 478, in post_save_connect
    import challenges.aws_utils as aws
  File "/code/apps/challenges/aws_utils.py", line 2220
    ):
    ^
SyntaxError: unmatched ')'
[2025-07-21 17:13:37] ERROR signal Signal handler <promise@0xffff863e4dc0 --> <bound method Celery._autodiscover_tasks of <Celery __main__ at 0xffff863f4cd0>>> raised: SyntaxError("unmatched ')'", ('/code/apps/challenges/aws_utils.py', 2220, 1, '):'))
Traceback (most recent call last):
  File "/usr/local/lib/python3.9/site-packages/celery/utils/dispatch/signal.py", line 288, in send
    response = receiver(signal=self, sender=sender, **named)
  File "/usr/local/lib/python3.9/site-packages/vine/promises.py", line 170, in __call__
    return self.throw()
  File "/usr/local/lib/python3.9/site-packages/vine/promises.py", line 167, in __call__
    retval = fun(*final_args, **final_kwargs)
  File "/usr/local/lib/python3.9/site-packages/celery/app/base.py", line 679, in _autodiscover_tasks
    return self._autodiscover_tasks_from_names(packages, related_name)
  File "/usr/local/lib/python3.9/site-packages/celery/app/base.py", line 684, in _autodiscover_tasks_from_names
    return self.loader.autodiscover_tasks(
  File "/usr/local/lib/python3.9/site-packages/celery/loaders/base.py", line 223, in autodiscover_tasks
    mod.__name__ for mod in autodiscover_tasks(packages or (),
  File "/usr/local/lib/python3.9/site-packages/celery/loaders/base.py", line 249, in autodiscover_tasks
    return [find_related_module(pkg, related_name) for pkg in packages]
  File "/usr/local/lib/python3.9/site-packages/celery/loaders/base.py", line 249, in <listcomp>
    return [find_related_module(pkg, related_name) for pkg in packages]
  File "/usr/local/lib/python3.9/site-packages/celery/loaders/base.py", line 268, in find_related_module
    return importlib.import_module('{0}.{1}'.format(package, related_name))
  File "/usr/local/lib/python3.9/importlib/__init__.py", line 127, in import_module
    return _bootstrap._gcd_import(name[level:], package, level)
  File "<frozen importlib._bootstrap>", line 1030, in _gcd_import
  File "<frozen importlib._bootstrap>", line 1007, in _find_and_load
  File "<frozen importlib._bootstrap>", line 986, in _find_and_load_unlocked
  File "<frozen importlib._bootstrap>", line 680, in _load_unlocked
  File "<frozen importlib._bootstrap_external>", line 850, in exec_module
  File "<frozen importlib._bootstrap>", line 228, in _call_with_frames_removed
  File "/code/apps/jobs/tasks.py", line 5, in <module>
    from challenges.models import ChallengePhase
  File "/code/apps/challenges/models.py", line 489, in <module>
    post_save_connect("evaluation_script", Challenge)
  File "/code/apps/challenges/models.py", line 478, in post_save_connect
    import challenges.aws_utils as aws
  File "/code/apps/challenges/aws_utils.py", line 2220
    ):
    ^
SyntaxError: unmatched ')'
[2025-07-21 17:13:38] ERROR signal Signal handler <bound method DjangoFixup.on_import_modules of <celery.fixups.django.DjangoFixup object at 0xffff8101c1c0>> raised: SyntaxError("unmatched ')'", ('/code/apps/challenges/aws_utils.py', 2220, 1, '):'))
Traceback (most recent call last):
  File "/usr/local/lib/python3.9/site-packages/celery/utils/dispatch/signal.py", line 288, in send
    response = receiver(signal=self, sender=sender, **named)
  File "/usr/local/lib/python3.9/site-packages/celery/fixups/django.py", line 84, in on_import_modules
    self.worker_fixup.validate_models()
  File "/usr/local/lib/python3.9/site-packages/celery/fixups/django.py", line 122, in validate_models
    self.django_setup()
  File "/usr/local/lib/python3.9/site-packages/celery/fixups/django.py", line 118, in django_setup
    django.setup()
  File "/usr/local/lib/python3.9/site-packages/django/__init__.py", line 24, in setup
    apps.populate(settings.INSTALLED_APPS)
  File "/usr/local/lib/python3.9/site-packages/django/apps/registry.py", line 114, in populate
    app_config.import_models()
  File "/usr/local/lib/python3.9/site-packages/django/apps/config.py", line 211, in import_models
    self.models_module = import_module(models_module_name)
  File "/usr/local/lib/python3.9/importlib/__init__.py", line 127, in import_module
    return _bootstrap._gcd_import(name[level:], package, level)
  File "<frozen importlib._bootstrap>", line 1030, in _gcd_import
  File "<frozen importlib._bootstrap>", line 1007, in _find_and_load
  File "<frozen importlib._bootstrap>", line 986, in _find_and_load_unlocked
  File "<frozen importlib._bootstrap>", line 680, in _load_unlocked
  File "<frozen importlib._bootstrap_external>", line 850, in exec_module
  File "<frozen importlib._bootstrap>", line 228, in _call_with_frames_removed
  File "/code/apps/challenges/models.py", line 489, in <module>
    post_save_connect("evaluation_script", Challenge)
  File "/code/apps/challenges/models.py", line 478, in post_save_connect
    import challenges.aws_utils as aws
  File "/code/apps/challenges/aws_utils.py", line 2220
    ):
    ^
SyntaxError: unmatched ')'
[2025-07-21 17:13:38] ERROR signal Signal handler <promise@0xffff81054dc0 --> <bound method Celery._autodiscover_tasks of <Celery __main__ at 0xffff81064d60>>> raised: SyntaxError("unmatched ')'", ('/code/apps/challenges/aws_utils.py', 2220, 1, '):'))
Traceback (most recent call last):
  File "/usr/local/lib/python3.9/site-packages/celery/utils/dispatch/signal.py", line 288, in send
    response = receiver(signal=self, sender=sender, **named)
  File "/usr/local/lib/python3.9/site-packages/vine/promises.py", line 170, in __call__
    return self.throw()
  File "/usr/local/lib/python3.9/site-packages/vine/promises.py", line 167, in __call__
    retval = fun(*final_args, **final_kwargs)
  File "/usr/local/lib/python3.9/site-packages/celery/app/base.py", line 679, in _autodiscover_tasks
    return self._autodiscover_tasks_from_names(packages, related_name)
  File "/usr/local/lib/python3.9/site-packages/celery/app/base.py", line 684, in _autodiscover_tasks_from_names
    return self.loader.autodiscover_tasks(
  File "/usr/local/lib/python3.9/site-packages/celery/loaders/base.py", line 223, in autodiscover_tasks
    mod.__name__ for mod in autodiscover_tasks(packages or (),
  File "/usr/local/lib/python3.9/site-packages/celery/loaders/base.py", line 249, in autodiscover_tasks
    return [find_related_module(pkg, related_name) for pkg in packages]
  File "/usr/local/lib/python3.9/site-packages/celery/loaders/base.py", line 249, in <listcomp>
    return [find_related_module(pkg, related_name) for pkg in packages]
  File "/usr/local/lib/python3.9/site-packages/celery/loaders/base.py", line 268, in find_related_module
    return importlib.import_module('{0}.{1}'.format(package, related_name))
  File "/usr/local/lib/python3.9/importlib/__init__.py", line 127, in import_module
    return _bootstrap._gcd_import(name[level:], package, level)
  File "<frozen importlib._bootstrap>", line 1030, in _gcd_import
  File "<frozen importlib._bootstrap>", line 1007, in _find_and_load
  File "<frozen importlib._bootstrap>", line 986, in _find_and_load_unlocked
  File "<frozen importlib._bootstrap>", line 680, in _load_unlocked
  File "<frozen importlib._bootstrap_external>", line 850, in exec_module
  File "<frozen importlib._bootstrap>", line 228, in _call_with_frames_removed
  File "/code/apps/jobs/tasks.py", line 5, in <module>
    from challenges.models import ChallengePhase
  File "/code/apps/challenges/models.py", line 489, in <module>
    post_save_connect("evaluation_script", Challenge)
  File "/code/apps/challenges/models.py", line 478, in post_save_connect
    import challenges.aws_utils as aws
  File "/code/apps/challenges/aws_utils.py", line 2220
    ):
    ^
SyntaxError: unmatched ')'
[2025-07-21 17:13:38] ERROR signal Signal handler <bound method DjangoFixup.on_import_modules of <celery.fixups.django.DjangoFixup object at 0xffff892bf220>> raised: SyntaxError("unmatched ')'", ('/code/apps/challenges/aws_utils.py', 2220, 1, '):'))
Traceback (most recent call last):
  File "/usr/local/lib/python3.9/site-packages/celery/utils/dispatch/signal.py", line 288, in send
    response = receiver(signal=self, sender=sender, **named)
  File "/usr/local/lib/python3.9/site-packages/celery/fixups/django.py", line 84, in on_import_modules
    self.worker_fixup.validate_models()
  File "/usr/local/lib/python3.9/site-packages/celery/fixups/django.py", line 122, in validate_models
    self.django_setup()
  File "/usr/local/lib/python3.9/site-packages/celery/fixups/django.py", line 118, in django_setup
    django.setup()
  File "/usr/local/lib/python3.9/site-packages/django/__init__.py", line 24, in setup
    apps.populate(settings.INSTALLED_APPS)
  File "/usr/local/lib/python3.9/site-packages/django/apps/registry.py", line 114, in populate
    app_config.import_models()
  File "/usr/local/lib/python3.9/site-packages/django/apps/config.py", line 211, in import_models
    self.models_module = import_module(models_module_name)
  File "/usr/local/lib/python3.9/importlib/__init__.py", line 127, in import_module
    return _bootstrap._gcd_import(name[level:], package, level)
  File "<frozen importlib._bootstrap>", line 1030, in _gcd_import
  File "<frozen importlib._bootstrap>", line 1007, in _find_and_load
  File "<frozen importlib._bootstrap>", line 986, in _find_and_load_unlocked
  File "<frozen importlib._bootstrap>", line 680, in _load_unlocked
  File "<frozen importlib._bootstrap_external>", line 850, in exec_module
  File "<frozen importlib._bootstrap>", line 228, in _call_with_frames_removed
  File "/code/apps/challenges/models.py", line 489, in <module>
    post_save_connect("evaluation_script", Challenge)
  File "/code/apps/challenges/models.py", line 478, in post_save_connect
    import challenges.aws_utils as aws
  File "/code/apps/challenges/aws_utils.py", line 2220
    ):
    ^
SyntaxError: unmatched ')'
[2025-07-21 17:13:38] ERROR signal Signal handler <promise@0xffff892f4dc0 --> <bound method Celery._autodiscover_tasks of <Celery __main__ at 0xffff89304d00>>> raised: SyntaxError("unmatched ')'", ('/code/apps/challenges/aws_utils.py', 2220, 1, '):'))
Traceback (most recent call last):
  File "/usr/local/lib/python3.9/site-packages/celery/utils/dispatch/signal.py", line 288, in send
    response = receiver(signal=self, sender=sender, **named)
  File "/usr/local/lib/python3.9/site-packages/vine/promises.py", line 170, in __call__
    return self.throw()
  File "/usr/local/lib/python3.9/site-packages/vine/promises.py", line 167, in __call__
    retval = fun(*final_args, **final_kwargs)
  File "/usr/local/lib/python3.9/site-packages/celery/app/base.py", line 679, in _autodiscover_tasks
    return self._autodiscover_tasks_from_names(packages, related_name)
  File "/usr/local/lib/python3.9/site-packages/celery/app/base.py", line 684, in _autodiscover_tasks_from_names
    return self.loader.autodiscover_tasks(
  File "/usr/local/lib/python3.9/site-packages/celery/loaders/base.py", line 223, in autodiscover_tasks
    mod.__name__ for mod in autodiscover_tasks(packages or (),
  File "/usr/local/lib/python3.9/site-packages/celery/loaders/base.py", line 249, in autodiscover_tasks
    return [find_related_module(pkg, related_name) for pkg in packages]
  File "/usr/local/lib/python3.9/site-packages/celery/loaders/base.py", line 249, in <listcomp>
    return [find_related_module(pkg, related_name) for pkg in packages]
  File "/usr/local/lib/python3.9/site-packages/celery/loaders/base.py", line 268, in find_related_module
    return importlib.import_module('{0}.{1}'.format(package, related_name))
  File "/usr/local/lib/python3.9/importlib/__init__.py", line 127, in import_module
    return _bootstrap._gcd_import(name[level:], package, level)
  File "<frozen importlib._bootstrap>", line 1030, in _gcd_import
  File "<frozen importlib._bootstrap>", line 1007, in _find_and_load
  File "<frozen importlib._bootstrap>", line 986, in _find_and_load_unlocked
  File "<frozen importlib._bootstrap>", line 680, in _load_unlocked
  File "<frozen importlib._bootstrap_external>", line 850, in exec_module
  File "<frozen importlib._bootstrap>", line 228, in _call_with_frames_removed
  File "/code/apps/jobs/tasks.py", line 5, in <module>
    from challenges.models import ChallengePhase
  File "/code/apps/challenges/models.py", line 489, in <module>
    post_save_connect("evaluation_script", Challenge)
  File "/code/apps/challenges/models.py", line 478, in post_save_connect
    import challenges.aws_utils as aws
  File "/code/apps/challenges/aws_utils.py", line 2220
    ):
    ^
SyntaxError: unmatched ')'
[2025-07-21 17:13:39] ERROR signal Signal handler <bound method DjangoFixup.on_import_modules of <celery.fixups.django.DjangoFixup object at 0xffff8cabb1c0>> raised: SyntaxError("unmatched ')'", ('/code/apps/challenges/aws_utils.py', 2220, 1, '):'))
Traceback (most recent call last):
  File "/usr/local/lib/python3.9/site-packages/celery/utils/dispatch/signal.py", line 288, in send
    response = receiver(signal=self, sender=sender, **named)
  File "/usr/local/lib/python3.9/site-packages/celery/fixups/django.py", line 84, in on_import_modules
    self.worker_fixup.validate_models()
  File "/usr/local/lib/python3.9/site-packages/celery/fixups/django.py", line 122, in validate_models
    self.django_setup()
  File "/usr/local/lib/python3.9/site-packages/celery/fixups/django.py", line 118, in django_setup
    django.setup()
  File "/usr/local/lib/python3.9/site-packages/django/__init__.py", line 24, in setup
    apps.populate(settings.INSTALLED_APPS)
  File "/usr/local/lib/python3.9/site-packages/django/apps/registry.py", line 114, in populate
    app_config.import_models()
  File "/usr/local/lib/python3.9/site-packages/django/apps/config.py", line 211, in import_models
    self.models_module = import_module(models_module_name)
  File "/usr/local/lib/python3.9/importlib/__init__.py", line 127, in import_module
    return _bootstrap._gcd_import(name[level:], package, level)
  File "<frozen importlib._bootstrap>", line 1030, in _gcd_import
  File "<frozen importlib._bootstrap>", line 1007, in _find_and_load
  File "<frozen importlib._bootstrap>", line 986, in _find_and_load_unlocked
  File "<frozen importlib._bootstrap>", line 680, in _load_unlocked
  File "<frozen importlib._bootstrap_external>", line 850, in exec_module
  File "<frozen importlib._bootstrap>", line 228, in _call_with_frames_removed
  File "/code/apps/challenges/models.py", line 489, in <module>
    post_save_connect("evaluation_script", Challenge)
  File "/code/apps/challenges/models.py", line 478, in post_save_connect
    import challenges.aws_utils as aws
  File "/code/apps/challenges/aws_utils.py", line 2220
    ):
    ^
SyntaxError: unmatched ')'
[2025-07-21 17:13:39] ERROR signal Signal handler <promise@0xffff8caf4dc0 --> <bound method Celery._autodiscover_tasks of <Celery __main__ at 0xffff8cb04d60>>> raised: SyntaxError("unmatched ')'", ('/code/apps/challenges/aws_utils.py', 2220, 1, '):'))
Traceback (most recent call last):
  File "/usr/local/lib/python3.9/site-packages/celery/utils/dispatch/signal.py", line 288, in send
    response = receiver(signal=self, sender=sender, **named)
  File "/usr/local/lib/python3.9/site-packages/vine/promises.py", line 170, in __call__
    return self.throw()
  File "/usr/local/lib/python3.9/site-packages/vine/promises.py", line 167, in __call__
    retval = fun(*final_args, **final_kwargs)
  File "/usr/local/lib/python3.9/site-packages/celery/app/base.py", line 679, in _autodiscover_tasks
    return self._autodiscover_tasks_from_names(packages, related_name)
  File "/usr/local/lib/python3.9/site-packages/celery/app/base.py", line 684, in _autodiscover_tasks_from_names
    return self.loader.autodiscover_tasks(
  File "/usr/local/lib/python3.9/site-packages/celery/loaders/base.py", line 223, in autodiscover_tasks
    mod.__name__ for mod in autodiscover_tasks(packages or (),
  File "/usr/local/lib/python3.9/site-packages/celery/loaders/base.py", line 249, in autodiscover_tasks
    return [find_related_module(pkg, related_name) for pkg in packages]
  File "/usr/local/lib/python3.9/site-packages/celery/loaders/base.py", line 249, in <listcomp>
    return [find_related_module(pkg, related_name) for pkg in packages]
  File "/usr/local/lib/python3.9/site-packages/celery/loaders/base.py", line 268, in find_related_module
    return importlib.import_module('{0}.{1}'.format(package, related_name))
  File "/usr/local/lib/python3.9/importlib/__init__.py", line 127, in import_module
    return _bootstrap._gcd_import(name[level:], package, level)
  File "<frozen importlib._bootstrap>", line 1030, in _gcd_import
  File "<frozen importlib._bootstrap>", line 1007, in _find_and_load
  File "<frozen importlib._bootstrap>", line 986, in _find_and_load_unlocked
  File "<frozen importlib._bootstrap>", line 680, in _load_unlocked
  File "<frozen importlib._bootstrap_external>", line 850, in exec_module
  File "<frozen importlib._bootstrap>", line 228, in _call_with_frames_removed
  File "/code/apps/jobs/tasks.py", line 5, in <module>
    from challenges.models import ChallengePhase
  File "/code/apps/challenges/models.py", line 489, in <module>
    post_save_connect("evaluation_script", Challenge)
  File "/code/apps/challenges/models.py", line 478, in post_save_connect
    import challenges.aws_utils as aws
  File "/code/apps/challenges/aws_utils.py", line 2220
    ):
    ^
SyntaxError: unmatched ')'
[2025-07-21 17:13:39] ERROR signal Signal handler <bound method DjangoFixup.on_import_modules of <celery.fixups.django.DjangoFixup object at 0xffffbc7af220>> raised: SyntaxError("unmatched ')'", ('/code/apps/challenges/aws_utils.py', 2220, 1, '):'))
Traceback (most recent call last):
  File "/usr/local/lib/python3.9/site-packages/celery/utils/dispatch/signal.py", line 288, in send
    response = receiver(signal=self, sender=sender, **named)
  File "/usr/local/lib/python3.9/site-packages/celery/fixups/django.py", line 84, in on_import_modules
    self.worker_fixup.validate_models()
  File "/usr/local/lib/python3.9/site-packages/celery/fixups/django.py", line 122, in validate_models
    self.django_setup()
  File "/usr/local/lib/python3.9/site-packages/celery/fixups/django.py", line 118, in django_setup
    django.setup()
  File "/usr/local/lib/python3.9/site-packages/django/__init__.py", line 24, in setup
    apps.populate(settings.INSTALLED_APPS)
  File "/usr/local/lib/python3.9/site-packages/django/apps/registry.py", line 114, in populate
    app_config.import_models()
  File "/usr/local/lib/python3.9/site-packages/django/apps/config.py", line 211, in import_models
    self.models_module = import_module(models_module_name)
  File "/usr/local/lib/python3.9/importlib/__init__.py", line 127, in import_module
    return _bootstrap._gcd_import(name[level:], package, level)
  File "<frozen importlib._bootstrap>", line 1030, in _gcd_import
  File "<frozen importlib._bootstrap>", line 1007, in _find_and_load
  File "<frozen importlib._bootstrap>", line 986, in _find_and_load_unlocked
  File "<frozen importlib._bootstrap>", line 680, in _load_unlocked
  File "<frozen importlib._bootstrap_external>", line 850, in exec_module
  File "<frozen importlib._bootstrap>", line 228, in _call_with_frames_removed
  File "/code/apps/challenges/models.py", line 489, in <module>
    post_save_connect("evaluation_script", Challenge)
  File "/code/apps/challenges/models.py", line 478, in post_save_connect
    import challenges.aws_utils as aws
  File "/code/apps/challenges/aws_utils.py", line 2220
    ):
    ^
SyntaxError: unmatched ')'
[2025-07-21 17:13:39] ERROR signal Signal handler <promise@0xffffbc7e4dc0 --> <bound method Celery._autodiscover_tasks of <Celery __main__ at 0xffffbc7f4d00>>> raised: SyntaxError("unmatched ')'", ('/code/apps/challenges/aws_utils.py', 2220, 1, '):'))
Traceback (most recent call last):
  File "/usr/local/lib/python3.9/site-packages/celery/utils/dispatch/signal.py", line 288, in send
    response = receiver(signal=self, sender=sender, **named)
  File "/usr/local/lib/python3.9/site-packages/vine/promises.py", line 170, in __call__
    return self.throw()
  File "/usr/local/lib/python3.9/site-packages/vine/promises.py", line 167, in __call__
    retval = fun(*final_args, **final_kwargs)
  File "/usr/local/lib/python3.9/site-packages/celery/app/base.py", line 679, in _autodiscover_tasks
    return self._autodiscover_tasks_from_names(packages, related_name)
  File "/usr/local/lib/python3.9/site-packages/celery/app/base.py", line 684, in _autodiscover_tasks_from_names
    return self.loader.autodiscover_tasks(
  File "/usr/local/lib/python3.9/site-packages/celery/loaders/base.py", line 223, in autodiscover_tasks
    mod.__name__ for mod in autodiscover_tasks(packages or (),
  File "/usr/local/lib/python3.9/site-packages/celery/loaders/base.py", line 249, in autodiscover_tasks
    return [find_related_module(pkg, related_name) for pkg in packages]
  File "/usr/local/lib/python3.9/site-packages/celery/loaders/base.py", line 249, in <listcomp>
    return [find_related_module(pkg, related_name) for pkg in packages]
  File "/usr/local/lib/python3.9/site-packages/celery/loaders/base.py", line 268, in find_related_module
    return importlib.import_module('{0}.{1}'.format(package, related_name))
  File "/usr/local/lib/python3.9/importlib/__init__.py", line 127, in import_module
    return _bootstrap._gcd_import(name[level:], package, level)
  File "<frozen importlib._bootstrap>", line 1030, in _gcd_import
  File "<frozen importlib._bootstrap>", line 1007, in _find_and_load
  File "<frozen importlib._bootstrap>", line 986, in _find_and_load_unlocked
  File "<frozen importlib._bootstrap>", line 680, in _load_unlocked
  File "<frozen importlib._bootstrap_external>", line 850, in exec_module
  File "<frozen importlib._bootstrap>", line 228, in _call_with_frames_removed
  File "/code/apps/jobs/tasks.py", line 5, in <module>
    from challenges.models import ChallengePhase
  File "/code/apps/challenges/models.py", line 489, in <module>
    post_save_connect("evaluation_script", Challenge)
  File "/code/apps/challenges/models.py", line 478, in post_save_connect
    import challenges.aws_utils as aws
  File "/code/apps/challenges/aws_utils.py", line 2220
    ):
    ^
SyntaxError: unmatched ')'
[2025-07-21 17:13:42] ERROR signal Signal handler <bound method DjangoFixup.on_import_modules of <celery.fixups.django.DjangoFixup object at 0xffff9e88c1c0>> raised: SyntaxError("unmatched ')'", ('/code/apps/challenges/aws_utils.py', 2220, 1, '):'))
Traceback (most recent call last):
  File "/usr/local/lib/python3.9/site-packages/celery/utils/dispatch/signal.py", line 288, in send
    response = receiver(signal=self, sender=sender, **named)
  File "/usr/local/lib/python3.9/site-packages/celery/fixups/django.py", line 84, in on_import_modules
    self.worker_fixup.validate_models()
  File "/usr/local/lib/python3.9/site-packages/celery/fixups/django.py", line 122, in validate_models
    self.django_setup()
  File "/usr/local/lib/python3.9/site-packages/celery/fixups/django.py", line 118, in django_setup
    django.setup()
  File "/usr/local/lib/python3.9/site-packages/django/__init__.py", line 24, in setup
    apps.populate(settings.INSTALLED_APPS)
  File "/usr/local/lib/python3.9/site-packages/django/apps/registry.py", line 114, in populate
    app_config.import_models()
  File "/usr/local/lib/python3.9/site-packages/django/apps/config.py", line 211, in import_models
    self.models_module = import_module(models_module_name)
  File "/usr/local/lib/python3.9/importlib/__init__.py", line 127, in import_module
    return _bootstrap._gcd_import(name[level:], package, level)
  File "<frozen importlib._bootstrap>", line 1030, in _gcd_import
  File "<frozen importlib._bootstrap>", line 1007, in _find_and_load
  File "<frozen importlib._bootstrap>", line 986, in _find_and_load_unlocked
  File "<frozen importlib._bootstrap>", line 680, in _load_unlocked
  File "<frozen importlib._bootstrap_external>", line 850, in exec_module
  File "<frozen importlib._bootstrap>", line 228, in _call_with_frames_removed
  File "/code/apps/challenges/models.py", line 489, in <module>
    post_save_connect("evaluation_script", Challenge)
  File "/code/apps/challenges/models.py", line 478, in post_save_connect
    import challenges.aws_utils as aws
  File "/code/apps/challenges/aws_utils.py", line 2220
    ):
    ^
SyntaxError: unmatched ')'
[2025-07-21 17:13:42] ERROR signal Signal handler <promise@0xffff9e8c4dc0 --> <bound method Celery._autodiscover_tasks of <Celery __main__ at 0xffff9e8d4d30>>> raised: SyntaxError("unmatched ')'", ('/code/apps/challenges/aws_utils.py', 2220, 1, '):'))
Traceback (most recent call last):
  File "/usr/local/lib/python3.9/site-packages/celery/utils/dispatch/signal.py", line 288, in send
    response = receiver(signal=self, sender=sender, **named)
  File "/usr/local/lib/python3.9/site-packages/vine/promises.py", line 170, in __call__
    return self.throw()
  File "/usr/local/lib/python3.9/site-packages/vine/promises.py", line 167, in __call__
    retval = fun(*final_args, **final_kwargs)
  File "/usr/local/lib/python3.9/site-packages/celery/app/base.py", line 679, in _autodiscover_tasks
    return self._autodiscover_tasks_from_names(packages, related_name)
  File "/usr/local/lib/python3.9/site-packages/celery/app/base.py", line 684, in _autodiscover_tasks_from_names
    return self.loader.autodiscover_tasks(
  File "/usr/local/lib/python3.9/site-packages/celery/loaders/base.py", line 223, in autodiscover_tasks
    mod.__name__ for mod in autodiscover_tasks(packages or (),
  File "/usr/local/lib/python3.9/site-packages/celery/loaders/base.py", line 249, in autodiscover_tasks
    return [find_related_module(pkg, related_name) for pkg in packages]
  File "/usr/local/lib/python3.9/site-packages/celery/loaders/base.py", line 249, in <listcomp>
    return [find_related_module(pkg, related_name) for pkg in packages]
  File "/usr/local/lib/python3.9/site-packages/celery/loaders/base.py", line 268, in find_related_module
    return importlib.import_module('{0}.{1}'.format(package, related_name))
  File "/usr/local/lib/python3.9/importlib/__init__.py", line 127, in import_module
    return _bootstrap._gcd_import(name[level:], package, level)
  File "<frozen importlib._bootstrap>", line 1030, in _gcd_import
  File "<frozen importlib._bootstrap>", line 1007, in _find_and_load
  File "<frozen importlib._bootstrap>", line 986, in _find_and_load_unlocked
  File "<frozen importlib._bootstrap>", line 680, in _load_unlocked
  File "<frozen importlib._bootstrap_external>", line 850, in exec_module
  File "<frozen importlib._bootstrap>", line 228, in _call_with_frames_removed
  File "/code/apps/jobs/tasks.py", line 5, in <module>
    from challenges.models import ChallengePhase
  File "/code/apps/challenges/models.py", line 489, in <module>
    post_save_connect("evaluation_script", Challenge)
  File "/code/apps/challenges/models.py", line 478, in post_save_connect
    import challenges.aws_utils as aws
  File "/code/apps/challenges/aws_utils.py", line 2220
    ):
    ^
SyntaxError: unmatched ')'
[2025-07-21 17:13:42] ERROR signal Signal handler <bound method DjangoFixup.on_import_modules of <celery.fixups.django.DjangoFixup object at 0xffffa0e4f220>> raised: SyntaxError("unmatched ')'", ('/code/apps/challenges/aws_utils.py', 2220, 1, '):'))
Traceback (most recent call last):
  File "/usr/local/lib/python3.9/site-packages/celery/utils/dispatch/signal.py", line 288, in send
    response = receiver(signal=self, sender=sender, **named)
  File "/usr/local/lib/python3.9/site-packages/celery/fixups/django.py", line 84, in on_import_modules
    self.worker_fixup.validate_models()
  File "/usr/local/lib/python3.9/site-packages/celery/fixups/django.py", line 122, in validate_models
    self.django_setup()
  File "/usr/local/lib/python3.9/site-packages/celery/fixups/django.py", line 118, in django_setup
    django.setup()
  File "/usr/local/lib/python3.9/site-packages/django/__init__.py", line 24, in setup
    apps.populate(settings.INSTALLED_APPS)
  File "/usr/local/lib/python3.9/site-packages/django/apps/registry.py", line 114, in populate
    app_config.import_models()
  File "/usr/local/lib/python3.9/site-packages/django/apps/config.py", line 211, in import_models
    self.models_module = import_module(models_module_name)
  File "/usr/local/lib/python3.9/importlib/__init__.py", line 127, in import_module
    return _bootstrap._gcd_import(name[level:], package, level)
  File "<frozen importlib._bootstrap>", line 1030, in _gcd_import
  File "<frozen importlib._bootstrap>", line 1007, in _find_and_load
  File "<frozen importlib._bootstrap>", line 986, in _find_and_load_unlocked
  File "<frozen importlib._bootstrap>", line 680, in _load_unlocked
  File "<frozen importlib._bootstrap_external>", line 850, in exec_module
  File "<frozen importlib._bootstrap>", line 228, in _call_with_frames_removed
  File "/code/apps/challenges/models.py", line 489, in <module>
    post_save_connect("evaluation_script", Challenge)
  File "/code/apps/challenges/models.py", line 478, in post_save_connect
    import challenges.aws_utils as aws
  File "/code/apps/challenges/aws_utils.py", line 2220
    ):
    ^
SyntaxError: unmatched ')'
[2025-07-21 17:13:42] ERROR signal Signal handler <promise@0xffffa0e84dc0 --> <bound method Celery._autodiscover_tasks of <Celery __main__ at 0xffffa0e94d00>>> raised: SyntaxError("unmatched ')'", ('/code/apps/challenges/aws_utils.py', 2220, 1, '):'))
Traceback (most recent call last):
  File "/usr/local/lib/python3.9/site-packages/celery/utils/dispatch/signal.py", line 288, in send
    response = receiver(signal=self, sender=sender, **named)
  File "/usr/local/lib/python3.9/site-packages/vine/promises.py", line 170, in __call__
    return self.throw()
  File "/usr/local/lib/python3.9/site-packages/vine/promises.py", line 167, in __call__
    retval = fun(*final_args, **final_kwargs)
  File "/usr/local/lib/python3.9/site-packages/celery/app/base.py", line 679, in _autodiscover_tasks
    return self._autodiscover_tasks_from_names(packages, related_name)
  File "/usr/local/lib/python3.9/site-packages/celery/app/base.py", line 684, in _autodiscover_tasks_from_names
    return self.loader.autodiscover_tasks(
  File "/usr/local/lib/python3.9/site-packages/celery/loaders/base.py", line 223, in autodiscover_tasks
    mod.__name__ for mod in autodiscover_tasks(packages or (),
  File "/usr/local/lib/python3.9/site-packages/celery/loaders/base.py", line 249, in autodiscover_tasks
    return [find_related_module(pkg, related_name) for pkg in packages]
  File "/usr/local/lib/python3.9/site-packages/celery/loaders/base.py", line 249, in <listcomp>
    return [find_related_module(pkg, related_name) for pkg in packages]
  File "/usr/local/lib/python3.9/site-packages/celery/loaders/base.py", line 268, in find_related_module
    return importlib.import_module('{0}.{1}'.format(package, related_name))
  File "/usr/local/lib/python3.9/importlib/__init__.py", line 127, in import_module
    return _bootstrap._gcd_import(name[level:], package, level)
  File "<frozen importlib._bootstrap>", line 1030, in _gcd_import
  File "<frozen importlib._bootstrap>", line 1007, in _find_and_load
  File "<frozen importlib._bootstrap>", line 986, in _find_and_load_unlocked
  File "<frozen importlib._bootstrap>", line 680, in _load_unlocked
  File "<frozen importlib._bootstrap_external>", line 850, in exec_module
  File "<frozen importlib._bootstrap>", line 228, in _call_with_frames_removed
  File "/code/apps/jobs/tasks.py", line 5, in <module>
    from challenges.models import ChallengePhase
  File "/code/apps/challenges/models.py", line 489, in <module>
    post_save_connect("evaluation_script", Challenge)
  File "/code/apps/challenges/models.py", line 478, in post_save_connect
    import challenges.aws_utils as aws
  File "/code/apps/challenges/aws_utils.py", line 2220
    ):
    ^
SyntaxError: unmatched ')'
[2025-07-21 17:13:46] ERROR signal Signal handler <bound method DjangoFixup.on_import_modules of <celery.fixups.django.DjangoFixup object at 0xffff97adf220>> raised: SyntaxError("unmatched ')'", ('/code/apps/challenges/aws_utils.py', 2220, 1, '):'))
Traceback (most recent call last):
  File "/usr/local/lib/python3.9/site-packages/celery/utils/dispatch/signal.py", line 288, in send
    response = receiver(signal=self, sender=sender, **named)
  File "/usr/local/lib/python3.9/site-packages/celery/fixups/django.py", line 84, in on_import_modules
    self.worker_fixup.validate_models()
  File "/usr/local/lib/python3.9/site-packages/celery/fixups/django.py", line 122, in validate_models
    self.django_setup()
  File "/usr/local/lib/python3.9/site-packages/celery/fixups/django.py", line 118, in django_setup
    django.setup()
  File "/usr/local/lib/python3.9/site-packages/django/__init__.py", line 24, in setup
    apps.populate(settings.INSTALLED_APPS)
  File "/usr/local/lib/python3.9/site-packages/django/apps/registry.py", line 114, in populate
    app_config.import_models()
  File "/usr/local/lib/python3.9/site-packages/django/apps/config.py", line 211, in import_models
    self.models_module = import_module(models_module_name)
  File "/usr/local/lib/python3.9/importlib/__init__.py", line 127, in import_module
    return _bootstrap._gcd_import(name[level:], package, level)
  File "<frozen importlib._bootstrap>", line 1030, in _gcd_import
  File "<frozen importlib._bootstrap>", line 1007, in _find_and_load
  File "<frozen importlib._bootstrap>", line 986, in _find_and_load_unlocked
  File "<frozen importlib._bootstrap>", line 680, in _load_unlocked
  File "<frozen importlib._bootstrap_external>", line 850, in exec_module
  File "<frozen importlib._bootstrap>", line 228, in _call_with_frames_removed
  File "/code/apps/challenges/models.py", line 489, in <module>
    post_save_connect("evaluation_script", Challenge)
  File "/code/apps/challenges/models.py", line 478, in post_save_connect
    import challenges.aws_utils as aws
  File "/code/apps/challenges/aws_utils.py", line 2220
    ):
    ^
SyntaxError: unmatched ')'
[2025-07-21 17:13:46] ERROR signal Signal handler <promise@0xffff97b14dc0 --> <bound method Celery._autodiscover_tasks of <Celery __main__ at 0xffff97b23d00>>> raised: SyntaxError("unmatched ')'", ('/code/apps/challenges/aws_utils.py', 2220, 1, '):'))
Traceback (most recent call last):
  File "/usr/local/lib/python3.9/site-packages/celery/utils/dispatch/signal.py", line 288, in send
    response = receiver(signal=self, sender=sender, **named)
  File "/usr/local/lib/python3.9/site-packages/vine/promises.py", line 170, in __call__
    return self.throw()
  File "/usr/local/lib/python3.9/site-packages/vine/promises.py", line 167, in __call__
    retval = fun(*final_args, **final_kwargs)
  File "/usr/local/lib/python3.9/site-packages/celery/app/base.py", line 679, in _autodiscover_tasks
    return self._autodiscover_tasks_from_names(packages, related_name)
  File "/usr/local/lib/python3.9/site-packages/celery/app/base.py", line 684, in _autodiscover_tasks_from_names
    return self.loader.autodiscover_tasks(
  File "/usr/local/lib/python3.9/site-packages/celery/loaders/base.py", line 223, in autodiscover_tasks
    mod.__name__ for mod in autodiscover_tasks(packages or (),
  File "/usr/local/lib/python3.9/site-packages/celery/loaders/base.py", line 249, in autodiscover_tasks
    return [find_related_module(pkg, related_name) for pkg in packages]
  File "/usr/local/lib/python3.9/site-packages/celery/loaders/base.py", line 249, in <listcomp>
    return [find_related_module(pkg, related_name) for pkg in packages]
  File "/usr/local/lib/python3.9/site-packages/celery/loaders/base.py", line 268, in find_related_module
    return importlib.import_module('{0}.{1}'.format(package, related_name))
  File "/usr/local/lib/python3.9/importlib/__init__.py", line 127, in import_module
    return _bootstrap._gcd_import(name[level:], package, level)
  File "<frozen importlib._bootstrap>", line 1030, in _gcd_import
  File "<frozen importlib._bootstrap>", line 1007, in _find_and_load
  File "<frozen importlib._bootstrap>", line 986, in _find_and_load_unlocked
  File "<frozen importlib._bootstrap>", line 680, in _load_unlocked
  File "<frozen importlib._bootstrap_external>", line 850, in exec_module
  File "<frozen importlib._bootstrap>", line 228, in _call_with_frames_removed
  File "/code/apps/jobs/tasks.py", line 5, in <module>
    from challenges.models import ChallengePhase
  File "/code/apps/challenges/models.py", line 489, in <module>
    post_save_connect("evaluation_script", Challenge)
  File "/code/apps/challenges/models.py", line 478, in post_save_connect
    import challenges.aws_utils as aws
  File "/code/apps/challenges/aws_utils.py", line 2220
    ):
    ^
SyntaxError: unmatched ')'
[2025-07-21 17:13:46] ERROR signal Signal handler <bound method DjangoFixup.on_import_modules of <celery.fixups.django.DjangoFixup object at 0xffff7e2bb1c0>> raised: SyntaxError("unmatched ')'", ('/code/apps/challenges/aws_utils.py', 2220, 1, '):'))
Traceback (most recent call last):
  File "/usr/local/lib/python3.9/site-packages/celery/utils/dispatch/signal.py", line 288, in send
    response = receiver(signal=self, sender=sender, **named)
  File "/usr/local/lib/python3.9/site-packages/celery/fixups/django.py", line 84, in on_import_modules
    self.worker_fixup.validate_models()
  File "/usr/local/lib/python3.9/site-packages/celery/fixups/django.py", line 122, in validate_models
    self.django_setup()
  File "/usr/local/lib/python3.9/site-packages/celery/fixups/django.py", line 118, in django_setup
    django.setup()
  File "/usr/local/lib/python3.9/site-packages/django/__init__.py", line 24, in setup
    apps.populate(settings.INSTALLED_APPS)
  File "/usr/local/lib/python3.9/site-packages/django/apps/registry.py", line 114, in populate
    app_config.import_models()
  File "/usr/local/lib/python3.9/site-packages/django/apps/config.py", line 211, in import_models
    self.models_module = import_module(models_module_name)
  File "/usr/local/lib/python3.9/importlib/__init__.py", line 127, in import_module
    return _bootstrap._gcd_import(name[level:], package, level)
  File "<frozen importlib._bootstrap>", line 1030, in _gcd_import
  File "<frozen importlib._bootstrap>", line 1007, in _find_and_load
  File "<frozen importlib._bootstrap>", line 986, in _find_and_load_unlocked
  File "<frozen importlib._bootstrap>", line 680, in _load_unlocked
  File "<frozen importlib._bootstrap_external>", line 850, in exec_module
  File "<frozen importlib._bootstrap>", line 228, in _call_with_frames_removed
  File "/code/apps/challenges/models.py", line 489, in <module>
    post_save_connect("evaluation_script", Challenge)
  File "/code/apps/challenges/models.py", line 478, in post_save_connect
    import challenges.aws_utils as aws
  File "/code/apps/challenges/aws_utils.py", line 2220
    ):
    ^
SyntaxError: unmatched ')'
