[2025-07-10 18:42:26] ERROR aws_utils An error occurred (Unknown) when calling the RegisterTaskDefinition operation: Failed to register task definition
Traceback (most recent call last):
  File "/code/apps/challenges/aws_utils.py", line 1079, in scale_resources
    response = client.register_task_definition(**task_def)
  File "/usr/local/lib/python3.9/unittest/mock.py", line 1092, in __call__
    return self._mock_call(*args, **kwargs)
  File "/usr/local/lib/python3.9/unittest/mock.py", line 1096, in _mock_call
    return self._execute_mock_call(*args, **kwargs)
  File "/usr/local/lib/python3.9/unittest/mock.py", line 1151, in _execute_mock_call
    raise effect
botocore.exceptions.ClientError: An error occurred (Unknown) when calling the RegisterTaskDefinition operation: Failed to register task definition
[2025-07-10 18:45:41] INFO aws_utils Set CloudWatch log retention for challenge 123 to 60 days
[2025-07-10 18:45:41] INFO aws_utils Set CloudWatch log retention for challenge 123 to 90 days
[2025-07-10 18:45:41] INFO aws_utils Set CloudWatch log retention for challenge 123 to 30 days
[2025-07-10 18:45:41] INFO aws_utils Starting cleanup of expired submission artifacts
[2025-07-10 18:45:41] INFO aws_utils Found <MagicMock name='filter().select_related().count()' id='281473107296944'> submissions eligible for cleanup
[2025-07-10 18:45:41] INFO aws_utils Cleanup completed. Processed: 0, Successful: 0, Failed: 0
[2025-07-10 18:45:41] INFO aws_utils Updated log retention for approved challenge 123
[2025-07-10 18:45:41] ERROR aws_utils An error occurred (SomeError) when calling the CreateService operation: Unknown
Traceback (most recent call last):
  File "/code/apps/challenges/aws_utils.py", line 365, in create_service_by_challenge_pk
    response = client.create_service(**definition)
  File "/usr/local/lib/python3.9/unittest/mock.py", line 1092, in __call__
    return self._mock_call(*args, **kwargs)
  File "/usr/local/lib/python3.9/unittest/mock.py", line 1096, in _mock_call
    return self._execute_mock_call(*args, **kwargs)
  File "/usr/local/lib/python3.9/unittest/mock.py", line 1151, in _execute_mock_call
    raise effect
botocore.exceptions.ClientError: An error occurred (SomeError) when calling the CreateService operation: Unknown
[2025-07-10 18:45:41] ERROR aws_utils An error occurred (ServiceError) when calling the UpdateService operation: Unknown
Traceback (most recent call last):
  File "/code/apps/challenges/aws_utils.py", line 414, in update_service_by_challenge_pk
    response = client.update_service(**kwargs)
  File "/usr/local/lib/python3.9/unittest/mock.py", line 1092, in __call__
    return self._mock_call(*args, **kwargs)
  File "/usr/local/lib/python3.9/unittest/mock.py", line 1096, in _mock_call
    return self._execute_mock_call(*args, **kwargs)
  File "/usr/local/lib/python3.9/unittest/mock.py", line 1151, in _execute_mock_call
    raise effect
botocore.exceptions.ClientError: An error occurred (ServiceError) when calling the UpdateService operation: Unknown
[2025-07-10 18:45:41] ERROR aws_utils An error occurred (DeregisterError) when calling the DeregisterTaskDefinition operation: Unknown
Traceback (most recent call last):
  File "/code/apps/challenges/aws_utils.py", line 459, in delete_service_by_challenge_pk
    client.deregister_task_definition(
  File "/usr/local/lib/python3.9/unittest/mock.py", line 1092, in __call__
    return self._mock_call(*args, **kwargs)
  File "/usr/local/lib/python3.9/unittest/mock.py", line 1096, in _mock_call
    return self._execute_mock_call(*args, **kwargs)
  File "/usr/local/lib/python3.9/unittest/mock.py", line 1151, in _execute_mock_call
    raise effect
botocore.exceptions.ClientError: An error occurred (DeregisterError) when calling the DeregisterTaskDefinition operation: Unknown
[2025-07-10 18:45:41] ERROR aws_utils An error occurred (DeleteServiceError) when calling the DeleteService operation: Unknown
Traceback (most recent call last):
  File "/code/apps/challenges/aws_utils.py", line 455, in delete_service_by_challenge_pk
    response = client.delete_service(**kwargs)
  File "/usr/local/lib/python3.9/unittest/mock.py", line 1092, in __call__
    return self._mock_call(*args, **kwargs)
  File "/usr/local/lib/python3.9/unittest/mock.py", line 1096, in _mock_call
    return self._execute_mock_call(*args, **kwargs)
  File "/usr/local/lib/python3.9/unittest/mock.py", line 1151, in _execute_mock_call
    raise effect
botocore.exceptions.ClientError: An error occurred (DeleteServiceError) when calling the DeleteService operation: Unknown
[2025-07-10 18:45:41] ERROR aws_utils An error occurred (Unknown) when calling the DeregisterTaskDefinition operation: Scaling inactive workers not supported
Traceback (most recent call last):
  File "/code/apps/challenges/aws_utils.py", line 1038, in scale_resources
    response = client.deregister_task_definition(
  File "/usr/local/lib/python3.9/unittest/mock.py", line 1092, in __call__
    return self._mock_call(*args, **kwargs)
  File "/usr/local/lib/python3.9/unittest/mock.py", line 1096, in _mock_call
    return self._execute_mock_call(*args, **kwargs)
  File "/usr/local/lib/python3.9/unittest/mock.py", line 1151, in _execute_mock_call
    raise effect
botocore.exceptions.ClientError: An error occurred (Unknown) when calling the DeregisterTaskDefinition operation: Scaling inactive workers not supported
[2025-07-10 18:45:41] ERROR aws_utils An error occurred (Unknown) when calling the RegisterTaskDefinition operation: Failed to register task definition
Traceback (most recent call last):
  File "/code/apps/challenges/aws_utils.py", line 1079, in scale_resources
    response = client.register_task_definition(**task_def)
  File "/usr/local/lib/python3.9/unittest/mock.py", line 1092, in __call__
    return self._mock_call(*args, **kwargs)
  File "/usr/local/lib/python3.9/unittest/mock.py", line 1096, in _mock_call
    return self._execute_mock_call(*args, **kwargs)
  File "/usr/local/lib/python3.9/unittest/mock.py", line 1151, in _execute_mock_call
    raise effect
botocore.exceptions.ClientError: An error occurred (Unknown) when calling the RegisterTaskDefinition operation: Failed to register task definition
[2025-07-10 18:47:05] INFO aws_utils Set CloudWatch log retention for challenge 123 to 60 days
[2025-07-10 18:47:05] INFO aws_utils Set CloudWatch log retention for challenge 123 to 90 days
[2025-07-10 18:47:05] INFO aws_utils Set CloudWatch log retention for challenge 123 to 30 days
[2025-07-10 18:47:05] INFO aws_utils Starting cleanup of expired submission artifacts
[2025-07-10 18:47:05] INFO aws_utils Found <MagicMock name='filter().select_related().count()' id='281473417552560'> submissions eligible for cleanup
[2025-07-10 18:47:05] INFO aws_utils Cleanup completed. Processed: 0, Successful: 0, Failed: 0
[2025-07-10 18:47:05] INFO aws_utils Updated log retention for approved challenge 123
[2025-07-10 18:47:08] ERROR aws_utils Failed to set log retention for challenge 123
Traceback (most recent call last):
  File "/code/apps/challenges/aws_utils.py", line 2007, in set_cloudwatch_log_retention
    logs_client.put_retention_policy(
  File "/usr/local/lib/python3.9/site-packages/botocore/client.py", line 535, in _api_call
    return self._make_api_call(operation_name, kwargs)
  File "/usr/local/lib/python3.9/site-packages/botocore/client.py", line 980, in _make_api_call
    raise error_class(parsed_response, operation_name)
botocore.errorfactory.UnrecognizedClientException: An error occurred (UnrecognizedClientException) when calling the PutRetentionPolicy operation: The security token included in the request is invalid.
[2025-07-10 18:47:08] WARNING aws_utils Failed to update log retention for challenge 123: An error occurred (UnrecognizedClientException) when calling the PutRetentionPolicy operation: The security token included in the request is invalid.
[2025-07-10 18:47:09] INFO aws_utils The worker service for challenge 125 was restarted, as evaluation_script was changed.
[2025-07-10 18:47:09] WARNING aws_utils Worker(s) for challenge 125 couldn't restart! Error: Please select challenges with active workers only.
[2025-07-10 18:47:09] INFO aws_utils The worker service for challenge 126 was restarted, as evaluation_script was changed.
[2025-07-10 18:47:09] WARNING aws_utils Worker(s) for challenge 126 couldn't restart! Error: Please select challenges with active workers only.
[2025-07-10 18:47:09] INFO aws_utils The worker service for challenge 127 was restarted, as evaluation_script was changed.
[2025-07-10 18:47:09] WARNING aws_utils Worker(s) for challenge 127 couldn't restart! Error: Please select challenges with active workers only.
[2025-07-10 18:47:09] INFO aws_utils The worker service for challenge 128 was restarted, as evaluation_script was changed.
[2025-07-10 18:47:09] WARNING aws_utils Worker(s) for challenge 128 couldn't restart! Error: Please select challenges with active workers only.
[2025-07-10 18:47:09] INFO aws_utils The worker service for challenge 128 was restarted, as evaluation_script was changed.
[2025-07-10 18:47:09] WARNING aws_utils Worker(s) for challenge 128 couldn't restart! Error: Please select challenges with active workers only.
[2025-07-10 18:47:09] INFO aws_utils The worker service for challenge 129 was restarted, as evaluation_script was changed.
[2025-07-10 18:47:09] WARNING aws_utils Worker(s) for challenge 129 couldn't restart! Error: Please select challenges with active workers only.
[2025-07-10 18:47:09] INFO aws_utils The worker service for challenge 130 was restarted, as evaluation_script was changed.
[2025-07-10 18:47:09] WARNING aws_utils Worker(s) for challenge 130 couldn't restart! Error: Please select challenges with active workers only.
[2025-07-10 18:47:09] INFO aws_utils The worker service for challenge 131 was restarted, as evaluation_script was changed.
[2025-07-10 18:47:09] WARNING aws_utils Worker(s) for challenge 131 couldn't restart! Error: Please select challenges with active workers only.
[2025-07-10 18:47:09] INFO aws_utils The worker service for challenge 132 was restarted, as evaluation_script was changed.
[2025-07-10 18:47:09] WARNING aws_utils Worker(s) for challenge 132 couldn't restart! Error: Please select challenges with active workers only.
[2025-07-10 18:47:09] INFO aws_utils The worker service for challenge 133 was restarted, as evaluation_script was changed.
[2025-07-10 18:47:09] WARNING aws_utils Worker(s) for challenge 133 couldn't restart! Error: Please select challenges with active workers only.
[2025-07-10 18:47:12] INFO aws_utils The worker service for challenge 317 was restarted, as test_annotation was changed.
[2025-07-10 18:47:12] WARNING aws_utils Worker(s) for challenge 317 couldn't restart! Error: Please select challenges with active workers only.
[2025-07-10 18:47:32] ERROR aws_utils An error occurred (SomeError) when calling the CreateService operation: Unknown
Traceback (most recent call last):
  File "/code/apps/challenges/aws_utils.py", line 365, in create_service_by_challenge_pk
    response = client.create_service(**definition)
  File "/usr/local/lib/python3.9/unittest/mock.py", line 1092, in __call__
    return self._mock_call(*args, **kwargs)
  File "/usr/local/lib/python3.9/unittest/mock.py", line 1096, in _mock_call
    return self._execute_mock_call(*args, **kwargs)
  File "/usr/local/lib/python3.9/unittest/mock.py", line 1151, in _execute_mock_call
    raise effect
botocore.exceptions.ClientError: An error occurred (SomeError) when calling the CreateService operation: Unknown
[2025-07-10 18:47:32] ERROR aws_utils An error occurred (ServiceError) when calling the UpdateService operation: Unknown
Traceback (most recent call last):
  File "/code/apps/challenges/aws_utils.py", line 414, in update_service_by_challenge_pk
    response = client.update_service(**kwargs)
  File "/usr/local/lib/python3.9/unittest/mock.py", line 1092, in __call__
    return self._mock_call(*args, **kwargs)
  File "/usr/local/lib/python3.9/unittest/mock.py", line 1096, in _mock_call
    return self._execute_mock_call(*args, **kwargs)
  File "/usr/local/lib/python3.9/unittest/mock.py", line 1151, in _execute_mock_call
    raise effect
botocore.exceptions.ClientError: An error occurred (ServiceError) when calling the UpdateService operation: Unknown
[2025-07-10 18:47:32] ERROR aws_utils An error occurred (DeregisterError) when calling the DeregisterTaskDefinition operation: Unknown
Traceback (most recent call last):
  File "/code/apps/challenges/aws_utils.py", line 459, in delete_service_by_challenge_pk
    client.deregister_task_definition(
  File "/usr/local/lib/python3.9/unittest/mock.py", line 1092, in __call__
    return self._mock_call(*args, **kwargs)
  File "/usr/local/lib/python3.9/unittest/mock.py", line 1096, in _mock_call
    return self._execute_mock_call(*args, **kwargs)
  File "/usr/local/lib/python3.9/unittest/mock.py", line 1151, in _execute_mock_call
    raise effect
botocore.exceptions.ClientError: An error occurred (DeregisterError) when calling the DeregisterTaskDefinition operation: Unknown
[2025-07-10 18:47:32] ERROR aws_utils An error occurred (DeleteServiceError) when calling the DeleteService operation: Unknown
Traceback (most recent call last):
  File "/code/apps/challenges/aws_utils.py", line 455, in delete_service_by_challenge_pk
    response = client.delete_service(**kwargs)
  File "/usr/local/lib/python3.9/unittest/mock.py", line 1092, in __call__
    return self._mock_call(*args, **kwargs)
  File "/usr/local/lib/python3.9/unittest/mock.py", line 1096, in _mock_call
    return self._execute_mock_call(*args, **kwargs)
  File "/usr/local/lib/python3.9/unittest/mock.py", line 1151, in _execute_mock_call
    raise effect
botocore.exceptions.ClientError: An error occurred (DeleteServiceError) when calling the DeleteService operation: Unknown
[2025-07-10 18:47:32] ERROR aws_utils An error occurred (Unknown) when calling the DeregisterTaskDefinition operation: Scaling inactive workers not supported
Traceback (most recent call last):
  File "/code/apps/challenges/aws_utils.py", line 1038, in scale_resources
    response = client.deregister_task_definition(
  File "/usr/local/lib/python3.9/unittest/mock.py", line 1092, in __call__
    return self._mock_call(*args, **kwargs)
  File "/usr/local/lib/python3.9/unittest/mock.py", line 1096, in _mock_call
    return self._execute_mock_call(*args, **kwargs)
  File "/usr/local/lib/python3.9/unittest/mock.py", line 1151, in _execute_mock_call
    raise effect
botocore.exceptions.ClientError: An error occurred (Unknown) when calling the DeregisterTaskDefinition operation: Scaling inactive workers not supported
[2025-07-10 18:47:32] ERROR aws_utils An error occurred (Unknown) when calling the RegisterTaskDefinition operation: Failed to register task definition
Traceback (most recent call last):
  File "/code/apps/challenges/aws_utils.py", line 1079, in scale_resources
    response = client.register_task_definition(**task_def)
  File "/usr/local/lib/python3.9/unittest/mock.py", line 1092, in __call__
    return self._mock_call(*args, **kwargs)
  File "/usr/local/lib/python3.9/unittest/mock.py", line 1096, in _mock_call
    return self._execute_mock_call(*args, **kwargs)
  File "/usr/local/lib/python3.9/unittest/mock.py", line 1151, in _execute_mock_call
    raise effect
botocore.exceptions.ClientError: An error occurred (Unknown) when calling the RegisterTaskDefinition operation: Failed to register task definition
[2025-07-11 19:35:02] INFO aws_utils The worker service for challenge 8 was restarted, as evaluation_script was changed.
[2025-07-11 19:35:02] WARNING aws_utils Worker(s) for challenge 8 couldn't restart! Error: Please select challenges with active workers only.
[2025-07-11 19:35:02] INFO aws_utils The worker service for challenge 9 was restarted, as evaluation_script was changed.
[2025-07-11 19:35:02] WARNING aws_utils Worker(s) for challenge 9 couldn't restart! Error: Please select challenges with active workers only.
[2025-07-11 19:35:02] INFO aws_utils The worker service for challenge 10 was restarted, as evaluation_script was changed.
[2025-07-11 19:35:02] WARNING aws_utils Worker(s) for challenge 10 couldn't restart! Error: Please select challenges with active workers only.
[2025-07-11 19:35:02] INFO aws_utils The worker service for challenge 11 was restarted, as evaluation_script was changed.
[2025-07-11 19:35:02] WARNING aws_utils Worker(s) for challenge 11 couldn't restart! Error: Please select challenges with active workers only.
[2025-07-11 19:35:02] INFO aws_utils The worker service for challenge 11 was restarted, as evaluation_script was changed.
[2025-07-11 19:35:02] WARNING aws_utils Worker(s) for challenge 11 couldn't restart! Error: Please select challenges with active workers only.
[2025-07-11 19:35:02] INFO aws_utils The worker service for challenge 12 was restarted, as evaluation_script was changed.
[2025-07-11 19:35:02] WARNING aws_utils Worker(s) for challenge 12 couldn't restart! Error: Please select challenges with active workers only.
[2025-07-11 19:35:02] INFO aws_utils The worker service for challenge 13 was restarted, as evaluation_script was changed.
[2025-07-11 19:35:02] WARNING aws_utils Worker(s) for challenge 13 couldn't restart! Error: Please select challenges with active workers only.
[2025-07-11 19:35:02] INFO aws_utils The worker service for challenge 14 was restarted, as evaluation_script was changed.
[2025-07-11 19:35:02] WARNING aws_utils Worker(s) for challenge 14 couldn't restart! Error: Please select challenges with active workers only.
[2025-07-11 19:35:02] INFO aws_utils The worker service for challenge 15 was restarted, as evaluation_script was changed.
[2025-07-11 19:35:02] WARNING aws_utils Worker(s) for challenge 15 couldn't restart! Error: Please select challenges with active workers only.
[2025-07-11 19:35:02] INFO aws_utils The worker service for challenge 16 was restarted, as evaluation_script was changed.
[2025-07-11 19:35:02] WARNING aws_utils Worker(s) for challenge 16 couldn't restart! Error: Please select challenges with active workers only.
[2025-07-11 19:35:19] INFO aws_utils Set CloudWatch log retention for challenge 123 to 60 days
[2025-07-11 19:35:19] INFO aws_utils Set CloudWatch log retention for challenge 123 to 90 days
[2025-07-11 19:35:19] INFO aws_utils Set CloudWatch log retention for challenge 123 to 30 days
[2025-07-11 19:35:22] INFO aws_utils Starting cleanup of expired submission artifacts
[2025-07-11 19:35:22] INFO aws_utils Found <MagicMock name='filter().select_related().count()' id='281473261439872'> submissions eligible for cleanup
[2025-07-11 19:35:22] INFO aws_utils Cleanup completed. Processed: 0, Successful: 0, Failed: 0
[2025-07-11 19:35:22] INFO aws_utils Updated log retention for approved challenge 123
[2025-07-11 19:35:23] ERROR aws_utils Failed to set log retention for challenge 13
Traceback (most recent call last):
  File "/code/apps/challenges/aws_utils.py", line 2007, in set_cloudwatch_log_retention
    logs_client.put_retention_policy(
  File "/usr/local/lib/python3.9/site-packages/botocore/client.py", line 535, in _api_call
    return self._make_api_call(operation_name, kwargs)
  File "/usr/local/lib/python3.9/site-packages/botocore/client.py", line 980, in _make_api_call
    raise error_class(parsed_response, operation_name)
botocore.errorfactory.UnrecognizedClientException: An error occurred (UnrecognizedClientException) when calling the PutRetentionPolicy operation: The security token included in the request is invalid.
[2025-07-11 19:35:23] WARNING aws_utils Failed to update log retention for challenge 13: An error occurred (UnrecognizedClientException) when calling the PutRetentionPolicy operation: The security token included in the request is invalid.
[2025-07-11 19:35:24] INFO aws_utils The worker service for challenge 22 was restarted, as evaluation_script was changed.
[2025-07-11 19:35:24] WARNING aws_utils Worker(s) for challenge 22 couldn't restart! Error: Please select challenges with active workers only.
[2025-07-11 19:35:24] INFO aws_utils The worker service for challenge 23 was restarted, as evaluation_script was changed.
[2025-07-11 19:35:24] WARNING aws_utils Worker(s) for challenge 23 couldn't restart! Error: Please select challenges with active workers only.
[2025-07-11 19:35:24] INFO aws_utils The worker service for challenge 24 was restarted, as evaluation_script was changed.
[2025-07-11 19:35:24] WARNING aws_utils Worker(s) for challenge 24 couldn't restart! Error: Please select challenges with active workers only.
[2025-07-11 19:35:24] INFO aws_utils The worker service for challenge 25 was restarted, as evaluation_script was changed.
[2025-07-11 19:35:24] WARNING aws_utils Worker(s) for challenge 25 couldn't restart! Error: Please select challenges with active workers only.
[2025-07-11 19:35:24] INFO aws_utils The worker service for challenge 25 was restarted, as evaluation_script was changed.
[2025-07-11 19:35:24] WARNING aws_utils Worker(s) for challenge 25 couldn't restart! Error: Please select challenges with active workers only.
[2025-07-11 19:35:24] INFO aws_utils The worker service for challenge 26 was restarted, as evaluation_script was changed.
[2025-07-11 19:35:24] WARNING aws_utils Worker(s) for challenge 26 couldn't restart! Error: Please select challenges with active workers only.
[2025-07-11 19:35:24] INFO aws_utils The worker service for challenge 27 was restarted, as evaluation_script was changed.
[2025-07-11 19:35:24] WARNING aws_utils Worker(s) for challenge 27 couldn't restart! Error: Please select challenges with active workers only.
[2025-07-11 19:35:24] INFO aws_utils The worker service for challenge 28 was restarted, as evaluation_script was changed.
[2025-07-11 19:35:24] WARNING aws_utils Worker(s) for challenge 28 couldn't restart! Error: Please select challenges with active workers only.
[2025-07-11 19:35:24] INFO aws_utils The worker service for challenge 29 was restarted, as evaluation_script was changed.
[2025-07-11 19:35:24] WARNING aws_utils Worker(s) for challenge 29 couldn't restart! Error: Please select challenges with active workers only.
[2025-07-11 19:35:24] INFO aws_utils The worker service for challenge 30 was restarted, as evaluation_script was changed.
[2025-07-11 19:35:24] WARNING aws_utils Worker(s) for challenge 30 couldn't restart! Error: Please select challenges with active workers only.
[2025-07-11 19:35:29] ERROR aws_utils An error occurred (Unknown) when calling the DeregisterTaskDefinition operation: Scaling inactive workers not supported
Traceback (most recent call last):
  File "/code/apps/challenges/aws_utils.py", line 1038, in scale_resources
    response = client.deregister_task_definition(
  File "/usr/local/lib/python3.9/unittest/mock.py", line 1092, in __call__
    return self._mock_call(*args, **kwargs)
  File "/usr/local/lib/python3.9/unittest/mock.py", line 1096, in _mock_call
    return self._execute_mock_call(*args, **kwargs)
  File "/usr/local/lib/python3.9/unittest/mock.py", line 1151, in _execute_mock_call
    raise effect
botocore.exceptions.ClientError: An error occurred (Unknown) when calling the DeregisterTaskDefinition operation: Scaling inactive workers not supported
[2025-07-11 19:35:29] ERROR aws_utils An error occurred (Unknown) when calling the RegisterTaskDefinition operation: Failed to register task definition
Traceback (most recent call last):
  File "/code/apps/challenges/aws_utils.py", line 1079, in scale_resources
    response = client.register_task_definition(**task_def)
  File "/usr/local/lib/python3.9/unittest/mock.py", line 1092, in __call__
    return self._mock_call(*args, **kwargs)
  File "/usr/local/lib/python3.9/unittest/mock.py", line 1096, in _mock_call
    return self._execute_mock_call(*args, **kwargs)
  File "/usr/local/lib/python3.9/unittest/mock.py", line 1151, in _execute_mock_call
    raise effect
botocore.exceptions.ClientError: An error occurred (Unknown) when calling the RegisterTaskDefinition operation: Failed to register task definition
[2025-07-11 19:37:11] INFO aws_utils The worker service for challenge 8 was restarted, as evaluation_script was changed.
[2025-07-11 19:37:11] WARNING aws_utils Worker(s) for challenge 8 couldn't restart! Error: Please select challenges with active workers only.
[2025-07-11 19:37:11] INFO aws_utils The worker service for challenge 9 was restarted, as evaluation_script was changed.
[2025-07-11 19:37:11] WARNING aws_utils Worker(s) for challenge 9 couldn't restart! Error: Please select challenges with active workers only.
[2025-07-11 19:37:11] INFO aws_utils The worker service for challenge 10 was restarted, as evaluation_script was changed.
[2025-07-11 19:37:11] WARNING aws_utils Worker(s) for challenge 10 couldn't restart! Error: Please select challenges with active workers only.
[2025-07-11 19:37:11] INFO aws_utils The worker service for challenge 11 was restarted, as evaluation_script was changed.
[2025-07-11 19:37:11] WARNING aws_utils Worker(s) for challenge 11 couldn't restart! Error: Please select challenges with active workers only.
[2025-07-11 19:37:11] INFO aws_utils The worker service for challenge 11 was restarted, as evaluation_script was changed.
[2025-07-11 19:37:11] WARNING aws_utils Worker(s) for challenge 11 couldn't restart! Error: Please select challenges with active workers only.
[2025-07-11 19:37:11] INFO aws_utils The worker service for challenge 12 was restarted, as evaluation_script was changed.
[2025-07-11 19:37:11] WARNING aws_utils Worker(s) for challenge 12 couldn't restart! Error: Please select challenges with active workers only.
[2025-07-11 19:37:11] INFO aws_utils The worker service for challenge 13 was restarted, as evaluation_script was changed.
[2025-07-11 19:37:11] WARNING aws_utils Worker(s) for challenge 13 couldn't restart! Error: Please select challenges with active workers only.
[2025-07-11 19:37:11] INFO aws_utils The worker service for challenge 14 was restarted, as evaluation_script was changed.
[2025-07-11 19:37:11] WARNING aws_utils Worker(s) for challenge 14 couldn't restart! Error: Please select challenges with active workers only.
[2025-07-11 19:37:11] INFO aws_utils The worker service for challenge 15 was restarted, as evaluation_script was changed.
[2025-07-11 19:37:11] WARNING aws_utils Worker(s) for challenge 15 couldn't restart! Error: Please select challenges with active workers only.
[2025-07-11 19:37:11] INFO aws_utils The worker service for challenge 16 was restarted, as evaluation_script was changed.
[2025-07-11 19:37:11] WARNING aws_utils Worker(s) for challenge 16 couldn't restart! Error: Please select challenges with active workers only.
[2025-07-11 19:37:38] INFO aws_utils Set CloudWatch log retention for challenge 123 to 60 days
[2025-07-11 19:37:38] INFO aws_utils Set CloudWatch log retention for challenge 123 to 90 days
[2025-07-11 19:37:38] INFO aws_utils Set CloudWatch log retention for challenge 123 to 30 days
[2025-07-11 19:37:41] INFO aws_utils Starting cleanup of expired submission artifacts
[2025-07-11 19:37:41] INFO aws_utils Found <MagicMock name='filter().select_related().count()' id='281472705460736'> submissions eligible for cleanup
[2025-07-11 19:37:41] INFO aws_utils Cleanup completed. Processed: 0, Successful: 0, Failed: 0
[2025-07-11 19:37:41] INFO aws_utils Updated log retention for approved challenge 123
[2025-07-11 19:37:41] ERROR aws_utils An error occurred (Unknown) when calling the DeregisterTaskDefinition operation: Scaling inactive workers not supported
Traceback (most recent call last):
  File "/code/apps/challenges/aws_utils.py", line 1038, in scale_resources
    response = client.deregister_task_definition(
  File "/usr/local/lib/python3.9/unittest/mock.py", line 1092, in __call__
    return self._mock_call(*args, **kwargs)
  File "/usr/local/lib/python3.9/unittest/mock.py", line 1096, in _mock_call
    return self._execute_mock_call(*args, **kwargs)
  File "/usr/local/lib/python3.9/unittest/mock.py", line 1151, in _execute_mock_call
    raise effect
botocore.exceptions.ClientError: An error occurred (Unknown) when calling the DeregisterTaskDefinition operation: Scaling inactive workers not supported
[2025-07-11 19:37:41] ERROR aws_utils An error occurred (Unknown) when calling the RegisterTaskDefinition operation: Failed to register task definition
Traceback (most recent call last):
  File "/code/apps/challenges/aws_utils.py", line 1079, in scale_resources
    response = client.register_task_definition(**task_def)
  File "/usr/local/lib/python3.9/unittest/mock.py", line 1092, in __call__
    return self._mock_call(*args, **kwargs)
  File "/usr/local/lib/python3.9/unittest/mock.py", line 1096, in _mock_call
    return self._execute_mock_call(*args, **kwargs)
  File "/usr/local/lib/python3.9/unittest/mock.py", line 1151, in _execute_mock_call
    raise effect
botocore.exceptions.ClientError: An error occurred (Unknown) when calling the RegisterTaskDefinition operation: Failed to register task definition
[2025-07-11 19:38:34] INFO aws_utils Set CloudWatch log retention for challenge 123 to 60 days
[2025-07-11 19:38:34] INFO aws_utils Set CloudWatch log retention for challenge 123 to 90 days
[2025-07-11 19:38:34] INFO aws_utils Set CloudWatch log retention for challenge 123 to 30 days
[2025-07-11 19:38:37] INFO aws_utils Starting cleanup of expired submission artifacts
[2025-07-11 19:38:37] INFO aws_utils Found <MagicMock name='filter().select_related().count()' id='281473155054608'> submissions eligible for cleanup
[2025-07-11 19:38:37] INFO aws_utils Cleanup completed. Processed: 0, Successful: 0, Failed: 0
[2025-07-11 19:38:37] INFO aws_utils Updated log retention for approved challenge 123
[2025-07-11 19:38:39] ERROR aws_utils Failed to set log retention for challenge 13
Traceback (most recent call last):
  File "/code/apps/challenges/aws_utils.py", line 2007, in set_cloudwatch_log_retention
    logs_client.put_retention_policy(
  File "/usr/local/lib/python3.9/site-packages/botocore/client.py", line 535, in _api_call
    return self._make_api_call(operation_name, kwargs)
  File "/usr/local/lib/python3.9/site-packages/botocore/client.py", line 980, in _make_api_call
    raise error_class(parsed_response, operation_name)
botocore.errorfactory.UnrecognizedClientException: An error occurred (UnrecognizedClientException) when calling the PutRetentionPolicy operation: The security token included in the request is invalid.
[2025-07-11 19:38:39] WARNING aws_utils Failed to update log retention for challenge 13: An error occurred (UnrecognizedClientException) when calling the PutRetentionPolicy operation: The security token included in the request is invalid.
[2025-07-11 19:38:39] INFO aws_utils The worker service for challenge 22 was restarted, as evaluation_script was changed.
[2025-07-11 19:38:39] WARNING aws_utils Worker(s) for challenge 22 couldn't restart! Error: Please select challenges with active workers only.
[2025-07-11 19:38:39] INFO aws_utils The worker service for challenge 23 was restarted, as evaluation_script was changed.
[2025-07-11 19:38:39] WARNING aws_utils Worker(s) for challenge 23 couldn't restart! Error: Please select challenges with active workers only.
[2025-07-11 19:38:39] INFO aws_utils The worker service for challenge 24 was restarted, as evaluation_script was changed.
[2025-07-11 19:38:39] WARNING aws_utils Worker(s) for challenge 24 couldn't restart! Error: Please select challenges with active workers only.
[2025-07-11 19:38:39] INFO aws_utils The worker service for challenge 25 was restarted, as evaluation_script was changed.
[2025-07-11 19:38:39] WARNING aws_utils Worker(s) for challenge 25 couldn't restart! Error: Please select challenges with active workers only.
[2025-07-11 19:38:39] INFO aws_utils The worker service for challenge 25 was restarted, as evaluation_script was changed.
[2025-07-11 19:38:39] WARNING aws_utils Worker(s) for challenge 25 couldn't restart! Error: Please select challenges with active workers only.
[2025-07-11 19:38:39] INFO aws_utils The worker service for challenge 26 was restarted, as evaluation_script was changed.
[2025-07-11 19:38:39] WARNING aws_utils Worker(s) for challenge 26 couldn't restart! Error: Please select challenges with active workers only.
[2025-07-11 19:38:39] INFO aws_utils The worker service for challenge 27 was restarted, as evaluation_script was changed.
[2025-07-11 19:38:39] WARNING aws_utils Worker(s) for challenge 27 couldn't restart! Error: Please select challenges with active workers only.
[2025-07-11 19:38:39] INFO aws_utils The worker service for challenge 28 was restarted, as evaluation_script was changed.
[2025-07-11 19:38:39] WARNING aws_utils Worker(s) for challenge 28 couldn't restart! Error: Please select challenges with active workers only.
[2025-07-11 19:38:39] INFO aws_utils The worker service for challenge 29 was restarted, as evaluation_script was changed.
[2025-07-11 19:38:39] WARNING aws_utils Worker(s) for challenge 29 couldn't restart! Error: Please select challenges with active workers only.
[2025-07-11 19:38:39] INFO aws_utils The worker service for challenge 30 was restarted, as evaluation_script was changed.
[2025-07-11 19:38:39] WARNING aws_utils Worker(s) for challenge 30 couldn't restart! Error: Please select challenges with active workers only.
[2025-07-11 19:38:44] ERROR aws_utils An error occurred (Unknown) when calling the DeregisterTaskDefinition operation: Scaling inactive workers not supported
Traceback (most recent call last):
  File "/code/apps/challenges/aws_utils.py", line 1038, in scale_resources
    response = client.deregister_task_definition(
  File "/usr/local/lib/python3.9/unittest/mock.py", line 1092, in __call__
    return self._mock_call(*args, **kwargs)
  File "/usr/local/lib/python3.9/unittest/mock.py", line 1096, in _mock_call
    return self._execute_mock_call(*args, **kwargs)
  File "/usr/local/lib/python3.9/unittest/mock.py", line 1151, in _execute_mock_call
    raise effect
botocore.exceptions.ClientError: An error occurred (Unknown) when calling the DeregisterTaskDefinition operation: Scaling inactive workers not supported
[2025-07-11 19:38:44] ERROR aws_utils An error occurred (Unknown) when calling the RegisterTaskDefinition operation: Failed to register task definition
Traceback (most recent call last):
  File "/code/apps/challenges/aws_utils.py", line 1079, in scale_resources
    response = client.register_task_definition(**task_def)
  File "/usr/local/lib/python3.9/unittest/mock.py", line 1092, in __call__
    return self._mock_call(*args, **kwargs)
  File "/usr/local/lib/python3.9/unittest/mock.py", line 1096, in _mock_call
    return self._execute_mock_call(*args, **kwargs)
  File "/usr/local/lib/python3.9/unittest/mock.py", line 1151, in _execute_mock_call
    raise effect
botocore.exceptions.ClientError: An error occurred (Unknown) when calling the RegisterTaskDefinition operation: Failed to register task definition
[2025-07-11 19:40:56] INFO aws_utils Set CloudWatch log retention for challenge 123 to 60 days
[2025-07-11 19:40:56] INFO aws_utils Set CloudWatch log retention for challenge 123 to 90 days
[2025-07-11 19:40:56] INFO aws_utils Set CloudWatch log retention for challenge 123 to 30 days
[2025-07-11 19:40:56] INFO aws_utils Starting cleanup of expired submission artifacts
[2025-07-11 19:40:56] INFO aws_utils Found <MagicMock name='filter().select_related().count()' id='281472681045824'> submissions eligible for cleanup
[2025-07-11 19:40:56] INFO aws_utils Cleanup completed. Processed: 0, Successful: 0, Failed: 0
[2025-07-11 19:40:56] INFO aws_utils Updated log retention for approved challenge 123
[2025-07-11 19:40:59] ERROR aws_utils Failed to set log retention for challenge 123
Traceback (most recent call last):
  File "/code/apps/challenges/aws_utils.py", line 2007, in set_cloudwatch_log_retention
    logs_client.put_retention_policy(
  File "/usr/local/lib/python3.9/site-packages/botocore/client.py", line 535, in _api_call
    return self._make_api_call(operation_name, kwargs)
  File "/usr/local/lib/python3.9/site-packages/botocore/client.py", line 980, in _make_api_call
    raise error_class(parsed_response, operation_name)
botocore.errorfactory.UnrecognizedClientException: An error occurred (UnrecognizedClientException) when calling the PutRetentionPolicy operation: The security token included in the request is invalid.
[2025-07-11 19:41:00] WARNING aws_utils Failed to update log retention for challenge 123: An error occurred (UnrecognizedClientException) when calling the PutRetentionPolicy operation: The security token included in the request is invalid.
[2025-07-11 19:41:00] INFO aws_utils The worker service for challenge 125 was restarted, as evaluation_script was changed.
[2025-07-11 19:41:00] WARNING aws_utils Worker(s) for challenge 125 couldn't restart! Error: Please select challenges with active workers only.
[2025-07-11 19:41:00] INFO aws_utils The worker service for challenge 126 was restarted, as evaluation_script was changed.
[2025-07-11 19:41:00] WARNING aws_utils Worker(s) for challenge 126 couldn't restart! Error: Please select challenges with active workers only.
[2025-07-11 19:41:00] INFO aws_utils The worker service for challenge 127 was restarted, as evaluation_script was changed.
[2025-07-11 19:41:00] WARNING aws_utils Worker(s) for challenge 127 couldn't restart! Error: Please select challenges with active workers only.
[2025-07-11 19:41:00] INFO aws_utils The worker service for challenge 128 was restarted, as evaluation_script was changed.
[2025-07-11 19:41:00] WARNING aws_utils Worker(s) for challenge 128 couldn't restart! Error: Please select challenges with active workers only.
[2025-07-11 19:41:00] INFO aws_utils The worker service for challenge 128 was restarted, as evaluation_script was changed.
[2025-07-11 19:41:00] WARNING aws_utils Worker(s) for challenge 128 couldn't restart! Error: Please select challenges with active workers only.
[2025-07-11 19:41:00] INFO aws_utils The worker service for challenge 129 was restarted, as evaluation_script was changed.
[2025-07-11 19:41:00] WARNING aws_utils Worker(s) for challenge 129 couldn't restart! Error: Please select challenges with active workers only.
[2025-07-11 19:41:00] INFO aws_utils The worker service for challenge 130 was restarted, as evaluation_script was changed.
[2025-07-11 19:41:00] WARNING aws_utils Worker(s) for challenge 130 couldn't restart! Error: Please select challenges with active workers only.
[2025-07-11 19:41:00] INFO aws_utils The worker service for challenge 131 was restarted, as evaluation_script was changed.
[2025-07-11 19:41:00] WARNING aws_utils Worker(s) for challenge 131 couldn't restart! Error: Please select challenges with active workers only.
[2025-07-11 19:41:00] INFO aws_utils The worker service for challenge 132 was restarted, as evaluation_script was changed.
[2025-07-11 19:41:00] WARNING aws_utils Worker(s) for challenge 132 couldn't restart! Error: Please select challenges with active workers only.
[2025-07-11 19:41:00] INFO aws_utils The worker service for challenge 133 was restarted, as evaluation_script was changed.
[2025-07-11 19:41:00] WARNING aws_utils Worker(s) for challenge 133 couldn't restart! Error: Please select challenges with active workers only.
[2025-07-11 19:41:03] INFO aws_utils The worker service for challenge 317 was restarted, as test_annotation was changed.
[2025-07-11 19:41:03] WARNING aws_utils Worker(s) for challenge 317 couldn't restart! Error: Please select challenges with active workers only.
[2025-07-11 19:41:26] ERROR aws_utils An error occurred (SomeError) when calling the CreateService operation: Unknown
Traceback (most recent call last):
  File "/code/apps/challenges/aws_utils.py", line 365, in create_service_by_challenge_pk
    response = client.create_service(**definition)
  File "/usr/local/lib/python3.9/unittest/mock.py", line 1092, in __call__
    return self._mock_call(*args, **kwargs)
  File "/usr/local/lib/python3.9/unittest/mock.py", line 1096, in _mock_call
    return self._execute_mock_call(*args, **kwargs)
  File "/usr/local/lib/python3.9/unittest/mock.py", line 1151, in _execute_mock_call
    raise effect
botocore.exceptions.ClientError: An error occurred (SomeError) when calling the CreateService operation: Unknown
[2025-07-11 19:41:26] ERROR aws_utils An error occurred (ServiceError) when calling the UpdateService operation: Unknown
Traceback (most recent call last):
  File "/code/apps/challenges/aws_utils.py", line 414, in update_service_by_challenge_pk
    response = client.update_service(**kwargs)
  File "/usr/local/lib/python3.9/unittest/mock.py", line 1092, in __call__
    return self._mock_call(*args, **kwargs)
  File "/usr/local/lib/python3.9/unittest/mock.py", line 1096, in _mock_call
    return self._execute_mock_call(*args, **kwargs)
  File "/usr/local/lib/python3.9/unittest/mock.py", line 1151, in _execute_mock_call
    raise effect
botocore.exceptions.ClientError: An error occurred (ServiceError) when calling the UpdateService operation: Unknown
[2025-07-11 19:41:26] ERROR aws_utils An error occurred (DeregisterError) when calling the DeregisterTaskDefinition operation: Unknown
Traceback (most recent call last):
  File "/code/apps/challenges/aws_utils.py", line 459, in delete_service_by_challenge_pk
    client.deregister_task_definition(
  File "/usr/local/lib/python3.9/unittest/mock.py", line 1092, in __call__
    return self._mock_call(*args, **kwargs)
  File "/usr/local/lib/python3.9/unittest/mock.py", line 1096, in _mock_call
    return self._execute_mock_call(*args, **kwargs)
  File "/usr/local/lib/python3.9/unittest/mock.py", line 1151, in _execute_mock_call
    raise effect
botocore.exceptions.ClientError: An error occurred (DeregisterError) when calling the DeregisterTaskDefinition operation: Unknown
[2025-07-11 19:41:26] ERROR aws_utils An error occurred (DeleteServiceError) when calling the DeleteService operation: Unknown
Traceback (most recent call last):
  File "/code/apps/challenges/aws_utils.py", line 455, in delete_service_by_challenge_pk
    response = client.delete_service(**kwargs)
  File "/usr/local/lib/python3.9/unittest/mock.py", line 1092, in __call__
    return self._mock_call(*args, **kwargs)
  File "/usr/local/lib/python3.9/unittest/mock.py", line 1096, in _mock_call
    return self._execute_mock_call(*args, **kwargs)
  File "/usr/local/lib/python3.9/unittest/mock.py", line 1151, in _execute_mock_call
    raise effect
botocore.exceptions.ClientError: An error occurred (DeleteServiceError) when calling the DeleteService operation: Unknown
[2025-07-11 19:41:26] ERROR aws_utils An error occurred (Unknown) when calling the DeregisterTaskDefinition operation: Scaling inactive workers not supported
Traceback (most recent call last):
  File "/code/apps/challenges/aws_utils.py", line 1038, in scale_resources
    response = client.deregister_task_definition(
  File "/usr/local/lib/python3.9/unittest/mock.py", line 1092, in __call__
    return self._mock_call(*args, **kwargs)
  File "/usr/local/lib/python3.9/unittest/mock.py", line 1096, in _mock_call
    return self._execute_mock_call(*args, **kwargs)
  File "/usr/local/lib/python3.9/unittest/mock.py", line 1151, in _execute_mock_call
    raise effect
botocore.exceptions.ClientError: An error occurred (Unknown) when calling the DeregisterTaskDefinition operation: Scaling inactive workers not supported
[2025-07-11 19:41:26] ERROR aws_utils An error occurred (Unknown) when calling the RegisterTaskDefinition operation: Failed to register task definition
Traceback (most recent call last):
  File "/code/apps/challenges/aws_utils.py", line 1079, in scale_resources
    response = client.register_task_definition(**task_def)
  File "/usr/local/lib/python3.9/unittest/mock.py", line 1092, in __call__
    return self._mock_call(*args, **kwargs)
  File "/usr/local/lib/python3.9/unittest/mock.py", line 1096, in _mock_call
    return self._execute_mock_call(*args, **kwargs)
  File "/usr/local/lib/python3.9/unittest/mock.py", line 1151, in _execute_mock_call
    raise effect
botocore.exceptions.ClientError: An error occurred (Unknown) when calling the RegisterTaskDefinition operation: Failed to register task definition
[2025-07-11 19:46:11] INFO aws_utils Set CloudWatch log retention for challenge 123 to 60 days
[2025-07-11 19:46:11] INFO aws_utils Set CloudWatch log retention for challenge 123 to 90 days
[2025-07-11 19:46:11] INFO aws_utils Set CloudWatch log retention for challenge 123 to 30 days
[2025-07-11 19:46:11] INFO aws_utils Starting cleanup of expired submission artifacts
[2025-07-11 19:46:11] INFO aws_utils Found <MagicMock name='filter().select_related().count()' id='281473112819024'> submissions eligible for cleanup
[2025-07-11 19:46:11] INFO aws_utils Cleanup completed. Processed: 0, Successful: 0, Failed: 0
[2025-07-11 19:46:11] INFO aws_utils Updated log retention for approved challenge 123
[2025-07-11 19:46:15] ERROR aws_utils Failed to set log retention for challenge 123
Traceback (most recent call last):
  File "/code/apps/challenges/aws_utils.py", line 2007, in set_cloudwatch_log_retention
    logs_client.put_retention_policy(
  File "/usr/local/lib/python3.9/site-packages/botocore/client.py", line 535, in _api_call
    return self._make_api_call(operation_name, kwargs)
  File "/usr/local/lib/python3.9/site-packages/botocore/client.py", line 980, in _make_api_call
    raise error_class(parsed_response, operation_name)
botocore.errorfactory.UnrecognizedClientException: An error occurred (UnrecognizedClientException) when calling the PutRetentionPolicy operation: The security token included in the request is invalid.
[2025-07-11 19:46:15] WARNING aws_utils Failed to update log retention for challenge 123: An error occurred (UnrecognizedClientException) when calling the PutRetentionPolicy operation: The security token included in the request is invalid.
[2025-07-11 19:46:15] INFO aws_utils The worker service for challenge 125 was restarted, as evaluation_script was changed.
[2025-07-11 19:46:15] WARNING aws_utils Worker(s) for challenge 125 couldn't restart! Error: Please select challenges with active workers only.
[2025-07-11 19:46:15] INFO aws_utils The worker service for challenge 126 was restarted, as evaluation_script was changed.
[2025-07-11 19:46:15] WARNING aws_utils Worker(s) for challenge 126 couldn't restart! Error: Please select challenges with active workers only.
[2025-07-11 19:46:15] INFO aws_utils The worker service for challenge 127 was restarted, as evaluation_script was changed.
[2025-07-11 19:46:15] WARNING aws_utils Worker(s) for challenge 127 couldn't restart! Error: Please select challenges with active workers only.
[2025-07-11 19:46:15] INFO aws_utils The worker service for challenge 128 was restarted, as evaluation_script was changed.
[2025-07-11 19:46:15] WARNING aws_utils Worker(s) for challenge 128 couldn't restart! Error: Please select challenges with active workers only.
[2025-07-11 19:46:15] INFO aws_utils The worker service for challenge 128 was restarted, as evaluation_script was changed.
[2025-07-11 19:46:15] WARNING aws_utils Worker(s) for challenge 128 couldn't restart! Error: Please select challenges with active workers only.
[2025-07-11 19:46:15] INFO aws_utils The worker service for challenge 129 was restarted, as evaluation_script was changed.
[2025-07-11 19:46:15] WARNING aws_utils Worker(s) for challenge 129 couldn't restart! Error: Please select challenges with active workers only.
[2025-07-11 19:46:15] INFO aws_utils The worker service for challenge 130 was restarted, as evaluation_script was changed.
[2025-07-11 19:46:15] WARNING aws_utils Worker(s) for challenge 130 couldn't restart! Error: Please select challenges with active workers only.
[2025-07-11 19:46:15] INFO aws_utils The worker service for challenge 131 was restarted, as evaluation_script was changed.
[2025-07-11 19:46:15] WARNING aws_utils Worker(s) for challenge 131 couldn't restart! Error: Please select challenges with active workers only.
[2025-07-11 19:46:15] INFO aws_utils The worker service for challenge 132 was restarted, as evaluation_script was changed.
[2025-07-11 19:46:15] WARNING aws_utils Worker(s) for challenge 132 couldn't restart! Error: Please select challenges with active workers only.
[2025-07-11 19:46:15] INFO aws_utils The worker service for challenge 133 was restarted, as evaluation_script was changed.
[2025-07-11 19:46:15] WARNING aws_utils Worker(s) for challenge 133 couldn't restart! Error: Please select challenges with active workers only.
[2025-07-11 19:46:18] INFO aws_utils The worker service for challenge 317 was restarted, as test_annotation was changed.
[2025-07-11 19:46:18] WARNING aws_utils Worker(s) for challenge 317 couldn't restart! Error: Please select challenges with active workers only.
[2025-07-11 19:46:38] ERROR aws_utils An error occurred (SomeError) when calling the CreateService operation: Unknown
Traceback (most recent call last):
  File "/code/apps/challenges/aws_utils.py", line 365, in create_service_by_challenge_pk
    response = client.create_service(**definition)
  File "/usr/local/lib/python3.9/unittest/mock.py", line 1092, in __call__
    return self._mock_call(*args, **kwargs)
  File "/usr/local/lib/python3.9/unittest/mock.py", line 1096, in _mock_call
    return self._execute_mock_call(*args, **kwargs)
  File "/usr/local/lib/python3.9/unittest/mock.py", line 1151, in _execute_mock_call
    raise effect
botocore.exceptions.ClientError: An error occurred (SomeError) when calling the CreateService operation: Unknown
